Workbook

Sheet HƯỚNG DẪN
A1: HƯỚNG DẪN SỬ DỤNG – FILE QUẢN LÝ ĐƠN HÀNG, LÃI LỖ & CÔNG NỢ
A2: Bản rút gọn: chỉ NHẬP 2 sheet màu vàng, 7 sheet còn lại tự động cập nhật.
A5: A. CHỈ CÓ 2 SHEET PHẢI NHẬP TAY
A6: 1. BẢNG GIÁ GỐC | B6: Nhập 1 lần cho mỗi sản phẩm: TÊN SẢN PHẨM, GIÁ GỐC (giá vốn), GIÁ BÁN GỢI Ý. Sau đó file tự biết giá gốc để tính lãi/lỗ.
A7: 2. NHẬP ĐƠN HÀNG | B7: Nhân viên sale chỉ nhập ở đây: ngày, khách, sản phẩm, số lượng, giá bán, VAT, số tiền khách đã trả. Tất cả phần còn lại tự tính.
A9: B. 7 SHEET TỰ ĐỘNG – KHÔNG GÕ GÌ VÀO
A10: 3. BÁO CÁO DOANH THU | B10: Doanh thu / VAT / đã thu / còn nợ / lãi theo từng tháng và cả năm. Chỉ cần đổi ô NĂM.
A11: 4. LÃI LỖ | B11: Tổng quan lãi lỗ, lãi lỗ theo tháng và lãi lỗ theo từng sản phẩm.
A12: 5. KHÁCH HÀNG | B12: Tự gom danh sách khách từ sheet NHẬP ĐƠN HÀNG: đã mua bao nhiêu, đã trả, còn nợ, lãi.
A13: 6. CÔNG NỢ | B13: Tự liệt kê những đơn khách còn nợ tiền, kèm số ngày kể từ ngày đặt.
A14: 7. KHÁCH LẤY VAT | B14: Tự liệt kê các đơn có VAT, kèm tiền thuế từng đơn và tổng thuế.
A15: 8. KHÁCH KHÔNG VAT | B15: Tự liệt kê các đơn không lấy VAT.
A17: C. QUY TẮC MÀU
A18: Ô MÀU VÀNG | B18: Nhân viên nhập tay.
A19: Ô MÀU XANH NHẠT | B19: Máy tự tính – KHÔNG gõ đè lên, sẽ mất công thức.
A20: Ô MÀU CAM (CẢNH BÁO) | B20: Nhắc dòng nào thiếu dữ liệu hoặc đang lỗ. Xử lý hết là số liệu chuẩn.
A22: D. CÁCH TÍNH LÃI LỖ
A23: TIỀN HÀNG | B23: SỐ LƯỢNG × GIÁ BÁN/SP (giá bán CHƯA gồm VAT)
A24: TỔNG VỐN | B24: SỐ LƯỢNG × GIÁ GỐC/SP (giá gốc lấy tự động từ BẢNG GIÁ GỐC)
A25: LÃI / LỖ | B25: TIỀN HÀNG − TỔNG VỐN. Số âm màu đỏ nghĩa là ĐANG LỖ.
A26: % LÃI | B26: LÃI / LỖ ÷ TIỀN HÀNG
A27: TIỀN VAT | B27: TIỀN HÀNG × THUẾ SUẤT (0% / 5% / 8% / 10% chọn ở cột LẤY VAT?)
A28: TỔNG PHẢI THU | B28: TIỀN HÀNG + TIỀN VAT
A29: CÒN NỢ | B29: TỔNG PHẢI THU − ĐÃ THANH TOÁN
A31: E. LƯU Ý QUAN TRỌNG
A32: Giá bán nhập là giá CHƯA VAT | B32: Nếu báo khách giá đã gồm 8% VAT thì lấy giá đó chia 1,08 rồi mới nhập.
A33: Tên sản phẩm phải chọn từ danh sách | B33: Gõ tay sai chính tả sẽ không lấy được giá gốc → cột CẢNH BÁO sẽ báo ngay.
A34: Muốn thêm sản phẩm mới | B34: Thêm 1 dòng ở BẢNG GIÁ GỐC là danh sách chọn tự có sản phẩm đó.
A35: Lô hàng có giá vốn khác | B35: Thêm 1 dòng sản phẩm riêng ở BẢNG GIÁ GỐC, ví dụ: GẤU TEDDY 25CM TRẮNG – lô T8.
A36: Muốn xem năm khác | B36: Vào BÁO CÁO DOANH THU, sửa ô NĂM (ô vàng).

Sheet BẢNG GIÁ GỐC
A1: BẢNG GIÁ GỐC SẢN PHẨM
A2: NHÂN VIÊN CHỈ NHẬP Ở ĐÂY: tên sản phẩm, giá gốc (giá vốn), giá bán gợi ý. Sheet NHẬP ĐƠN HÀNG sẽ tự lấy giá gốc để tính lãi lỗ.
A4: TÊN SẢN PHẨM | B4: QUY CÁCH / KÍCH THƯỚC | C4: GIÁ GỐC / SP (đ) | D4: GIÁ BÁN GỢI Ý / SP (đ) | E4: LÃI GỢI Ý / SP (đ) | F4: % LÃI GỢI Ý | G4: GHI CHÚ
A5: GẤU TEDDY 25CM TRẮNG | B5: 25CM | C5: 35000 | D5: 50000 | E5: =IF($A5="","",N($D5)-N($C5)) -> 15000 | F5: =IF(OR($A5="",N($D5)=0),"",($D5-$C5)/$D5) -> 0.3
A6: GẤU TEDDY 30CM | B6: 30CM | C6: 35000 | D6: 50000 | E6: =IF($A6="","",N($D6)-N($C6)) -> 15000 | F6: =IF(OR($A6="",N($D6)=0),"",($D6-$C6)/$D6) -> 0.3
A7: GẤU TEDDY 20CM LÔNG MỊN | B7: 20CM | C7: 35000 | D7: 50000 | E7: =IF($A7="","",N($D7)-N($C7)) -> 15000 | F7: =IF(OR($A7="",N($D7)=0),"",($D7-$C7)/$D7) -> 0.3
A8: GỐI ÔM CỎ | B8: 25CM | C8: 35000 | D8: 45000 | E8: =IF($A8="","",N($D8)-N($C8)) -> 10000 | F8: =IF(OR($A8="",N($D8)=0),"",($D8-$C8)/$D8) -> 0.22222222
A9: GẤU TEDDY 20CM LÔNG XÙ | B9: 20CM | C9: 35000 | D9: 45000 | E9: =IF($A9="","",N($D9)-N($C9)) -> 10000 | F9: =IF(OR($A9="",N($D9)=0),"",($D9-$C9)/$D9) -> 0.22222222
A10: GẤU TEDDY 27CM NÂU | B10: 27CM | C10: 35000 | D10: 50000 | E10: =IF($A10="","",N($D10)-N($C10)) -> 15000 | F10: =IF(OR($A10="",N($D10)=0),"",($D10-$C10)/$D10) -> 0.3
A11: GẤU TỐT NGHIỆP | B11: 27CM | C11: 40000 | D11: 55000 | E11: =IF($A11="","",N($D11)-N($C11)) -> 15000 | F11: =IF(OR($A11="",N($D11)=0),"",($D11-$C11)/$D11) -> 0.27272727
A12: GẤU TEDY INLOGO HOA THÁI | B12: 30CM | C12: 42000 | D12: 52000 | E12: =IF($A12="","",N($D12)-N($C12)) -> 10000 | F12: =IF(OR($A12="",N($D12)=0),"",($D12-$C12)/$D12) -> 0.19230769
A13: GẤU TRÁI TIM INLOGO 1 MẶT HOA THÁI | B13: 40CM | C13: 42000 | D13: 55000 | E13: =IF($A13="","",N($D13)-N($C13)) -> 13000 | F13: =IF(OR($A13="",N($D13)=0),"",($D13-$C13)/$D13) -> 0.23636364
A14: GẤU BÔNG LENA TRÚC | B14: 30CM | C14: 50000 | D14: 65000 | E14: =IF($A14="","",N($D14)-N($C14)) -> 15000 | F14: =IF(OR($A14="",N($D14)=0),"",($D14-$C14)/$D14) -> 0.23076923
A15: CÁ MẬP INLOGO | B15: 30CM | C15: 36000 | D15: 48000 | E15: =IF($A15="","",N($D15)-N($C15)) -> 12000 | F15: =IF(OR($A15="",N($D15)=0),"",($D15-$C15)/$D15) -> 0.25
A16: MẦM INLOGO / ĐÀO TIÊN INLOGO | B16: 20CM | C16: 36000 | D16: 48000 | E16: =IF($A16="","",N($D16)-N($C16)) -> 12000 | F16: =IF(OR($A16="",N($D16)=0),"",($D16-$C16)/$D16) -> 0.25
... A18: TEDDY TRẮNG QUẢNG CHÂU INLOGO | B18: 30CM | C18: 45000 | D18: 58000 | E18: =IF($A18="","",N($D18)-N($C18)) -> 13000 | F18: =IF(OR($A18="",N($D18)=0),"",($D18-$C18)/$D18) -> 0.22413793
E19: =IF($A19="","",N($D19)-N($C19)) | F19: =IF(OR($A19="",N($D19)=0),"",($D19-$C19)/$D19)
E20: =IF($A20="","",N($D20)-N($C20)) | F20: =IF(OR($A20="",N($D20)=0),"",($D20-$C20)/$D20)
E21: =IF($A21="","",N($D21)-N($C21)) | F21: =IF(OR($A21="",N($D21)=0),"",($D21-$C21)/$D21)
E22: =IF($A22="","",N($D22)-N($C22)) | F22: =IF(OR($A22="",N($D22)=0),"",($D22-$C22)/$D22)
E23: =IF($A23="","",N($D23)-N($C23)) | F23: =IF(OR($A23="",N($D23)=0),"",($D23-$C23)/$D23)
E24: =IF($A24="","",N($D24)-N($C24)) | F24: =IF(OR($A24="",N($D24)=0),"",($D24-$C24)/$D24)
E25: =IF($A25="","",N($D25)-N($C25)) | F25: =IF(OR($A25="",N($D25)=0),"",($D25-$C25)/$D25)
E26: =IF($A26="","",N($D26)-N($C26)) | F26: =IF(OR($A26="",N($D26)=0),"",($D26-$C26)/$D26)
E27: =IF($A27="","",N($D27)-N($C27)) | F27: =IF(OR($A27="",N($D27)=0),"",($D27-$C27)/$D27)
E28: =IF($A28="","",N($D28)-N($C28)) | F28: =IF(OR($A28="",N($D28)=0),"",($D28-$C28)/$D28)
E29: =IF($A29="","",N($D29)-N($C29)) | F29: =IF(OR($A29="",N($D29)=0),"",($D29-$C29)/$D29)
E30: =IF($A30="","",N($D30)-N($C30)) | F30: =IF(OR($A30="",N($D30)=0),"",($D30-$C30)/$D30)
... E204: =IF($A204="","",N($D204)-N($C204)) | F204: =IF(OR($A204="",N($D204)=0),"",($D204-$C204)/$D204)

Sheet NHẬP ĐƠN HÀNG
A1: NHẬP ĐƠN HÀNG (SHEET DUY NHẤT NHÂN VIÊN SALE PHẢI NHẬP)
A2: Chỉ gõ vào Ô MÀU VÀNG. Thành tiền, VAT, tổng phải thu, còn nợ, tổng vốn và lãi/lỗ đều tự tính.
A3: SỐ ĐƠN | B3: =COUNTA($C$6:$C$505) -> 6 | C3: TIỀN HÀNG (đ) | D3: =SUM($L$6:$L$505) -> 15300000 | E3: TỔNG VỐN (đ) | F3: =SUM($T$6:$T$505) -> 10950000 | G3: LÃI / LỖ (đ) | H3: =SUM($U$6:$U$505) -> 4350000 | I3: % LÃI | J3: =IF(SUM($L$6:$L$505)=0,"",SUM($U$6:$U$505)/SUM($L$6:$L$505)) -> 0.28431373 | K3: TỔNG PHẢI THU (đ) | L3: =SUM($P$6:$P$505) -> 15391200 | M3: ĐÃ THU (đ) | N3: =SUM($Q$6:$Q$505) -> 6110000 | O3: CÒN NỢ (đ) | P3: =SUM($R$6:$R$505) -> 9281200 | Q3: DÒNG CẦN KIỂM TRA | R3: =SUMPRODUCT(--(LEN($X$6:$X$505)>0)) -> 3
A5: STT | B5: NGÀY ĐẶT | C5: TÊN KHÁCH HÀNG | D5: SỐ ĐIỆN THOẠI | E5: CÔNG TY (nếu có) | F5: MÃ SỐ THUẾ (nếu lấy VAT) | G5: ĐỊA CHỈ GIAO HÀNG | H5: TÊN SẢN PHẨM | I5: SỐ LƯỢNG | J5: GIÁ GỐC / SP (đ) | K5: GIÁ BÁN / SP (đ) (chưa VAT) | L5: TIỀN HÀNG (đ) | M5: LẤY VAT? | N5: THUẾ SUẤT | O5: TIỀN VAT (đ) | P5: TỔNG PHẢI THU (đ) | Q5: ĐÃ THANH TOÁN (đ) | R5: CÒN NỢ (đ) | S5: TÌNH TRẠNG | T5: TỔNG VỐN (đ) | U5: LÃI / LỖ (đ) | V5: % LÃI | W5: GHI CHÚ | X5: CẢNH BÁO | Y5: _nợ | Z5: _vat | AA5: _kvat | AB5: _khách | AC5: _sp
A6: =IF($C6="","",COUNTA($C$6:$C6)) -> 1 | C6: BGB - GẤU TỐT NGHIỆP AMES EL | D6: 0865895498 | E6: CÔNG TY CỔ PHẦN ĐÀO TẠO AMES - CHI NHÁNH THANH HÓA | F6: 0402018889-005 | G6: 18 Phan Chu Trinh, Hạc Thành, Thanh Hóa | H6: GẤU TỐT NGHIỆP | I6: 20 | J6: =IF($H6="","",IFERROR(VLOOKUP($H6,'BẢNG GIÁ GỐC'!$A$5:$D$204,3,FALSE()),"")) -> 40000 | K6: 57000 | L6: =IF($C6="","",N($I6)*N($K6)) -> 1140000 | M6: VAT 8% | N6: =IF($C6="","",IF($M6="VAT 5%",0.05,IF($M6="VAT 8%",0.08,IF($M6="VAT 10%",0.1,0)))) -> 0.08 | O6: =IF($C6="","",$L6*$N6) -> 91200 | P6: =IF($C6="","",$L6+$O6) -> 1231200 | Q6: 0 | R6: =IF($C6="","",MAX(0,$P6-N($Q6))) -> 1231200 | S6: =IF(OR($C6="",$P6=0),"",IF(N($Q6)<=0,"Chưa thanh toán",IF(N($Q6)<$P6,"Thanh toán một phần","Đã thanh toán"))) -> Chưa thanh toán | T6: =IF(OR($C6="",$J6=""),"",N($I6)*$J6) -> 800000 | U6: =IF(OR($C6="",$T6=""),"",$L6-$T6) -> 340000 | V6: =IF(OR($U6="",$L6=0),"",$U6/$L6) -> 0.29824561 | W6: Chuyển từ file cũ (DH-000003) – file cũ THIẾU NGÀY ĐẶT, vui lòng bổ sung | X6: =IF($C6="","",IF(AND($H6="",N($I6)=0,N($K6)=0),"Dòng chỉ lưu thông tin khách (chưa có đơn); ",IF($B6="","Thiếu ngày đặt; ","")&IF($H6="","Thiếu tên sản phẩm; ",IF($J6="","Sản phẩm chưa có trong BẢNG GIÁ GỐC; ",""))&IF(N($I6)<=0,"Thiếu số lượng; ","")&IF(N($K6)<=0,"Thiếu giá bán; ","")&IF(AND($N6>0,$F6=""),"Khách lấy VAT thiếu mã số thuế; ","")&IF(N($Q6)>$P6,"Đã thu vượt tổng phải thu; ","")&IF(AND($L6>0,$U6<0),"CẢNH BÁO: ĐƠN NÀY ĐANG LỖ; ",""))) -> Thiếu ngày đặt; | Y6: =IF(AND($C6<>"",$R6>0),COUNTIFS($C$6:$C6,"<>",$R$6:$R6,">0"),"") -> 1 | Z6: =IF(AND($H6<>"",N($N6)>0),COUNTIFS($H$6:$H6,"<>",$N$6:$N6,">0"),"") -> 1 | AA6: =IF(AND($H6<>"",N($N6)=0),COUNTIFS($H$6:$H6,"<>",$N$6:$N6,"<=0"),"") | AB6: =IF($C6="","",IF(COUNTIF($C$6:$C6,$C6)>1,"",MAX($AB$5:AB5)+1)) -> 1 | AC6: =IF($H6="","",IF(COUNTIF($H$6:$H6,$H6)>1,"",MAX($AC$5:AC5)+1)) -> 1
A7: =IF($C7="","",COUNTA($C$6:$C7)) -> 2 | B7: 46224 | C7: NGUYỆT ANH | D7: 0914121088 | E7: BGB - K2 NBK 130C | F7: 2500740944 | G7: Gần Nguyễn Hoàng (đoạn đường tránh qua TP. Tam Kỳ) | H7: GẤU TEDDY 25CM TRẮNG | I7: 130 | J7: =IF($H7="","",IFERROR(VLOOKUP($H7,'BẢNG GIÁ GỐC'!$A$5:$D$204,3,FALSE()),"")) -> 35000 | K7: 48000 | L7: =IF($C7="","",N($I7)*N($K7)) -> 6240000 | M7: Không lấy VAT | N7: =IF($C7="","",IF($M7="VAT 5%",0.05,IF($M7="VAT 8%",0.08,IF($M7="VAT 10%",0.1,0)))) -> 0 | O7: =IF($C7="","",$L7*$N7) -> 0 | P7: =IF($C7="","",$L7+$O7) -> 6240000 | Q7: 3110000 | R7: =IF($C7="","",MAX(0,$P7-N($Q7))) -> 3130000 | S7: =IF(OR($C7="",$P7=0),"",IF(N($Q7)<=0,"Chưa thanh toán",IF(N($Q7)<$P7,"Thanh toán một phần","Đã thanh toán"))) -> Thanh toán một phần | T7: =IF(OR($C7="",$J7=""),"",N($I7)*$J7) -> 4550000 | U7: =IF(OR($C7="",$T7=""),"",$L7-$T7) -> 1690000 | V7: =IF(OR($U7="",$L7=0),"",$U7/$L7) -> 0.27083333 | W7: Chuyển từ file cũ (DH-000006) | X7: =IF($C7="","",IF(AND($H7="",N($I7)=0,N($K7)=0),"Dòng chỉ lưu thông tin khách (chưa có đơn); ",IF($B7="","Thiếu ngày đặt; ","")&IF($H7="","Thiếu tên sản phẩm; ",IF($J7="","Sản phẩm chưa có trong BẢNG GIÁ GỐC; ",""))&IF(N($I7)<=0,"Thiếu số lượng; ","")&IF(N($K7)<=0,"Thiếu giá bán; ","")&IF(AND($N7>0,$F7=""),"Khách lấy VAT thiếu mã số thuế; ","")&IF(N($Q7)>$P7,"Đã thu vượt tổng phải thu; ","")&IF(AND($L7>0,$U7<0),"CẢNH BÁO: ĐƠN NÀY ĐANG LỖ; ",""))) | Y7: =IF(AND($C7<>"",$R7>0),COUNTIFS($C$6:$C7,"<>",$R$6:$R7,">0"),"") -> 2 | Z7: =IF(AND($H7<>"",N($N7)>0),COUNTIFS($H$6:$H7,"<>",$N$6:$N7,">0"),"") | AA7: =IF(AND($H7<>"",N($N7)=0),COUNTIFS($H$6:$H7,"<>",$N$6:$N7,"<=0"),"") -> 1 | AB7: =IF($C7="","",IF(COUNTIF($C$6:$C7,$C7)>1,"",MAX($AB$5:AB6)+1)) -> 2 | AC7: =IF($H7="","",IF(COUNTIF($H$6:$H7,$H7)>1,"",MAX($AC$5:AC6)+1)) -> 2
A8: =IF($C8="","",COUNTA($C$6:$C8)) -> 3 | B8: 46224 | C8: KH-0007 (file cũ chưa có tên) | H8: GỐI ÔM CỎ | I8: 80 | J8: =IF($H8="","",IFERROR(VLOOKUP($H8,'BẢNG GIÁ GỐC'!$A$5:$D$204,3,FALSE()),"")) -> 35000 | K8: 52000 | L8: =IF($C8="","",N($I8)*N($K8)) -> 4160000 | M8: Không lấy VAT | N8: =IF($C8="","",IF($M8="VAT 5%",0.05,IF($M8="VAT 8%",0.08,IF($M8="VAT 10%",0.1,0)))) -> 0 | O8: =IF($C8="","",$L8*$N8) -> 0 | P8: =IF($C8="","",$L8+$O8) -> 4160000 | Q8: 1500000 | R8: =IF($C8="","",MAX(0,$P8-N($Q8))) -> 2660000 | S8: =IF(OR($C8="",$P8=0),"",IF(N($Q8)<=0,"Chưa thanh toán",IF(N($Q8)<$P8,"Thanh toán một phần","Đã thanh toán"))) -> Thanh toán một phần | T8: =IF(OR($C8="",$J8=""),"",N($I8)*$J8) -> 2800000 | U8: =IF(OR($C8="",$T8=""),"",$L8-$T8) -> 1360000 | V8: =IF(OR($U8="",$L8=0),"",$U8/$L8) -> 0.32692308 | W8: Chuyển từ file cũ (DH-000007) – bổ sung tên và SĐT khách | X8: =IF($C8="","",IF(AND($H8="",N($I8)=0,N($K8)=0),"Dòng chỉ lưu thông tin khách (chưa có đơn); ",IF($B8="","Thiếu ngày đặt; ","")&IF($H8="","Thiếu tên sản phẩm; ",IF($J8="","Sản phẩm chưa có trong BẢNG GIÁ GỐC; ",""))&IF(N($I8)<=0,"Thiếu số lượng; ","")&IF(N($K8)<=0,"Thiếu giá bán; ","")&IF(AND($N8>0,$F8=""),"Khách lấy VAT thiếu mã số thuế; ","")&IF(N($Q8)>$P8,"Đã thu vượt tổng phải thu; ","")&IF(AND($L8>0,$U8<0),"CẢNH BÁO: ĐƠN NÀY ĐANG LỖ; ",""))) | Y8: =IF(AND($C8<>"",$R8>0),COUNTIFS($C$6:$C8,"<>",$R$6:$R8,">0"),"") -> 3 | Z8: =IF(AND($H8<>"",N($N8)>0),COUNTIFS($H$6:$H8,"<>",$N$6:$N8,">0"),"") | AA8: =IF(AND($H8<>"",N($N8)=0),COUNTIFS($H$6:$H8,"<>",$N$6:$N8,"<=0"),"") -> 2 | AB8: =IF($C8="","",IF(COUNTIF($C$6:$C8,$C8)>1,"",MAX($AB$5:AB7)+1)) -> 3 | AC8: =IF($H8="","",IF(COUNTIF($H$6:$H8,$H8)>1,"",MAX($AC$5:AC7)+1)) -> 3
A9: =IF($C9="","",COUNTA($C$6:$C9)) -> 4 | B9: 46224 | C9: KH-007 (file cũ chưa có tên) | H9: GẤU TEDDY 25CM TRẮNG | I9: 80 | J9: =IF($H9="","",IFERROR(VLOOKUP($H9,'BẢNG GIÁ GỐC'!$A$5:$D$204,3,FALSE()),"")) -> 35000 | K9: 47000 | L9: =IF($C9="","",N($I9)*N($K9)) -> 3760000 | M9: Không lấy VAT | N9: =IF($C9="","",IF($M9="VAT 5%",0.05,IF($M9="VAT 8%",0.08,IF($M9="VAT 10%",0.1,0)))) -> 0 | O9: =IF($C9="","",$L9*$N9) -> 0 | P9: =IF($C9="","",$L9+$O9) -> 3760000 | Q9: 1500000 | R9: =IF($C9="","",MAX(0,$P9-N($Q9))) -> 2260000 | S9: =IF(OR($C9="",$P9=0),"",IF(N($Q9)<=0,"Chưa thanh toán",IF(N($Q9)<$P9,"Thanh toán một phần","Đã thanh toán"))) -> Thanh toán một phần | T9: =IF(OR($C9="",$J9=""),"",N($I9)*$J9) -> 2800000 | U9: =IF(OR($C9="",$T9=""),"",$L9-$T9) -> 960000 | V9: =IF(OR($U9="",$L9=0),"",$U9/$L9) -> 0.25531915 | W9: Chuyển từ file cũ (DH-000008) – bổ sung tên và SĐT khách | X9: =IF($C9="","",IF(AND($H9="",N($I9)=0,N($K9)=0),"Dòng chỉ lưu thông tin khách (chưa có đơn); ",IF($B9="","Thiếu ngày đặt; ","")&IF($H9="","Thiếu tên sản phẩm; ",IF($J9="","Sản phẩm chưa có trong BẢNG GIÁ GỐC; ",""))&IF(N($I9)<=0,"Thiếu số lượng; ","")&IF(N($K9)<=0,"Thiếu giá bán; ","")&IF(AND($N9>0,$F9=""),"Khách lấy VAT thiếu mã số thuế; ","")&IF(N($Q9)>$P9,"Đã thu vượt tổng phải thu; ","")&IF(AND($L9>0,$U9<0),"CẢNH BÁO: ĐƠN NÀY ĐANG LỖ; ",""))) | Y9: =IF(AND($C9<>"",$R9>0),COUNTIFS($C$6:$C9,"<>",$R$6:$R9,">0"),"") -> 4 | Z9: =IF(AND($H9<>"",N($N9)>0),COUNTIFS($H$6:$H9,"<>",$N$6:$N9,">0"),"") | AA9: =IF(AND($H9<>"",N($N9)=0),COUNTIFS($H$6:$H9,"<>",$N$6:$N9,"<=0"),"") -> 3 | AB9: =IF($C9="","",IF(COUNTIF($C$6:$C9,$C9)>1,"",MAX($AB$5:AB8)+1)) -> 4 | AC9: =IF($H9="","",IF(COUNTIF($H$6:$H9,$H9)>1,"",MAX($AC$5:AC8)+1))
A10: =IF($C10="","",COUNTA($C$6:$C10)) -> 5 | C10: A TÀI - HUYNDAI - 20C | D10: 0935494005 | G10: 461 Tây Sơn, Quy Nhơn Nam, Gia Lai | J10: =IF($H10="","",IFERROR(VLOOKUP($H10,'BẢNG GIÁ GỐC'!$A$5:$D$204,3,FALSE()),"")) | L10: =IF($C10="","",N($I10)*N($K10)) -> 0 | M10: Không lấy VAT | N10: =IF($C10="","",IF($M10="VAT 5%",0.05,IF($M10="VAT 8%",0.08,IF($M10="VAT 10%",0.1,0)))) -> 0 | O10: =IF($C10="","",$L10*$N10) -> 0 | P10: =IF($C10="","",$L10+$O10) -> 0 | R10: =IF($C10="","",MAX(0,$P10-N($Q10))) -> 0 | S10: =IF(OR($C10="",$P10=0),"",IF(N($Q10)<=0,"Chưa thanh toán",IF(N($Q10)<$P10,"Thanh toán một phần","Đã thanh toán"))) | T10: =IF(OR($C10="",$J10=""),"",N($I10)*$J10) | U10: =IF(OR($C10="",$T10=""),"",$L10-$T10) | V10: =IF(OR($U10="",$L10=0),"",$U10/$L10) | W10: Khách có trong danh mục cũ nhưng chưa phát sinh đơn thật | X10: =IF($C10="","",IF(AND($H10="",N($I10)=0,N($K10)=0),"Dòng chỉ lưu thông tin khách (chưa có đơn); ",IF($B10="","Thiếu ngày đặt; ","")&IF($H10="","Thiếu tên sản phẩm; ",IF($J10="","Sản phẩm chưa có trong BẢNG GIÁ GỐC; ",""))&IF(N($I10)<=0,"Thiếu số lượng; ","")&IF(N($K10)<=0,"Thiếu giá bán; ","")&IF(AND($N10>0,$F10=""),"Khách lấy VAT thiếu mã số thuế; ","")&IF(N($Q10)>$P10,"Đã thu vượt tổng phải thu; ","")&IF(AND($L10>0,$U10<0),"CẢNH BÁO: ĐƠN NÀY ĐANG LỖ; ",""))) -> Dòng chỉ lưu thông tin khách (chưa có đơn); | Y10: =IF(AND($C10<>"",$R10>0),COUNTIFS($C$6:$C10,"<>",$R$6:$R10,">0"),"") | Z10: =IF(AND($H10<>"",N($N10)>0),COUNTIFS($H$6:$H10,"<>",$N$6:$N10,">0"),"") | AA10: =IF(AND($H10<>"",N($N10)=0),COUNTIFS($H$6:$H10,"<>",$N$6:$N10,"<=0"),"") | AB10: =IF($C10="","",IF(COUNTIF($C$6:$C10,$C10)>1,"",MAX($AB$5:AB9)+1)) -> 5 | AC10: =IF($H10="","",IF(COUNTIF($H$6:$H10,$H10)>1,"",MAX($AC$5:AC9)+1))
A11: =IF($C11="","",COUNTA($C$6:$C11)) -> 6 | C11: BGB - CÔ AN MẾN TẶNG | D11: 0903535291 | G11: 658 đường 2/9 Hải Châu - Đà Nẵng | J11: =IF($H11="","",IFERROR(VLOOKUP($H11,'BẢNG GIÁ GỐC'!$A$5:$D$204,3,FALSE()),"")) | L11: =IF($C11="","",N($I11)*N($K11)) -> 0 | M11: Không lấy VAT | N11: =IF($C11="","",IF($M11="VAT 5%",0.05,IF($M11="VAT 8%",0.08,IF($M11="VAT 10%",0.1,0)))) -> 0 | O11: =IF($C11="","",$L11*$N11) -> 0 | P11: =IF($C11="","",$L11+$O11) -> 0 | R11: =IF($C11="","",MAX(0,$P11-N($Q11))) -> 0 | S11: =IF(OR($C11="",$P11=0),"",IF(N($Q11)<=0,"Chưa thanh toán",IF(N($Q11)<$P11,"Thanh toán một phần","Đã thanh toán"))) | T11: =IF(OR($C11="",$J11=""),"",N($I11)*$J11) | U11: =IF(OR($C11="",$T11=""),"",$L11-$T11) | V11: =IF(OR($U11="",$L11=0),"",$U11/$L11) | W11: Khách có trong danh mục cũ nhưng chưa phát sinh đơn thật | X11: =IF($C11="","",IF(AND($H11="",N($I11)=0,N($K11)=0),"Dòng chỉ lưu thông tin khách (chưa có đơn); ",IF($B11="","Thiếu ngày đặt; ","")&IF($H11="","Thiếu tên sản phẩm; ",IF($J11="","Sản phẩm chưa có trong BẢNG GIÁ GỐC; ",""))&IF(N($I11)<=0,"Thiếu số lượng; ","")&IF(N($K11)<=0,"Thiếu giá bán; ","")&IF(AND($N11>0,$F11=""),"Khách lấy VAT thiếu mã số thuế; ","")&IF(N($Q11)>$P11,"Đã thu vượt tổng phải thu; ","")&IF(AND($L11>0,$U11<0),"CẢNH BÁO: ĐƠN NÀY ĐANG LỖ; ",""))) -> Dòng chỉ lưu thông tin khách (chưa có đơn); | Y11: =IF(AND($C11<>"",$R11>0),COUNTIFS($C$6:$C11,"<>",$R$6:$R11,">0"),"") | Z11: =IF(AND($H11<>"",N($N11)>0),COUNTIFS($H$6:$H11,"<>",$N$6:$N11,">0"),"") | AA11: =IF(AND($H11<>"",N($N11)=0),COUNTIFS($H$6:$H11,"<>",$N$6:$N11,"<=0"),"") | AB11: =IF($C11="","",IF(COUNTIF($C$6:$C11,$C11)>1,"",MAX($AB$5:AB10)+1)) -> 6 | AC11: =IF($H11="","",IF(COUNTIF($H$6:$H11,$H11)>1,"",MAX($AC$5:AC10)+1))
A12: =IF($C12="","",COUNTA($C$6:$C12)) | J12: =IF($H12="","",IFERROR(VLOOKUP($H12,'BẢNG GIÁ GỐC'!$A$5:$D$204,3,FALSE()),"")) | L12: =IF($C12="","",N($I12)*N($K12)) | N12: =IF($C12="","",IF($M12="VAT 5%",0.05,IF($M12="VAT 8%",0.08,IF($M12="VAT 10%",0.1,0)))) | O12: =IF($C12="","",$L12*$N12) | P12: =IF($C12="","",$L12+$O12) | R12: =IF($C12="","",MAX(0,$P12-N($Q12))) | S12: =IF(OR($C12="",$P12=0),"",IF(N($Q12)<=0,"Chưa thanh toán",IF(N($Q12)<$P12,"Thanh toán một phần","Đã thanh toán"))) | T12: =IF(OR($C12="",$J12=""),"",N($I12)*$J12) | U12: =IF(OR($C12="",$T12=""),"",$L12-$T12) | V12: =IF(OR($U12="",$L12=0),"",$U12/$L12) | X12: =IF($C12="","",IF(AND($H12="",N($I12)=0,N($K12)=0),"Dòng chỉ lưu thông tin khách (chưa có đơn); ",IF($B12="","Thiếu ngày đặt; ","")&IF($H12="","Thiếu tên sản phẩm; ",IF($J12="","Sản phẩm chưa có trong BẢNG GIÁ GỐC; ",""))&IF(N($I12)<=0,"Thiếu số lượng; ","")&IF(N($K12)<=0,"Thiếu giá bán; ","")&IF(AND($N12>0,$F12=""),"Khách lấy VAT thiếu mã số thuế; ","")&IF(N($Q12)>$P12,"Đã thu vượt tổng phải thu; ","")&IF(AND($L12>0,$U12<0),"CẢNH BÁO: ĐƠN NÀY ĐANG LỖ; ",""))) | Y12: =IF(AND($C12<>"",$R12>0),COUNTIFS($C$6:$C12,"<>",$R$6:$R12,">0"),"") | Z12: =IF(AND($H12<>"",N($N12)>0),COUNTIFS($H$6:$H12,"<>",$N$6:$N12,">0"),"") | AA12: =IF(AND($H12<>"",N($N12)=0),COUNTIFS($H$6:$H12,"<>",$N$6:$N12,"<=0"),"") | AB12: =IF($C12="","",IF(COUNTIF($C$6:$C12,$C12)>1,"",MAX($AB$5:AB11)+1)) | AC12: =IF($H12="","",IF(COUNTIF($H$6:$H12,$H12)>1,"",MAX($AC$5:AC11)+1))
A13: =IF($C13="","",COUNTA($C$6:$C13)) | J13: =IF($H13="","",IFERROR(VLOOKUP($H13,'BẢNG GIÁ GỐC'!$A$5:$D$204,3,FALSE()),"")) | L13: =IF($C13="","",N($I13)*N($K13)) | N13: =IF($C13="","",IF($M13="VAT 5%",0.05,IF($M13="VAT 8%",0.08,IF($M13="VAT 10%",0.1,0)))) | O13: =IF($C13="","",$L13*$N13) | P13: =IF($C13="","",$L13+$O13) | R13: =IF($C13="","",MAX(0,$P13-N($Q13))) | S13: =IF(OR($C13="",$P13=0),"",IF(N($Q13)<=0,"Chưa thanh toán",IF(N($Q13)<$P13,"Thanh toán một phần","Đã thanh toán"))) | T13: =IF(OR($C13="",$J13=""),"",N($I13)*$J13) | U13: =IF(OR($C13="",$T13=""),"",$L13-$T13) | V13: =IF(OR($U13="",$L13=0),"",$U13/$L13) | X13: =IF($C13="","",IF(AND($H13="",N($I13)=0,N($K13)=0),"Dòng chỉ lưu thông tin khách (chưa có đơn); ",IF($B13="","Thiếu ngày đặt; ","")&IF($H13="","Thiếu tên sản phẩm; ",IF($J13="","Sản phẩm chưa có trong BẢNG GIÁ GỐC; ",""))&IF(N($I13)<=0,"Thiếu số lượng; ","")&IF(N($K13)<=0,"Thiếu giá bán; ","")&IF(AND($N13>0,$F13=""),"Khách lấy VAT thiếu mã số thuế; ","")&IF(N($Q13)>$P13,"Đã thu vượt tổng phải thu; ","")&IF(AND($L13>0,$U13<0),"CẢNH BÁO: ĐƠN NÀY ĐANG LỖ; ",""))) | Y13: =IF(AND($C13<>"",$R13>0),COUNTIFS($C$6:$C13,"<>",$R$6:$R13,">0"),"") | Z13: =IF(AND($H13<>"",N($N13)>0),COUNTIFS($H$6:$H13,"<>",$N$6:$N13,">0"),"") | AA13: =IF(AND($H13<>"",N($N13)=0),COUNTIFS($H$6:$H13,"<>",$N$6:$N13,"<=0"),"") | AB13: =IF($C13="","",IF(COUNTIF($C$6:$C13,$C13)>1,"",MAX($AB$5:AB12)+1)) | AC13: =IF($H13="","",IF(COUNTIF($H$6:$H13,$H13)>1,"",MAX($AC$5:AC12)+1))
A14: =IF($C14="","",COUNTA($C$6:$C14)) | J14: =IF($H14="","",IFERROR(VLOOKUP($H14,'BẢNG GIÁ GỐC'!$A$5:$D$204,3,FALSE()),"")) | L14: =IF($C14="","",N($I14)*N($K14)) | N14: =IF($C14="","",IF($M14="VAT 5%",0.05,IF($M14="VAT 8%",0.08,IF($M14="VAT 10%",0.1,0)))) | O14: =IF($C14="","",$L14*$N14) | P14: =IF($C14="","",$L14+$O14) | R14: =IF($C14="","",MAX(0,$P14-N($Q14))) | S14: =IF(OR($C14="",$P14=0),"",IF(N($Q14)<=0,"Chưa thanh toán",IF(N($Q14)<$P14,"Thanh toán một phần","Đã thanh toán"))) | T14: =IF(OR($C14="",$J14=""),"",N($I14)*$J14) | U14: =IF(OR($C14="",$T14=""),"",$L14-$T14) | V14: =IF(OR($U14="",$L14=0),"",$U14/$L14) | X14: =IF($C14="","",IF(AND($H14="",N($I14)=0,N($K14)=0),"Dòng chỉ lưu thông tin khách (chưa có đơn); ",IF($B14="","Thiếu ngày đặt; ","")&IF($H14="","Thiếu tên sản phẩm; ",IF($J14="","Sản phẩm chưa có trong BẢNG GIÁ GỐC; ",""))&IF(N($I14)<=0,"Thiếu số lượng; ","")&IF(N($K14)<=0,"Thiếu giá bán; ","")&IF(AND($N14>0,$F14=""),"Khách lấy VAT thiếu mã số thuế; ","")&IF(N($Q14)>$P14,"Đã thu vượt tổng phải thu; ","")&IF(AND($L14>0,$U14<0),"CẢNH BÁO: ĐƠN NÀY ĐANG LỖ; ",""))) | Y14: =IF(AND($C14<>"",$R14>0),COUNTIFS($C$6:$C14,"<>",$R$6:$R14,">0"),"") | Z14: =IF(AND($H14<>"",N($N14)>0),COUNTIFS($H$6:$H14,"<>",$N$6:$N14,">0"),"") | AA14: =IF(AND($H14<>"",N($N14)=0),COUNTIFS($H$6:$H14,"<>",$N$6:$N14,"<=0"),"") | AB14: =IF($C14="","",IF(COUNTIF($C$6:$C14,$C14)>1,"",MAX($AB$5:AB13)+1)) | AC14: =IF($H14="","",IF(COUNTIF($H$6:$H14,$H14)>1,"",MAX($AC$5:AC13)+1))
A15: =IF($C15="","",COUNTA($C$6:$C15)) | J15: =IF($H15="","",IFERROR(VLOOKUP($H15,'BẢNG GIÁ GỐC'!$A$5:$D$204,3,FALSE()),"")) | L15: =IF($C15="","",N($I15)*N($K15)) | N15: =IF($C15="","",IF($M15="VAT 5%",0.05,IF($M15="VAT 8%",0.08,IF($M15="VAT 10%",0.1,0)))) | O15: =IF($C15="","",$L15*$N15) | P15: =IF($C15="","",$L15+$O15) | R15: =IF($C15="","",MAX(0,$P15-N($Q15))) | S15: =IF(OR($C15="",$P15=0),"",IF(N($Q15)<=0,"Chưa thanh toán",IF(N($Q15)<$P15,"Thanh toán một phần","Đã thanh toán"))) | T15: =IF(OR($C15="",$J15=""),"",N($I15)*$J15) | U15: =IF(OR($C15="",$T15=""),"",$L15-$T15) | V15: =IF(OR($U15="",$L15=0),"",$U15/$L15) | X15: =IF($C15="","",IF(AND($H15="",N($I15)=0,N($K15)=0),"Dòng chỉ lưu thông tin khách (chưa có đơn); ",IF($B15="","Thiếu ngày đặt; ","")&IF($H15="","Thiếu tên sản phẩm; ",IF($J15="","Sản phẩm chưa có trong BẢNG GIÁ GỐC; ",""))&IF(N($I15)<=0,"Thiếu số lượng; ","")&IF(N($K15)<=0,"Thiếu giá bán; ","")&IF(AND($N15>0,$F15=""),"Khách lấy VAT thiếu mã số thuế; ","")&IF(N($Q15)>$P15,"Đã thu vượt tổng phải thu; ","")&IF(AND($L15>0,$U15<0),"CẢNH BÁO: ĐƠN NÀY ĐANG LỖ; ",""))) | Y15: =IF(AND($C15<>"",$R15>0),COUNTIFS($C$6:$C15,"<>",$R$6:$R15,">0"),"") | Z15: =IF(AND($H15<>"",N($N15)>0),COUNTIFS($H$6:$H15,"<>",$N$6:$N15,">0"),"") | AA15: =IF(AND($H15<>"",N($N15)=0),COUNTIFS($H$6:$H15,"<>",$N$6:$N15,"<=0"),"") | AB15: =IF($C15="","",IF(COUNTIF($C$6:$C15,$C15)>1,"",MAX($AB$5:AB14)+1)) | AC15: =IF($H15="","",IF(COUNTIF($H$6:$H15,$H15)>1,"",MAX($AC$5:AC14)+1))
A16: =IF($C16="","",COUNTA($C$6:$C16)) | J16: =IF($H16="","",IFERROR(VLOOKUP($H16,'BẢNG GIÁ GỐC'!$A$5:$D$204,3,FALSE()),"")) | L16: =IF($C16="","",N($I16)*N($K16)) | N16: =IF($C16="","",IF($M16="VAT 5%",0.05,IF($M16="VAT 8%",0.08,IF($M16="VAT 10%",0.1,0)))) | O16: =IF($C16="","",$L16*$N16) | P16: =IF($C16="","",$L16+$O16) | R16: =IF($C16="","",MAX(0,$P16-N($Q16))) | S16: =IF(OR($C16="",$P16=0),"",IF(N($Q16)<=0,"Chưa thanh toán",IF(N($Q16)<$P16,"Thanh toán một phần","Đã thanh toán"))) | T16: =IF(OR($C16="",$J16=""),"",N($I16)*$J16) | U16: =IF(OR($C16="",$T16=""),"",$L16-$T16) | V16: =IF(OR($U16="",$L16=0),"",$U16/$L16) | X16: =IF($C16="","",IF(AND($H16="",N($I16)=0,N($K16)=0),"Dòng chỉ lưu thông tin khách (chưa có đơn); ",IF($B16="","Thiếu ngày đặt; ","")&IF($H16="","Thiếu tên sản phẩm; ",IF($J16="","Sản phẩm chưa có trong BẢNG GIÁ GỐC; ",""))&IF(N($I16)<=0,"Thiếu số lượng; ","")&IF(N($K16)<=0,"Thiếu giá bán; ","")&IF(AND($N16>0,$F16=""),"Khách lấy VAT thiếu mã số thuế; ","")&IF(N($Q16)>$P16,"Đã thu vượt tổng phải thu; ","")&IF(AND($L16>0,$U16<0),"CẢNH BÁO: ĐƠN NÀY ĐANG LỖ; ",""))) | Y16: =IF(AND($C16<>"",$R16>0),COUNTIFS($C$6:$C16,"<>",$R$6:$R16,">0"),"") | Z16: =IF(AND($H16<>"",N($N16)>0),COUNTIFS($H$6:$H16,"<>",$N$6:$N16,">0"),"") | AA16: =IF(AND($H16<>"",N($N16)=0),COUNTIFS($H$6:$H16,"<>",$N$6:$N16,"<=0"),"") | AB16: =IF($C16="","",IF(COUNTIF($C$6:$C16,$C16)>1,"",MAX($AB$5:AB15)+1)) | AC16: =IF($H16="","",IF(COUNTIF($H$6:$H16,$H16)>1,"",MAX($AC$5:AC15)+1))
A17: =IF($C17="","",COUNTA($C$6:$C17)) | J17: =IF($H17="","",IFERROR(VLOOKUP($H17,'BẢNG GIÁ GỐC'!$A$5:$D$204,3,FALSE()),"")) | L17: =IF($C17="","",N($I17)*N($K17)) | N17: =IF($C17="","",IF($M17="VAT 5%",0.05,IF($M17="VAT 8%",0.08,IF($M17="VAT 10%",0.1,0)))) | O17: =IF($C17="","",$L17*$N17) | P17: =IF($C17="","",$L17+$O17) | R17: =IF($C17="","",MAX(0,$P17-N($Q17))) | S17: =IF(OR($C17="",$P17=0),"",IF(N($Q17)<=0,"Chưa thanh toán",IF(N($Q17)<$P17,"Thanh toán một phần","Đã thanh toán"))) | T17: =IF(OR($C17="",$J17=""),"",N($I17)*$J17) | U17: =IF(OR($C17="",$T17=""),"",$L17-$T17) | V17: =IF(OR($U17="",$L17=0),"",$U17/$L17) | X17: =IF($C17="","",IF(AND($H17="",N($I17)=0,N($K17)=0),"Dòng chỉ lưu thông tin khách (chưa có đơn); ",IF($B17="","Thiếu ngày đặt; ","")&IF($H17="","Thiếu tên sản phẩm; ",IF($J17="","Sản phẩm chưa có trong BẢNG GIÁ GỐC; ",""))&IF(N($I17)<=0,"Thiếu số lượng; ","")&IF(N($K17)<=0,"Thiếu giá bán; ","")&IF(AND($N17>0,$F17=""),"Khách lấy VAT thiếu mã số thuế; ","")&IF(N($Q17)>$P17,"Đã thu vượt tổng phải thu; ","")&IF(AND($L17>0,$U17<0),"CẢNH BÁO: ĐƠN NÀY ĐANG LỖ; ",""))) | Y17: =IF(AND($C17<>"",$R17>0),COUNTIFS($C$6:$C17,"<>",$R$6:$R17,">0"),"") | Z17: =IF(AND($H17<>"",N($N17)>0),COUNTIFS($H$6:$H17,"<>",$N$6:$N17,">0"),"") | AA17: =IF(AND($H17<>"",N($N17)=0),COUNTIFS($H$6:$H17,"<>",$N$6:$N17,"<=0"),"") | AB17: =IF($C17="","",IF(COUNTIF($C$6:$C17,$C17)>1,"",MAX($AB$5:AB16)+1)) | AC17: =IF($H17="","",IF(COUNTIF($H$6:$H17,$H17)>1,"",MAX($AC$5:AC16)+1))
A18: =IF($C18="","",COUNTA($C$6:$C18)) | J18: =IF($H18="","",IFERROR(VLOOKUP($H18,'BẢNG GIÁ GỐC'!$A$5:$D$204,3,FALSE()),"")) | L18: =IF($C18="","",N($I18)*N($K18)) | N18: =IF($C18="","",IF($M18="VAT 5%",0.05,IF($M18="VAT 8%",0.08,IF($M18="VAT 10%",0.1,0)))) | O18: =IF($C18="","",$L18*$N18) | P18: =IF($C18="","",$L18+$O18) | R18: =IF($C18="","",MAX(0,$P18-N($Q18))) | S18: =IF(OR($C18="",$P18=0),"",IF(N($Q18)<=0,"Chưa thanh toán",IF(N($Q18)<$P18,"Thanh toán một phần","Đã thanh toán"))) | T18: =IF(OR($C18="",$J18=""),"",N($I18)*$J18) | U18: =IF(OR($C18="",$T18=""),"",$L18-$T18) | V18: =IF(OR($U18="",$L18=0),"",$U18/$L18) | X18: =IF($C18="","",IF(AND($H18="",N($I18)=0,N($K18)=0),"Dòng chỉ lưu thông tin khách (chưa có đơn); ",IF($B18="","Thiếu ngày đặt; ","")&IF($H18="","Thiếu tên sản phẩm; ",IF($J18="","Sản phẩm chưa có trong BẢNG GIÁ GỐC; ",""))&IF(N($I18)<=0,"Thiếu số lượng; ","")&IF(N($K18)<=0,"Thiếu giá bán; ","")&IF(AND($N18>0,$F18=""),"Khách lấy VAT thiếu mã số thuế; ","")&IF(N($Q18)>$P18,"Đã thu vượt tổng phải thu; ","")&IF(AND($L18>0,$U18<0),"CẢNH BÁO: ĐƠN NÀY ĐANG LỖ; ",""))) | Y18: =IF(AND($C18<>"",$R18>0),COUNTIFS($C$6:$C18,"<>",$R$6:$R18,">0"),"") | Z18: =IF(AND($H18<>"",N($N18)>0),COUNTIFS($H$6:$H18,"<>",$N$6:$N18,">0"),"") | AA18: =IF(AND($H18<>"",N($N18)=0),COUNTIFS($H$6:$H18,"<>",$N$6:$N18,"<=0"),"") | AB18: =IF($C18="","",IF(COUNTIF($C$6:$C18,$C18)>1,"",MAX($AB$5:AB17)+1)) | AC18: =IF($H18="","",IF(COUNTIF($H$6:$H18,$H18)>1,"",MAX($AC$5:AC17)+1))
A19: =IF($C19="","",COUNTA($C$6:$C19)) | J19: =IF($H19="","",IFERROR(VLOOKUP($H19,'BẢNG GIÁ GỐC'!$A$5:$D$204,3,FALSE()),"")) | L19: =IF($C19="","",N($I19)*N($K19)) | N19: =IF($C19="","",IF($M19="VAT 5%",0.05,IF($M19="VAT 8%",0.08,IF($M19="VAT 10%",0.1,0)))) | O19: =IF($C19="","",$L19*$N19) | P19: =IF($C19="","",$L19+$O19) | R19: =IF($C19="","",MAX(0,$P19-N($Q19))) | S19: =IF(OR($C19="",$P19=0),"",IF(N($Q19)<=0,"Chưa thanh toán",IF(N($Q19)<$P19,"Thanh toán một phần","Đã thanh toán"))) | T19: =IF(OR($C19="",$J19=""),"",N($I19)*$J19) | U19: =IF(OR($C19="",$T19=""),"",$L19-$T19) | V19: =IF(OR($U19="",$L19=0),"",$U19/$L19) | X19: =IF($C19="","",IF(AND($H19="",N($I19)=0,N($K19)=0),"Dòng chỉ lưu thông tin khách (chưa có đơn); ",IF($B19="","Thiếu ngày đặt; ","")&IF($H19="","Thiếu tên sản phẩm; ",IF($J19="","Sản phẩm chưa có trong BẢNG GIÁ GỐC; ",""))&IF(N($I19)<=0,"Thiếu số lượng; ","")&IF(N($K19)<=0,"Thiếu giá bán; ","")&IF(AND($N19>0,$F19=""),"Khách lấy VAT thiếu mã số thuế; ","")&IF(N($Q19)>$P19,"Đã thu vượt tổng phải thu; ","")&IF(AND($L19>0,$U19<0),"CẢNH BÁO: ĐƠN NÀY ĐANG LỖ; ",""))) | Y19: =IF(AND($C19<>"",$R19>0),COUNTIFS($C$6:$C19,"<>",$R$6:$R19,">0"),"") | Z19: =IF(AND($H19<>"",N($N19)>0),COUNTIFS($H$6:$H19,"<>",$N$6:$N19,">0"),"") | AA19: =IF(AND($H19<>"",N($N19)=0),COUNTIFS($H$6:$H19,"<>",$N$6:$N19,"<=0"),"") | AB19: =IF($C19="","",IF(COUNTIF($C$6:$C19,$C19)>1,"",MAX($AB$5:AB18)+1)) | AC19: =IF($H19="","",IF(COUNTIF($H$6:$H19,$H19)>1,"",MAX($AC$5:AC18)+1))
A20: =IF($C20="","",COUNTA($C$6:$C20)) | J20: =IF($H20="","",IFERROR(VLOOKUP($H20,'BẢNG GIÁ GỐC'!$A$5:$D$204,3,FALSE()),"")) | L20: =IF($C20="","",N($I20)*N($K20)) | N20: =IF($C20="","",IF($M20="VAT 5%",0.05,IF($M20="VAT 8%",0.08,IF($M20="VAT 10%",0.1,0)))) | O20: =IF($C20="","",$L20*$N20) | P20: =IF($C20="","",$L20+$O20) | R20: =IF($C20="","",MAX(0,$P20-N($Q20))) | S20: =IF(OR($C20="",$P20=0),"",IF(N($Q20)<=0,"Chưa thanh toán",IF(N($Q20)<$P20,"Thanh toán một phần","Đã thanh toán"))) | T20: =IF(OR($C20="",$J20=""),"",N($I20)*$J20) | U20: =IF(OR($C20="",$T20=""),"",$L20-$T20) | V20: =IF(OR($U20="",$L20=0),"",$U20/$L20) | X20: =IF($C20="","",IF(AND($H20="",N($I20)=0,N($K20)=0),"Dòng chỉ lưu thông tin khách (chưa có đơn); ",IF($B20="","Thiếu ngày đặt; ","")&IF($H20="","Thiếu tên sản phẩm; ",IF($J20="","Sản phẩm chưa có trong BẢNG GIÁ GỐC; ",""))&IF(N($I20)<=0,"Thiếu số lượng; ","")&IF(N($K20)<=0,"Thiếu giá bán; ","")&IF(AND($N20>0,$F20=""),"Khách lấy VAT thiếu mã số thuế; ","")&IF(N($Q20)>$P20,"Đã thu vượt tổng phải thu; ","")&IF(AND($L20>0,$U20<0),"CẢNH BÁO: ĐƠN NÀY ĐANG LỖ; ",""))) | Y20: =IF(AND($C20<>"",$R20>0),COUNTIFS($C$6:$C20,"<>",$R$6:$R20,">0"),"") | Z20: =IF(AND($H20<>"",N($N20)>0),COUNTIFS($H$6:$H20,"<>",$N$6:$N20,">0"),"") | AA20: =IF(AND($H20<>"",N($N20)=0),COUNTIFS($H$6:$H20,"<>",$N$6:$N20,"<=0"),"") | AB20: =IF($C20="","",IF(COUNTIF($C$6:$C20,$C20)>1,"",MAX($AB$5:AB19)+1)) | AC20: =IF($H20="","",IF(COUNTIF($H$6:$H20,$H20)>1,"",MAX($AC$5:AC19)+1))
A21: =IF($C21="","",COUNTA($C$6:$C21)) | J21: =IF($H21="","",IFERROR(VLOOKUP($H21,'BẢNG GIÁ GỐC'!$A$5:$D$204,3,FALSE()),"")) | L21: =IF($C21="","",N($I21)*N($K21)) | N21: =IF($C21="","",IF($M21="VAT 5%",0.05,IF($M21="VAT 8%",0.08,IF($M21="VAT 10%",0.1,0)))) | O21: =IF($C21="","",$L21*$N21) | P21: =IF($C21="","",$L21+$O21) | R21: =IF($C21="","",MAX(0,$P21-N($Q21))) | S21: =IF(OR($C21="",$P21=0),"",IF(N($Q21)<=0,"Chưa thanh toán",IF(N($Q21)<$P21,"Thanh toán một phần","Đã thanh toán"))) | T21: =IF(OR($C21="",$J21=""),"",N($I21)*$J21) | U21: =IF(OR($C21="",$T21=""),"",$L21-$T21) | V21: =IF(OR($U21="",$L21=0),"",$U21/$L21) | X21: =IF($C21="","",IF(AND($H21="",N($I21)=0,N($K21)=0),"Dòng chỉ lưu thông tin khách (chưa có đơn); ",IF($B21="","Thiếu ngày đặt; ","")&IF($H21="","Thiếu tên sản phẩm; ",IF($J21="","Sản phẩm chưa có trong BẢNG GIÁ GỐC; ",""))&IF(N($I21)<=0,"Thiếu số lượng; ","")&IF(N($K21)<=0,"Thiếu giá bán; ","")&IF(AND($N21>0,$F21=""),"Khách lấy VAT thiếu mã số thuế; ","")&IF(N($Q21)>$P21,"Đã thu vượt tổng phải thu; ","")&IF(AND($L21>0,$U21<0),"CẢNH BÁO: ĐƠN NÀY ĐANG LỖ; ",""))) | Y21: =IF(AND($C21<>"",$R21>0),COUNTIFS($C$6:$C21,"<>",$R$6:$R21,">0"),"") | Z21: =IF(AND($H21<>"",N($N21)>0),COUNTIFS($H$6:$H21,"<>",$N$6:$N21,">0"),"") | AA21: =IF(AND($H21<>"",N($N21)=0),COUNTIFS($H$6:$H21,"<>",$N$6:$N21,"<=0"),"") | AB21: =IF($C21="","",IF(COUNTIF($C$6:$C21,$C21)>1,"",MAX($AB$5:AB20)+1)) | AC21: =IF($H21="","",IF(COUNTIF($H$6:$H21,$H21)>1,"",MAX($AC$5:AC20)+1))
A22: =IF($C22="","",COUNTA($C$6:$C22)) | J22: =IF($H22="","",IFERROR(VLOOKUP($H22,'BẢNG GIÁ GỐC'!$A$5:$D$204,3,FALSE()),"")) | L22: =IF($C22="","",N($I22)*N($K22)) | N22: =IF($C22="","",IF($M22="VAT 5%",0.05,IF($M22="VAT 8%",0.08,IF($M22="VAT 10%",0.1,0)))) | O22: =IF($C22="","",$L22*$N22) | P22: =IF($C22="","",$L22+$O22) | R22: =IF($C22="","",MAX(0,$P22-N($Q22))) | S22: =IF(OR($C22="",$P22=0),"",IF(N($Q22)<=0,"Chưa thanh toán",IF(N($Q22)<$P22,"Thanh toán một phần","Đã thanh toán"))) | T22: =IF(OR($C22="",$J22=""),"",N($I22)*$J22) | U22: =IF(OR($C22="",$T22=""),"",$L22-$T22) | V22: =IF(OR($U22="",$L22=0),"",$U22/$L22) | X22: =IF($C22="","",IF(AND($H22="",N($I22)=0,N($K22)=0),"Dòng chỉ lưu thông tin khách (chưa có đơn); ",IF($B22="","Thiếu ngày đặt; ","")&IF($H22="","Thiếu tên sản phẩm; ",IF($J22="","Sản phẩm chưa có trong BẢNG GIÁ GỐC; ",""))&IF(N($I22)<=0,"Thiếu số lượng; ","")&IF(N($K22)<=0,"Thiếu giá bán; ","")&IF(AND($N22>0,$F22=""),"Khách lấy VAT thiếu mã số thuế; ","")&IF(N($Q22)>$P22,"Đã thu vượt tổng phải thu; ","")&IF(AND($L22>0,$U22<0),"CẢNH BÁO: ĐƠN NÀY ĐANG LỖ; ",""))) | Y22: =IF(AND($C22<>"",$R22>0),COUNTIFS($C$6:$C22,"<>",$R$6:$R22,">0"),"") | Z22: =IF(AND($H22<>"",N($N22)>0),COUNTIFS($H$6:$H22,"<>",$N$6:$N22,">0"),"") | AA22: =IF(AND($H22<>"",N($N22)=0),COUNTIFS($H$6:$H22,"<>",$N$6:$N22,"<=0"),"") | AB22: =IF($C22="","",IF(COUNTIF($C$6:$C22,$C22)>1,"",MAX($AB$5:AB21)+1)) | AC22: =IF($H22="","",IF(COUNTIF($H$6:$H22,$H22)>1,"",MAX($AC$5:AC21)+1))
A23: =IF($C23="","",COUNTA($C$6:$C23)) | J23: =IF($H23="","",IFERROR(VLOOKUP($H23,'BẢNG GIÁ GỐC'!$A$5:$D$204,3,FALSE()),"")) | L23: =IF($C23="","",N($I23)*N($K23)) | N23: =IF($C23="","",IF($M23="VAT 5%",0.05,IF($M23="VAT 8%",0.08,IF($M23="VAT 10%",0.1,0)))) | O23: =IF($C23="","",$L23*$N23) | P23: =IF($C23="","",$L23+$O23) | R23: =IF($C23="","",MAX(0,$P23-N($Q23))) | S23: =IF(OR($C23="",$P23=0),"",IF(N($Q23)<=0,"Chưa thanh toán",IF(N($Q23)<$P23,"Thanh toán một phần","Đã thanh toán"))) | T23: =IF(OR($C23="",$J23=""),"",N($I23)*$J23) | U23: =IF(OR($C23="",$T23=""),"",$L23-$T23) | V23: =IF(OR($U23="",$L23=0),"",$U23/$L23) | X23: =IF($C23="","",IF(AND($H23="",N($I23)=0,N($K23)=0),"Dòng chỉ lưu thông tin khách (chưa có đơn); ",IF($B23="","Thiếu ngày đặt; ","")&IF($H23="","Thiếu tên sản phẩm; ",IF($J23="","Sản phẩm chưa có trong BẢNG GIÁ GỐC; ",""))&IF(N($I23)<=0,"Thiếu số lượng; ","")&IF(N($K23)<=0,"Thiếu giá bán; ","")&IF(AND($N23>0,$F23=""),"Khách lấy VAT thiếu mã số thuế; ","")&IF(N($Q23)>$P23,"Đã thu vượt tổng phải thu; ","")&IF(AND($L23>0,$U23<0),"CẢNH BÁO: ĐƠN NÀY ĐANG LỖ; ",""))) | Y23: =IF(AND($C23<>"",$R23>0),COUNTIFS($C$6:$C23,"<>",$R$6:$R23,">0"),"") | Z23: =IF(AND($H23<>"",N($N23)>0),COUNTIFS($H$6:$H23,"<>",$N$6:$N23,">0"),"") | AA23: =IF(AND($H23<>"",N($N23)=0),COUNTIFS($H$6:$H23,"<>",$N$6:$N23,"<=0"),"") | AB23: =IF($C23="","",IF(COUNTIF($C$6:$C23,$C23)>1,"",MAX($AB$5:AB22)+1)) | AC23: =IF($H23="","",IF(COUNTIF($H$6:$H23,$H23)>1,"",MAX($AC$5:AC22)+1))
... A505: =IF($C505="","",COUNTA($C$6:$C505)) | J505: =IF($H505="","",IFERROR(VLOOKUP($H505,'BẢNG GIÁ GỐC'!$A$5:$D$204,3,FALSE()),"")) | L505: =IF($C505="","",N($I505)*N($K505)) | N505: =IF($C505="","",IF($M505="VAT 5%",0.05,IF($M505="VAT 8%",0.08,IF($M505="VAT 10%",0.1,0)))) | O505: =IF($C505="","",$L505*$N505) | P505: =IF($C505="","",$L505+$O505) | R505: =IF($C505="","",MAX(0,$P505-N($Q505))) | S505: =IF(OR($C505="",$P505=0),"",IF(N($Q505)<=0,"Chưa thanh toán",IF(N($Q505)<$P505,"Thanh toán một phần","Đã thanh toán"))) | T505: =IF(OR($C505="",$J505=""),"",N($I505)*$J505) | U505: =IF(OR($C505="",$T505=""),"",$L505-$T505) | V505: =IF(OR($U505="",$L505=0),"",$U505/$L505) | X505: =IF($C505="","",IF(AND($H505="",N($I505)=0,N($K505)=0),"Dòng chỉ lưu thông tin khách (chưa có đơn); ",IF($B505="","Thiếu ngày đặt; ","")&IF($H505="","Thiếu tên sản phẩm; ",IF($J505="","Sản phẩm chưa có trong BẢNG GIÁ GỐC; ",""))&IF(N($I505)<=0,"Thiếu số lượng; ","")&IF(N($K505)<=0,"Thiếu giá bán; ","")&IF(AND($N505>0,$F505=""),"Khách lấy VAT thiếu mã số thuế; ","")&IF(N($Q505)>$P505,"Đã thu vượt tổng phải thu; ","")&IF(AND($L505>0,$U505<0),"CẢNH BÁO: ĐƠN NÀY ĐANG LỖ; ",""))) | Y505: =IF(AND($C505<>"",$R505>0),COUNTIFS($C$6:$C505,"<>",$R$6:$R505,">0"),"") | Z505: =IF(AND($H505<>"",N($N505)>0),COUNTIFS($H$6:$H505,"<>",$N$6:$N505,">0"),"") | AA505: =IF(AND($H505<>"",N($N505)=0),COUNTIFS($H$6:$H505,"<>",$N$6:$N505,"<=0"),"") | AB505: =IF($C505="","",IF(COUNTIF($C$6:$C505,$C505)>1,"",MAX($AB$5:AB504)+1)) | AC505: =IF($H505="","",IF(COUNTIF($H$6:$H505,$H505)>1,"",MAX($AC$5:AC504)+1))

Sheet BÁO CÁO DOANH THU
A1: BÁO CÁO DOANH THU THEO THÁNG (TỰ ĐỘNG)
A2: Toàn bộ số liệu lấy từ sheet NHẬP ĐƠN HÀNG. Chỉ được sửa ô NĂM màu vàng.
A3: NĂM: | B3: 2026 | C3: ← đổi năm ở ô vàng này, cả bảng tự cập nhật
A5: THÁNG | B5: SỐ ĐƠN | C5: TIỀN HÀNG (đ) | D5: TIỀN VAT (đ) | E5: TỔNG PHẢI THU (đ) | F5: ĐÃ THU (đ) | G5: CÒN NỢ (đ) | H5: TỔNG VỐN (đ) | I5: LÃI / LỖ (đ) | J5: % LÃI
A6: =DATE($B$3,$M6,1) -> 46023 | B6: =COUNTIFS('NHẬP ĐƠN HÀNG'!$B$6:$B$505,">="&$A6,'NHẬP ĐƠN HÀNG'!$B$6:$B$505,"<"&DATE($B$3,$M6+1,1),'NHẬP ĐƠN HÀNG'!$C$6:$C$505,"<>") -> 0 | C6: =SUMIFS('NHẬP ĐƠN HÀNG'!$L$6:$L$505,'NHẬP ĐƠN HÀNG'!$B$6:$B$505,">="&$A6,'NHẬP ĐƠN HÀNG'!$B$6:$B$505,"<"&DATE($B$3,$M6+1,1)) -> 0 | D6: =SUMIFS('NHẬP ĐƠN HÀNG'!$O$6:$O$505,'NHẬP ĐƠN HÀNG'!$B$6:$B$505,">="&$A6,'NHẬP ĐƠN HÀNG'!$B$6:$B$505,"<"&DATE($B$3,$M6+1,1)) -> 0 | E6: =SUMIFS('NHẬP ĐƠN HÀNG'!$P$6:$P$505,'NHẬP ĐƠN HÀNG'!$B$6:$B$505,">="&$A6,'NHẬP ĐƠN HÀNG'!$B$6:$B$505,"<"&DATE($B$3,$M6+1,1)) -> 0 | F6: =SUMIFS('NHẬP ĐƠN HÀNG'!$Q$6:$Q$505,'NHẬP ĐƠN HÀNG'!$B$6:$B$505,">="&$A6,'NHẬP ĐƠN HÀNG'!$B$6:$B$505,"<"&DATE($B$3,$M6+1,1)) -> 0 | G6: =SUMIFS('NHẬP ĐƠN HÀNG'!$R$6:$R$505,'NHẬP ĐƠN HÀNG'!$B$6:$B$505,">="&$A6,'NHẬP ĐƠN HÀNG'!$B$6:$B$505,"<"&DATE($B$3,$M6+1,1)) -> 0 | H6: =SUMIFS('NHẬP ĐƠN HÀNG'!$T$6:$T$505,'NHẬP ĐƠN HÀNG'!$B$6:$B$505,">="&$A6,'NHẬP ĐƠN HÀNG'!$B$6:$B$505,"<"&DATE($B$3,$M6+1,1)) -> 0 | I6: =SUMIFS('NHẬP ĐƠN HÀNG'!$U$6:$U$505,'NHẬP ĐƠN HÀNG'!$B$6:$B$505,">="&$A6,'NHẬP ĐƠN HÀNG'!$B$6:$B$505,"<"&DATE($B$3,$M6+1,1)) -> 0 | J6: =IF($C6=0,"",$I6/$C6) | M6: 1
A7: =DATE($B$3,$M7,1) -> 46054 | B7: =COUNTIFS('NHẬP ĐƠN HÀNG'!$B$6:$B$505,">="&$A7,'NHẬP ĐƠN HÀNG'!$B$6:$B$505,"<"&DATE($B$3,$M7+1,1),'NHẬP ĐƠN HÀNG'!$C$6:$C$505,"<>") -> 0 | C7: =SUMIFS('NHẬP ĐƠN HÀNG'!$L$6:$L$505,'NHẬP ĐƠN HÀNG'!$B$6:$B$505,">="&$A7,'NHẬP ĐƠN HÀNG'!$B$6:$B$505,"<"&DATE($B$3,$M7+1,1)) -> 0 | D7: =SUMIFS('NHẬP ĐƠN HÀNG'!$O$6:$O$505,'NHẬP ĐƠN HÀNG'!$B$6:$B$505,">="&$A7,'NHẬP ĐƠN HÀNG'!$B$6:$B$505,"<"&DATE($B$3,$M7+1,1)) -> 0 | E7: =SUMIFS('NHẬP ĐƠN HÀNG'!$P$6:$P$505,'NHẬP ĐƠN HÀNG'!$B$6:$B$505,">="&$A7,'NHẬP ĐƠN HÀNG'!$B$6:$B$505,"<"&DATE($B$3,$M7+1,1)) -> 0 | F7: =SUMIFS('NHẬP ĐƠN HÀNG'!$Q$6:$Q$505,'NHẬP ĐƠN HÀNG'!$B$6:$B$505,">="&$A7,'NHẬP ĐƠN HÀNG'!$B$6:$B$505,"<"&DATE($B$3,$M7+1,1)) -> 0 | G7: =SUMIFS('NHẬP ĐƠN HÀNG'!$R$6:$R$505,'NHẬP ĐƠN HÀNG'!$B$6:$B$505,">="&$A7,'NHẬP ĐƠN HÀNG'!$B$6:$B$505,"<"&DATE($B$3,$M7+1,1)) -> 0 | H7: =SUMIFS('NHẬP ĐƠN HÀNG'!$T$6:$T$505,'NHẬP ĐƠN HÀNG'!$B$6:$B$505,">="&$A7,'NHẬP ĐƠN HÀNG'!$B$6:$B$505,"<"&DATE($B$3,$M7+1,1)) -> 0 | I7: =SUMIFS('NHẬP ĐƠN HÀNG'!$U$6:$U$505,'NHẬP ĐƠN HÀNG'!$B$6:$B$505,">="&$A7,'NHẬP ĐƠN HÀNG'!$B$6:$B$505,"<"&DATE($B$3,$M7+1,1)) -> 0 | J7: =IF($C7=0,"",$I7/$C7) | M7: 2
A8: =DATE($B$3,$M8,1) -> 46082 | B8: =COUNTIFS('NHẬP ĐƠN HÀNG'!$B$6:$B$505,">="&$A8,'NHẬP ĐƠN HÀNG'!$B$6:$B$505,"<"&DATE($B$3,$M8+1,1),'NHẬP ĐƠN HÀNG'!$C$6:$C$505,"<>") -> 0 | C8: =SUMIFS('NHẬP ĐƠN HÀNG'!$L$6:$L$505,'NHẬP ĐƠN HÀNG'!$B$6:$B$505,">="&$A8,'NHẬP ĐƠN HÀNG'!$B$6:$B$505,"<"&DATE($B$3,$M8+1,1)) -> 0 | D8: =SUMIFS('NHẬP ĐƠN HÀNG'!$O$6:$O$505,'NHẬP ĐƠN HÀNG'!$B$6:$B$505,">="&$A8,'NHẬP ĐƠN HÀNG'!$B$6:$B$505,"<"&DATE($B$3,$M8+1,1)) -> 0 | E8: =SUMIFS('NHẬP ĐƠN HÀNG'!$P$6:$P$505,'NHẬP ĐƠN HÀNG'!$B$6:$B$505,">="&$A8,'NHẬP ĐƠN HÀNG'!$B$6:$B$505,"<"&DATE($B$3,$M8+1,1)) -> 0 | F8: =SUMIFS('NHẬP ĐƠN HÀNG'!$Q$6:$Q$505,'NHẬP ĐƠN HÀNG'!$B$6:$B$505,">="&$A8,'NHẬP ĐƠN HÀNG'!$B$6:$B$505,"<"&DATE($B$3,$M8+1,1)) -> 0 | G8: =SUMIFS('NHẬP ĐƠN HÀNG'!$R$6:$R$505,'NHẬP ĐƠN HÀNG'!$B$6:$B$505,">="&$A8,'NHẬP ĐƠN HÀNG'!$B$6:$B$505,"<"&DATE($B$3,$M8+1,1)) -> 0 | H8: =SUMIFS('NHẬP ĐƠN HÀNG'!$T$6:$T$505,'NHẬP ĐƠN HÀNG'!$B$6:$B$505,">="&$A8,'NHẬP ĐƠN HÀNG'!$B$6:$B$505,"<"&DATE($B$3,$M8+1,1)) -> 0 | I8: =SUMIFS('NHẬP ĐƠN HÀNG'!$U$6:$U$505,'NHẬP ĐƠN HÀNG'!$B$6:$B$505,">="&$A8,'NHẬP ĐƠN HÀNG'!$B$6:$B$505,"<"&DATE($B$3,$M8+1,1)) -> 0 | J8: =IF($C8=0,"",$I8/$C8) | M8: 3
A9: =DATE($B$3,$M9,1) -> 46113 | B9: =COUNTIFS('NHẬP ĐƠN HÀNG'!$B$6:$B$505,">="&$A9,'NHẬP ĐƠN HÀNG'!$B$6:$B$505,"<"&DATE($B$3,$M9+1,1),'NHẬP ĐƠN HÀNG'!$C$6:$C$505,"<>") -> 0 | C9: =SUMIFS('NHẬP ĐƠN HÀNG'!$L$6:$L$505,'NHẬP ĐƠN HÀNG'!$B$6:$B$505,">="&$A9,'NHẬP ĐƠN HÀNG'!$B$6:$B$505,"<"&DATE($B$3,$M9+1,1)) -> 0 | D9: =SUMIFS('NHẬP ĐƠN HÀNG'!$O$6:$O$505,'NHẬP ĐƠN HÀNG'!$B$6:$B$505,">="&$A9,'NHẬP ĐƠN HÀNG'!$B$6:$B$505,"<"&DATE($B$3,$M9+1,1)) -> 0 | E9: =SUMIFS('NHẬP ĐƠN HÀNG'!$P$6:$P$505,'NHẬP ĐƠN HÀNG'!$B$6:$B$505,">="&$A9,'NHẬP ĐƠN HÀNG'!$B$6:$B$505,"<"&DATE($B$3,$M9+1,1)) -> 0 | F9: =SUMIFS('NHẬP ĐƠN HÀNG'!$Q$6:$Q$505,'NHẬP ĐƠN HÀNG'!$B$6:$B$505,">="&$A9,'NHẬP ĐƠN HÀNG'!$B$6:$B$505,"<"&DATE($B$3,$M9+1,1)) -> 0 | G9: =SUMIFS('NHẬP ĐƠN HÀNG'!$R$6:$R$505,'NHẬP ĐƠN HÀNG'!$B$6:$B$505,">="&$A9,'NHẬP ĐƠN HÀNG'!$B$6:$B$505,"<"&DATE($B$3,$M9+1,1)) -> 0 | H9: =SUMIFS('NHẬP ĐƠN HÀNG'!$T$6:$T$505,'NHẬP ĐƠN HÀNG'!$B$6:$B$505,">="&$A9,'NHẬP ĐƠN HÀNG'!$B$6:$B$505,"<"&DATE($B$3,$M9+1,1)) -> 0 | I9: =SUMIFS('NHẬP ĐƠN HÀNG'!$U$6:$U$505,'NHẬP ĐƠN HÀNG'!$B$6:$B$505,">="&$A9,'NHẬP ĐƠN HÀNG'!$B$6:$B$505,"<"&DATE($B$3,$M9+1,1)) -> 0 | J9: =IF($C9=0,"",$I9/$C9) | M9: 4
A10: =DATE($B$3,$M10,1) -> 46143 | B10: =COUNTIFS('NHẬP ĐƠN HÀNG'!$B$6:$B$505,">="&$A10,'NHẬP ĐƠN HÀNG'!$B$6:$B$505,"<"&DATE($B$3,$M10+1,1),'NHẬP ĐƠN HÀNG'!$C$6:$C$505,"<>") -> 0 | C10: =SUMIFS('NHẬP ĐƠN HÀNG'!$L$6:$L$505,'NHẬP ĐƠN HÀNG'!$B$6:$B$505,">="&$A10,'NHẬP ĐƠN HÀNG'!$B$6:$B$505,"<"&DATE($B$3,$M10+1,1)) -> 0 | D10: =SUMIFS('NHẬP ĐƠN HÀNG'!$O$6:$O$505,'NHẬP ĐƠN HÀNG'!$B$6:$B$505,">="&$A10,'NHẬP ĐƠN HÀNG'!$B$6:$B$505,"<"&DATE($B$3,$M10+1,1)) -> 0 | E10: =SUMIFS('NHẬP ĐƠN HÀNG'!$P$6:$P$505,'NHẬP ĐƠN HÀNG'!$B$6:$B$505,">="&$A10,'NHẬP ĐƠN HÀNG'!$B$6:$B$505,"<"&DATE($B$3,$M10+1,1)) -> 0 | F10: =SUMIFS('NHẬP ĐƠN HÀNG'!$Q$6:$Q$505,'NHẬP ĐƠN HÀNG'!$B$6:$B$505,">="&$A10,'NHẬP ĐƠN HÀNG'!$B$6:$B$505,"<"&DATE($B$3,$M10+1,1)) -> 0 | G10: =SUMIFS('NHẬP ĐƠN HÀNG'!$R$6:$R$505,'NHẬP ĐƠN HÀNG'!$B$6:$B$505,">="&$A10,'NHẬP ĐƠN HÀNG'!$B$6:$B$505,"<"&DATE($B$3,$M10+1,1)) -> 0 | H10: =SUMIFS('NHẬP ĐƠN HÀNG'!$T$6:$T$505,'NHẬP ĐƠN HÀNG'!$B$6:$B$505,">="&$A10,'NHẬP ĐƠN HÀNG'!$B$6:$B$505,"<"&DATE($B$3,$M10+1,1)) -> 0 | I10: =SUMIFS('NHẬP ĐƠN HÀNG'!$U$6:$U$505,'NHẬP ĐƠN HÀNG'!$B$6:$B$505,">="&$A10,'NHẬP ĐƠN HÀNG'!$B$6:$B$505,"<"&DATE($B$3,$M10+1,1)) -> 0 | J10: =IF($C10=0,"",$I10/$C10) | M10: 5
A11: =DATE($B$3,$M11,1) -> 46174 | B11: =COUNTIFS('NHẬP ĐƠN HÀNG'!$B$6:$B$505,">="&$A11,'NHẬP ĐƠN HÀNG'!$B$6:$B$505,"<"&DATE($B$3,$M11+1,1),'NHẬP ĐƠN HÀNG'!$C$6:$C$505,"<>") -> 0 | C11: =SUMIFS('NHẬP ĐƠN HÀNG'!$L$6:$L$505,'NHẬP ĐƠN HÀNG'!$B$6:$B$505,">="&$A11,'NHẬP ĐƠN HÀNG'!$B$6:$B$505,"<"&DATE($B$3,$M11+1,1)) -> 0 | D11: =SUMIFS('NHẬP ĐƠN HÀNG'!$O$6:$O$505,'NHẬP ĐƠN HÀNG'!$B$6:$B$505,">="&$A11,'NHẬP ĐƠN HÀNG'!$B$6:$B$505,"<"&DATE($B$3,$M11+1,1)) -> 0 | E11: =SUMIFS('NHẬP ĐƠN HÀNG'!$P$6:$P$505,'NHẬP ĐƠN HÀNG'!$B$6:$B$505,">="&$A11,'NHẬP ĐƠN HÀNG'!$B$6:$B$505,"<"&DATE($B$3,$M11+1,1)) -> 0 | F11: =SUMIFS('NHẬP ĐƠN HÀNG'!$Q$6:$Q$505,'NHẬP ĐƠN HÀNG'!$B$6:$B$505,">="&$A11,'NHẬP ĐƠN HÀNG'!$B$6:$B$505,"<"&DATE($B$3,$M11+1,1)) -> 0 | G11: =SUMIFS('NHẬP ĐƠN HÀNG'!$R$6:$R$505,'NHẬP ĐƠN HÀNG'!$B$6:$B$505,">="&$A11,'NHẬP ĐƠN HÀNG'!$B$6:$B$505,"<"&DATE($B$3,$M11+1,1)) -> 0 | H11: =SUMIFS('NHẬP ĐƠN HÀNG'!$T$6:$T$505,'NHẬP ĐƠN HÀNG'!$B$6:$B$505,">="&$A11,'NHẬP ĐƠN HÀNG'!$B$6:$B$505,"<"&DATE($B$3,$M11+1,1)) -> 0 | I11: =SUMIFS('NHẬP ĐƠN HÀNG'!$U$6:$U$505,'NHẬP ĐƠN HÀNG'!$B$6:$B$505,">="&$A11,'NHẬP ĐƠN HÀNG'!$B$6:$B$505,"<"&DATE($B$3,$M11+1,1)) -> 0 | J11: =IF($C11=0,"",$I11/$C11) | M11: 6
A12: =DATE($B$3,$M12,1) -> 46204 | B12: =COUNTIFS('NHẬP ĐƠN HÀNG'!$B$6:$B$505,">="&$A12,'NHẬP ĐƠN HÀNG'!$B$6:$B$505,"<"&DATE($B$3,$M12+1,1),'NHẬP ĐƠN HÀNG'!$C$6:$C$505,"<>") -> 3 | C12: =SUMIFS('NHẬP ĐƠN HÀNG'!$L$6:$L$505,'NHẬP ĐƠN HÀNG'!$B$6:$B$505,">="&$A12,'NHẬP ĐƠN HÀNG'!$B$6:$B$505,"<"&DATE($B$3,$M12+1,1)) -> 14160000 | D12: =SUMIFS('NHẬP ĐƠN HÀNG'!$O$6:$O$505,'NHẬP ĐƠN HÀNG'!$B$6:$B$505,">="&$A12,'NHẬP ĐƠN HÀNG'!$B$6:$B$505,"<"&DATE($B$3,$M12+1,1)) -> 0 | E12: =SUMIFS('NHẬP ĐƠN HÀNG'!$P$6:$P$505,'NHẬP ĐƠN HÀNG'!$B$6:$B$505,">="&$A12,'NHẬP ĐƠN HÀNG'!$B$6:$B$505,"<"&DATE($B$3,$M12+1,1)) -> 14160000 | F12: =SUMIFS('NHẬP ĐƠN HÀNG'!$Q$6:$Q$505,'NHẬP ĐƠN HÀNG'!$B$6:$B$505,">="&$A12,'NHẬP ĐƠN HÀNG'!$B$6:$B$505,"<"&DATE($B$3,$M12+1,1)) -> 6110000 | G12: =SUMIFS('NHẬP ĐƠN HÀNG'!$R$6:$R$505,'NHẬP ĐƠN HÀNG'!$B$6:$B$505,">="&$A12,'NHẬP ĐƠN HÀNG'!$B$6:$B$505,"<"&DATE($B$3,$M12+1,1)) -> 8050000 | H12: =SUMIFS('NHẬP ĐƠN HÀNG'!$T$6:$T$505,'NHẬP ĐƠN HÀNG'!$B$6:$B$505,">="&$A12,'NHẬP ĐƠN HÀNG'!$B$6:$B$505,"<"&DATE($B$3,$M12+1,1)) -> 10150000 | I12: =SUMIFS('NHẬP ĐƠN HÀNG'!$U$6:$U$505,'NHẬP ĐƠN HÀNG'!$B$6:$B$505,">="&$A12,'NHẬP ĐƠN HÀNG'!$B$6:$B$505,"<"&DATE($B$3,$M12+1,1)) -> 4010000 | J12: =IF($C12=0,"",$I12/$C12) -> 0.28319209 | M12: 7
A13: =DATE($B$3,$M13,1) -> 46235 | B13: =COUNTIFS('NHẬP ĐƠN HÀNG'!$B$6:$B$505,">="&$A13,'NHẬP ĐƠN HÀNG'!$B$6:$B$505,"<"&DATE($B$3,$M13+1,1),'NHẬP ĐƠN HÀNG'!$C$6:$C$505,"<>") -> 0 | C13: =SUMIFS('NHẬP ĐƠN HÀNG'!$L$6:$L$505,'NHẬP ĐƠN HÀNG'!$B$6:$B$505,">="&$A13,'NHẬP ĐƠN HÀNG'!$B$6:$B$505,"<"&DATE($B$3,$M13+1,1)) -> 0 | D13: =SUMIFS('NHẬP ĐƠN HÀNG'!$O$6:$O$505,'NHẬP ĐƠN HÀNG'!$B$6:$B$505,">="&$A13,'NHẬP ĐƠN HÀNG'!$B$6:$B$505,"<"&DATE($B$3,$M13+1,1)) -> 0 | E13: =SUMIFS('NHẬP ĐƠN HÀNG'!$P$6:$P$505,'NHẬP ĐƠN HÀNG'!$B$6:$B$505,">="&$A13,'NHẬP ĐƠN HÀNG'!$B$6:$B$505,"<"&DATE($B$3,$M13+1,1)) -> 0 | F13: =SUMIFS('NHẬP ĐƠN HÀNG'!$Q$6:$Q$505,'NHẬP ĐƠN HÀNG'!$B$6:$B$505,">="&$A13,'NHẬP ĐƠN HÀNG'!$B$6:$B$505,"<"&DATE($B$3,$M13+1,1)) -> 0 | G13: =SUMIFS('NHẬP ĐƠN HÀNG'!$R$6:$R$505,'NHẬP ĐƠN HÀNG'!$B$6:$B$505,">="&$A13,'NHẬP ĐƠN HÀNG'!$B$6:$B$505,"<"&DATE($B$3,$M13+1,1)) -> 0 | H13: =SUMIFS('NHẬP ĐƠN HÀNG'!$T$6:$T$505,'NHẬP ĐƠN HÀNG'!$B$6:$B$505,">="&$A13,'NHẬP ĐƠN HÀNG'!$B$6:$B$505,"<"&DATE($B$3,$M13+1,1)) -> 0 | I13: =SUMIFS('NHẬP ĐƠN HÀNG'!$U$6:$U$505,'NHẬP ĐƠN HÀNG'!$B$6:$B$505,">="&$A13,'NHẬP ĐƠN HÀNG'!$B$6:$B$505,"<"&DATE($B$3,$M13+1,1)) -> 0 | J13: =IF($C13=0,"",$I13/$C13) | M13: 8
A14: =DATE($B$3,$M14,1) -> 46266 | B14: =COUNTIFS('NHẬP ĐƠN HÀNG'!$B$6:$B$505,">="&$A14,'NHẬP ĐƠN HÀNG'!$B$6:$B$505,"<"&DATE($B$3,$M14+1,1),'NHẬP ĐƠN HÀNG'!$C$6:$C$505,"<>") -> 0 | C14: =SUMIFS('NHẬP ĐƠN HÀNG'!$L$6:$L$505,'NHẬP ĐƠN HÀNG'!$B$6:$B$505,">="&$A14,'NHẬP ĐƠN HÀNG'!$B$6:$B$505,"<"&DATE($B$3,$M14+1,1)) -> 0 | D14: =SUMIFS('NHẬP ĐƠN HÀNG'!$O$6:$O$505,'NHẬP ĐƠN HÀNG'!$B$6:$B$505,">="&$A14,'NHẬP ĐƠN HÀNG'!$B$6:$B$505,"<"&DATE($B$3,$M14+1,1)) -> 0 | E14: =SUMIFS('NHẬP ĐƠN HÀNG'!$P$6:$P$505,'NHẬP ĐƠN HÀNG'!$B$6:$B$505,">="&$A14,'NHẬP ĐƠN HÀNG'!$B$6:$B$505,"<"&DATE($B$3,$M14+1,1)) -> 0 | F14: =SUMIFS('NHẬP ĐƠN HÀNG'!$Q$6:$Q$505,'NHẬP ĐƠN HÀNG'!$B$6:$B$505,">="&$A14,'NHẬP ĐƠN HÀNG'!$B$6:$B$505,"<"&DATE($B$3,$M14+1,1)) -> 0 | G14: =SUMIFS('NHẬP ĐƠN HÀNG'!$R$6:$R$505,'NHẬP ĐƠN HÀNG'!$B$6:$B$505,">="&$A14,'NHẬP ĐƠN HÀNG'!$B$6:$B$505,"<"&DATE($B$3,$M14+1,1)) -> 0 | H14: =SUMIFS('NHẬP ĐƠN HÀNG'!$T$6:$T$505,'NHẬP ĐƠN HÀNG'!$B$6:$B$505,">="&$A14,'NHẬP ĐƠN HÀNG'!$B$6:$B$505,"<"&DATE($B$3,$M14+1,1)) -> 0 | I14: =SUMIFS('NHẬP ĐƠN HÀNG'!$U$6:$U$505,'NHẬP ĐƠN HÀNG'!$B$6:$B$505,">="&$A14,'NHẬP ĐƠN HÀNG'!$B$6:$B$505,"<"&DATE($B$3,$M14+1,1)) -> 0 | J14: =IF($C14=0,"",$I14/$C14) | M14: 9
A15: =DATE($B$3,$M15,1) -> 46296 | B15: =COUNTIFS('NHẬP ĐƠN HÀNG'!$B$6:$B$505,">="&$A15,'NHẬP ĐƠN HÀNG'!$B$6:$B$505,"<"&DATE($B$3,$M15+1,1),'NHẬP ĐƠN HÀNG'!$C$6:$C$505,"<>") -> 0 | C15: =SUMIFS('NHẬP ĐƠN HÀNG'!$L$6:$L$505,'NHẬP ĐƠN HÀNG'!$B$6:$B$505,">="&$A15,'NHẬP ĐƠN HÀNG'!$B$6:$B$505,"<"&DATE($B$3,$M15+1,1)) -> 0 | D15: =SUMIFS('NHẬP ĐƠN HÀNG'!$O$6:$O$505,'NHẬP ĐƠN HÀNG'!$B$6:$B$505,">="&$A15,'NHẬP ĐƠN HÀNG'!$B$6:$B$505,"<"&DATE($B$3,$M15+1,1)) -> 0 | E15: =SUMIFS('NHẬP ĐƠN HÀNG'!$P$6:$P$505,'NHẬP ĐƠN HÀNG'!$B$6:$B$505,">="&$A15,'NHẬP ĐƠN HÀNG'!$B$6:$B$505,"<"&DATE($B$3,$M15+1,1)) -> 0 | F15: =SUMIFS('NHẬP ĐƠN HÀNG'!$Q$6:$Q$505,'NHẬP ĐƠN HÀNG'!$B$6:$B$505,">="&$A15,'NHẬP ĐƠN HÀNG'!$B$6:$B$505,"<"&DATE($B$3,$M15+1,1)) -> 0 | G15: =SUMIFS('NHẬP ĐƠN HÀNG'!$R$6:$R$505,'NHẬP ĐƠN HÀNG'!$B$6:$B$505,">="&$A15,'NHẬP ĐƠN HÀNG'!$B$6:$B$505,"<"&DATE($B$3,$M15+1,1)) -> 0 | H15: =SUMIFS('NHẬP ĐƠN HÀNG'!$T$6:$T$505,'NHẬP ĐƠN HÀNG'!$B$6:$B$505,">="&$A15,'NHẬP ĐƠN HÀNG'!$B$6:$B$505,"<"&DATE($B$3,$M15+1,1)) -> 0 | I15: =SUMIFS('NHẬP ĐƠN HÀNG'!$U$6:$U$505,'NHẬP ĐƠN HÀNG'!$B$6:$B$505,">="&$A15,'NHẬP ĐƠN HÀNG'!$B$6:$B$505,"<"&DATE($B$3,$M15+1,1)) -> 0 | J15: =IF($C15=0,"",$I15/$C15) | M15: 10
A16: =DATE($B$3,$M16,1) -> 46327 | B16: =COUNTIFS('NHẬP ĐƠN HÀNG'!$B$6:$B$505,">="&$A16,'NHẬP ĐƠN HÀNG'!$B$6:$B$505,"<"&DATE($B$3,$M16+1,1),'NHẬP ĐƠN HÀNG'!$C$6:$C$505,"<>") -> 0 | C16: =SUMIFS('NHẬP ĐƠN HÀNG'!$L$6:$L$505,'NHẬP ĐƠN HÀNG'!$B$6:$B$505,">="&$A16,'NHẬP ĐƠN HÀNG'!$B$6:$B$505,"<"&DATE($B$3,$M16+1,1)) -> 0 | D16: =SUMIFS('NHẬP ĐƠN HÀNG'!$O$6:$O$505,'NHẬP ĐƠN HÀNG'!$B$6:$B$505,">="&$A16,'NHẬP ĐƠN HÀNG'!$B$6:$B$505,"<"&DATE($B$3,$M16+1,1)) -> 0 | E16: =SUMIFS('NHẬP ĐƠN HÀNG'!$P$6:$P$505,'NHẬP ĐƠN HÀNG'!$B$6:$B$505,">="&$A16,'NHẬP ĐƠN HÀNG'!$B$6:$B$505,"<"&DATE($B$3,$M16+1,1)) -> 0 | F16: =SUMIFS('NHẬP ĐƠN HÀNG'!$Q$6:$Q$505,'NHẬP ĐƠN HÀNG'!$B$6:$B$505,">="&$A16,'NHẬP ĐƠN HÀNG'!$B$6:$B$505,"<"&DATE($B$3,$M16+1,1)) -> 0 | G16: =SUMIFS('NHẬP ĐƠN HÀNG'!$R$6:$R$505,'NHẬP ĐƠN HÀNG'!$B$6:$B$505,">="&$A16,'NHẬP ĐƠN HÀNG'!$B$6:$B$505,"<"&DATE($B$3,$M16+1,1)) -> 0 | H16: =SUMIFS('NHẬP ĐƠN HÀNG'!$T$6:$T$505,'NHẬP ĐƠN HÀNG'!$B$6:$B$505,">="&$A16,'NHẬP ĐƠN HÀNG'!$B$6:$B$505,"<"&DATE($B$3,$M16+1,1)) -> 0 | I16: =SUMIFS('NHẬP ĐƠN HÀNG'!$U$6:$U$505,'NHẬP ĐƠN HÀNG'!$B$6:$B$505,">="&$A16,'NHẬP ĐƠN HÀNG'!$B$6:$B$505,"<"&DATE($B$3,$M16+1,1)) -> 0 | J16: =IF($C16=0,"",$I16/$C16) | M16: 11
A17: =DATE($B$3,$M17,1) -> 46357 | B17: =COUNTIFS('NHẬP ĐƠN HÀNG'!$B$6:$B$505,">="&$A17,'NHẬP ĐƠN HÀNG'!$B$6:$B$505,"<"&DATE($B$3,$M17+1,1),'NHẬP ĐƠN HÀNG'!$C$6:$C$505,"<>") -> 0 | C17: =SUMIFS('NHẬP ĐƠN HÀNG'!$L$6:$L$505,'NHẬP ĐƠN HÀNG'!$B$6:$B$505,">="&$A17,'NHẬP ĐƠN HÀNG'!$B$6:$B$505,"<"&DATE($B$3,$M17+1,1)) -> 0 | D17: =SUMIFS('NHẬP ĐƠN HÀNG'!$O$6:$O$505,'NHẬP ĐƠN HÀNG'!$B$6:$B$505,">="&$A17,'NHẬP ĐƠN HÀNG'!$B$6:$B$505,"<"&DATE($B$3,$M17+1,1)) -> 0 | E17: =SUMIFS('NHẬP ĐƠN HÀNG'!$P$6:$P$505,'NHẬP ĐƠN HÀNG'!$B$6:$B$505,">="&$A17,'NHẬP ĐƠN HÀNG'!$B$6:$B$505,"<"&DATE($B$3,$M17+1,1)) -> 0 | F17: =SUMIFS('NHẬP ĐƠN HÀNG'!$Q$6:$Q$505,'NHẬP ĐƠN HÀNG'!$B$6:$B$505,">="&$A17,'NHẬP ĐƠN HÀNG'!$B$6:$B$505,"<"&DATE($B$3,$M17+1,1)) -> 0 | G17: =SUMIFS('NHẬP ĐƠN HÀNG'!$R$6:$R$505,'NHẬP ĐƠN HÀNG'!$B$6:$B$505,">="&$A17,'NHẬP ĐƠN HÀNG'!$B$6:$B$505,"<"&DATE($B$3,$M17+1,1)) -> 0 | H17: =SUMIFS('NHẬP ĐƠN HÀNG'!$T$6:$T$505,'NHẬP ĐƠN HÀNG'!$B$6:$B$505,">="&$A17,'NHẬP ĐƠN HÀNG'!$B$6:$B$505,"<"&DATE($B$3,$M17+1,1)) -> 0 | I17: =SUMIFS('NHẬP ĐƠN HÀNG'!$U$6:$U$505,'NHẬP ĐƠN HÀNG'!$B$6:$B$505,">="&$A17,'NHẬP ĐƠN HÀNG'!$B$6:$B$505,"<"&DATE($B$3,$M17+1,1)) -> 0 | J17: =IF($C17=0,"",$I17/$C17) | M17: 12
A18: TỔNG CẢ NĂM | B18: =SUM(B6:B17) -> 3 | C18: =SUM(C6:C17) -> 14160000 | D18: =SUM(D6:D17) -> 0 | E18: =SUM(E6:E17) -> 14160000 | F18: =SUM(F6:F17) -> 6110000 | G18: =SUM(G6:G17) -> 8050000 | H18: =SUM(H6:H17) -> 10150000 | I18: =SUM(I6:I17) -> 4010000 | J18: =IF($C18=0,"",$I18/$C18) -> 0.28319209
A20: Ghi chú: đơn chưa nhập NGÀY ĐẶT sẽ không được tính vào bất kỳ tháng nào – xem cột CẢNH BÁO ở sheet NHẬP ĐƠN HÀNG để bổ sung.

Sheet LÃI LỖ
A1: BÁO CÁO LÃI – LỖ (TỰ ĐỘNG)
A2: Lãi = TIỀN HÀNG − TỔNG VỐN. Giá vốn lấy từ BẢNG GIÁ GỐC, doanh thu lấy từ NHẬP ĐƠN HÀNG.
A4: A. TỔNG QUAN TOÀN BỘ
A5: TỔNG TIỀN HÀNG (doanh thu chưa VAT) | B5: =SUM('NHẬP ĐƠN HÀNG'!$L$6:$L$505) -> 15300000
A6: TỔNG VỐN (giá gốc) | B6: =SUM('NHẬP ĐƠN HÀNG'!$T$6:$T$505) -> 10950000
A7: LÃI / LỖ | B7: =SUM('NHẬP ĐƠN HÀNG'!$U$6:$U$505) -> 4350000
A8: % LÃI | B8: =IF($B5=0,"",$B7/$B5) -> 0.28431373
A9: TỔNG TIỀN VAT | B9: =SUM('NHẬP ĐƠN HÀNG'!$O$6:$O$505) -> 91200
A10: TỔNG PHẢI THU (gồm VAT) | B10: =SUM('NHẬP ĐƠN HÀNG'!$P$6:$P$505) -> 15391200
A11: KHÁCH ĐÃ THANH TOÁN | B11: =SUM('NHẬP ĐƠN HÀNG'!$Q$6:$Q$505) -> 6110000
A12: KHÁCH CÒN NỢ | B12: =SUM('NHẬP ĐƠN HÀNG'!$R$6:$R$505) -> 9281200
A13: SỐ ĐƠN ĐANG LỖ | B13: =COUNTIFS('NHẬP ĐƠN HÀNG'!$L$6:$L$505,">0",'NHẬP ĐƠN HÀNG'!$U$6:$U$505,"<0") -> 0
A15: B. LÃI – LỖ THEO THÁNG (theo năm đang chọn ở sheet BÁO CÁO DOANH THU)
A16: THÁNG | B16: TIỀN HÀNG (đ) | C16: TỔNG VỐN (đ) | D16: LÃI / LỖ (đ) | E16: % LÃI | F16: SỐ ĐƠN
A17: ='BÁO CÁO DOANH THU'!$A$6 -> 46023 | B17: ='BÁO CÁO DOANH THU'!$C$6 -> 0 | C17: ='BÁO CÁO DOANH THU'!$H$6 -> 0 | D17: ='BÁO CÁO DOANH THU'!$I$6 -> 0 | E17: =IF($B17=0,"",$D17/$B17) | F17: ='BÁO CÁO DOANH THU'!$B$6 -> 0
A18: ='BÁO CÁO DOANH THU'!$A$7 -> 46054 | B18: ='BÁO CÁO DOANH THU'!$C$7 -> 0 | C18: ='BÁO CÁO DOANH THU'!$H$7 -> 0 | D18: ='BÁO CÁO DOANH THU'!$I$7 -> 0 | E18: =IF($B18=0,"",$D18/$B18) | F18: ='BÁO CÁO DOANH THU'!$B$7 -> 0
A19: ='BÁO CÁO DOANH THU'!$A$8 -> 46082 | B19: ='BÁO CÁO DOANH THU'!$C$8 -> 0 | C19: ='BÁO CÁO DOANH THU'!$H$8 -> 0 | D19: ='BÁO CÁO DOANH THU'!$I$8 -> 0 | E19: =IF($B19=0,"",$D19/$B19) | F19: ='BÁO CÁO DOANH THU'!$B$8 -> 0
A20: ='BÁO CÁO DOANH THU'!$A$9 -> 46113 | B20: ='BÁO CÁO DOANH THU'!$C$9 -> 0 | C20: ='BÁO CÁO DOANH THU'!$H$9 -> 0 | D20: ='BÁO CÁO DOANH THU'!$I$9 -> 0 | E20: =IF($B20=0,"",$D20/$B20) | F20: ='BÁO CÁO DOANH THU'!$B$9 -> 0
A21: ='BÁO CÁO DOANH THU'!$A$10 -> 46143 | B21: ='BÁO CÁO DOANH THU'!$C$10 -> 0 | C21: ='BÁO CÁO DOANH THU'!$H$10 -> 0 | D21: ='BÁO CÁO DOANH THU'!$I$10 -> 0 | E21: =IF($B21=0,"",$D21/$B21) | F21: ='BÁO CÁO DOANH THU'!$B$10 -> 0
A22: ='BÁO CÁO DOANH THU'!$A$11 -> 46174 | B22: ='BÁO CÁO DOANH THU'!$C$11 -> 0 | C22: ='BÁO CÁO DOANH THU'!$H$11 -> 0 | D22: ='BÁO CÁO DOANH THU'!$I$11 -> 0 | E22: =IF($B22=0,"",$D22/$B22) | F22: ='BÁO CÁO DOANH THU'!$B$11 -> 0
A23: ='BÁO CÁO DOANH THU'!$A$12 -> 46204 | B23: ='BÁO CÁO DOANH THU'!$C$12 -> 14160000 | C23: ='BÁO CÁO DOANH THU'!$H$12 -> 10150000 | D23: ='BÁO CÁO DOANH THU'!$I$12 -> 4010000 | E23: =IF($B23=0,"",$D23/$B23) -> 0.28319209 | F23: ='BÁO CÁO DOANH THU'!$B$12 -> 3
A24: ='BÁO CÁO DOANH THU'!$A$13 -> 46235 | B24: ='BÁO CÁO DOANH THU'!$C$13 -> 0 | C24: ='BÁO CÁO DOANH THU'!$H$13 -> 0 | D24: ='BÁO CÁO DOANH THU'!$I$13 -> 0 | E24: =IF($B24=0,"",$D24/$B24) | F24: ='BÁO CÁO DOANH THU'!$B$13 -> 0
A25: ='BÁO CÁO DOANH THU'!$A$14 -> 46266 | B25: ='BÁO CÁO DOANH THU'!$C$14 -> 0 | C25: ='BÁO CÁO DOANH THU'!$H$14 -> 0 | D25: ='BÁO CÁO DOANH THU'!$I$14 -> 0 | E25: =IF($B25=0,"",$D25/$B25) | F25: ='BÁO CÁO DOANH THU'!$B$14 -> 0
A26: ='BÁO CÁO DOANH THU'!$A$15 -> 46296 | B26: ='BÁO CÁO DOANH THU'!$C$15 -> 0 | C26: ='BÁO CÁO DOANH THU'!$H$15 -> 0 | D26: ='BÁO CÁO DOANH THU'!$I$15 -> 0 | E26: =IF($B26=0,"",$D26/$B26) | F26: ='BÁO CÁO DOANH THU'!$B$15 -> 0
A27: ='BÁO CÁO DOANH THU'!$A$16 -> 46327 | B27: ='BÁO CÁO DOANH THU'!$C$16 -> 0 | C27: ='BÁO CÁO DOANH THU'!$H$16 -> 0 | D27: ='BÁO CÁO DOANH THU'!$I$16 -> 0 | E27: =IF($B27=0,"",$D27/$B27) | F27: ='BÁO CÁO DOANH THU'!$B$16 -> 0
A28: ='BÁO CÁO DOANH THU'!$A$17 -> 46357 | B28: ='BÁO CÁO DOANH THU'!$C$17 -> 0 | C28: ='BÁO CÁO DOANH THU'!$H$17 -> 0 | D28: ='BÁO CÁO DOANH THU'!$I$17 -> 0 | E28: =IF($B28=0,"",$D28/$B28) | F28: ='BÁO CÁO DOANH THU'!$B$17 -> 0
A29: TỔNG CẢ NĂM | B29: =SUM(B17:B28) -> 14160000 | C29: =SUM(C17:C28) -> 10150000 | D29: =SUM(D17:D28) -> 4010000 | E29: =IF($B29=0,"",$D29/$B29) -> 0.28319209 | F29: =SUM(F17:F28) -> 3
A31: C. LÃI – LỖ THEO TỪNG SẢN PHẨM (toàn bộ dữ liệu đã nhập)
A32: TÊN SẢN PHẨM | B32: SỐ LƯỢNG ĐÃ BÁN | C32: TIỀN HÀNG (đ) | D32: TỔNG VỐN (đ) | E32: LÃI / LỖ (đ) | F32: % LÃI
A33: =IFERROR(INDEX('NHẬP ĐƠN HÀNG'!$H$6:$H$505,MATCH(1,'NHẬP ĐƠN HÀNG'!$AC$6:$AC$505,0)),"") -> GẤU TỐT NGHIỆP | B33: =IF($A33="","",SUMIF('NHẬP ĐƠN HÀNG'!$H$6:$H$505,$A33,'NHẬP ĐƠN HÀNG'!$I$6:$I$505)) -> 20 | C33: =IF($A33="","",SUMIF('NHẬP ĐƠN HÀNG'!$H$6:$H$505,$A33,'NHẬP ĐƠN HÀNG'!$L$6:$L$505)) -> 1140000 | D33: =IF($A33="","",SUMIF('NHẬP ĐƠN HÀNG'!$H$6:$H$505,$A33,'NHẬP ĐƠN HÀNG'!$T$6:$T$505)) -> 800000 | E33: =IF($A33="","",SUMIF('NHẬP ĐƠN HÀNG'!$H$6:$H$505,$A33,'NHẬP ĐƠN HÀNG'!$U$6:$U$505)) -> 340000 | F33: =IF(OR($A33="",$C33=0),"",$E33/$C33) -> 0.29824561
A34: =IFERROR(INDEX('NHẬP ĐƠN HÀNG'!$H$6:$H$505,MATCH(2,'NHẬP ĐƠN HÀNG'!$AC$6:$AC$505,0)),"") -> GẤU TEDDY 25CM TRẮNG | B34: =IF($A34="","",SUMIF('NHẬP ĐƠN HÀNG'!$H$6:$H$505,$A34,'NHẬP ĐƠN HÀNG'!$I$6:$I$505)) -> 210 | C34: =IF($A34="","",SUMIF('NHẬP ĐƠN HÀNG'!$H$6:$H$505,$A34,'NHẬP ĐƠN HÀNG'!$L$6:$L$505)) -> 10000000 | D34: =IF($A34="","",SUMIF('NHẬP ĐƠN HÀNG'!$H$6:$H$505,$A34,'NHẬP ĐƠN HÀNG'!$T$6:$T$505)) -> 7350000 | E34: =IF($A34="","",SUMIF('NHẬP ĐƠN HÀNG'!$H$6:$H$505,$A34,'NHẬP ĐƠN HÀNG'!$U$6:$U$505)) -> 2650000 | F34: =IF(OR($A34="",$C34=0),"",$E34/$C34) -> 0.265
A35: =IFERROR(INDEX('NHẬP ĐƠN HÀNG'!$H$6:$H$505,MATCH(3,'NHẬP ĐƠN HÀNG'!$AC$6:$AC$505,0)),"") -> GỐI ÔM CỎ | B35: =IF($A35="","",SUMIF('NHẬP ĐƠN HÀNG'!$H$6:$H$505,$A35,'NHẬP ĐƠN HÀNG'!$I$6:$I$505)) -> 80 | C35: =IF($A35="","",SUMIF('NHẬP ĐƠN HÀNG'!$H$6:$H$505,$A35,'NHẬP ĐƠN HÀNG'!$L$6:$L$505)) -> 4160000 | D35: =IF($A35="","",SUMIF('NHẬP ĐƠN HÀNG'!$H$6:$H$505,$A35,'NHẬP ĐƠN HÀNG'!$T$6:$T$505)) -> 2800000 | E35: =IF($A35="","",SUMIF('NHẬP ĐƠN HÀNG'!$H$6:$H$505,$A35,'NHẬP ĐƠN HÀNG'!$U$6:$U$505)) -> 1360000 | F35: =IF(OR($A35="",$C35=0),"",$E35/$C35) -> 0.32692308
A36: =IFERROR(INDEX('NHẬP ĐƠN HÀNG'!$H$6:$H$505,MATCH(4,'NHẬP ĐƠN HÀNG'!$AC$6:$AC$505,0)),"") | B36: =IF($A36="","",SUMIF('NHẬP ĐƠN HÀNG'!$H$6:$H$505,$A36,'NHẬP ĐƠN HÀNG'!$I$6:$I$505)) | C36: =IF($A36="","",SUMIF('NHẬP ĐƠN HÀNG'!$H$6:$H$505,$A36,'NHẬP ĐƠN HÀNG'!$L$6:$L$505)) | D36: =IF($A36="","",SUMIF('NHẬP ĐƠN HÀNG'!$H$6:$H$505,$A36,'NHẬP ĐƠN HÀNG'!$T$6:$T$505)) | E36: =IF($A36="","",SUMIF('NHẬP ĐƠN HÀNG'!$H$6:$H$505,$A36,'NHẬP ĐƠN HÀNG'!$U$6:$U$505)) | F36: =IF(OR($A36="",$C36=0),"",$E36/$C36)
A37: =IFERROR(INDEX('NHẬP ĐƠN HÀNG'!$H$6:$H$505,MATCH(5,'NHẬP ĐƠN HÀNG'!$AC$6:$AC$505,0)),"") | B37: =IF($A37="","",SUMIF('NHẬP ĐƠN HÀNG'!$H$6:$H$505,$A37,'NHẬP ĐƠN HÀNG'!$I$6:$I$505)) | C37: =IF($A37="","",SUMIF('NHẬP ĐƠN HÀNG'!$H$6:$H$505,$A37,'NHẬP ĐƠN HÀNG'!$L$6:$L$505)) | D37: =IF($A37="","",SUMIF('NHẬP ĐƠN HÀNG'!$H$6:$H$505,$A37,'NHẬP ĐƠN HÀNG'!$T$6:$T$505)) | E37: =IF($A37="","",SUMIF('NHẬP ĐƠN HÀNG'!$H$6:$H$505,$A37,'NHẬP ĐƠN HÀNG'!$U$6:$U$505)) | F37: =IF(OR($A37="",$C37=0),"",$E37/$C37)
A38: =IFERROR(INDEX('NHẬP ĐƠN HÀNG'!$H$6:$H$505,MATCH(6,'NHẬP ĐƠN HÀNG'!$AC$6:$AC$505,0)),"") | B38: =IF($A38="","",SUMIF('NHẬP ĐƠN HÀNG'!$H$6:$H$505,$A38,'NHẬP ĐƠN HÀNG'!$I$6:$I$505)) | C38: =IF($A38="","",SUMIF('NHẬP ĐƠN HÀNG'!$H$6:$H$505,$A38,'NHẬP ĐƠN HÀNG'!$L$6:$L$505)) | D38: =IF($A38="","",SUMIF('NHẬP ĐƠN HÀNG'!$H$6:$H$505,$A38,'NHẬP ĐƠN HÀNG'!$T$6:$T$505)) | E38: =IF($A38="","",SUMIF('NHẬP ĐƠN HÀNG'!$H$6:$H$505,$A38,'NHẬP ĐƠN HÀNG'!$U$6:$U$505)) | F38: =IF(OR($A38="",$C38=0),"",$E38/$C38)
