Workbook

Sheet HƯỚNG DẪN
A1: HƯỚNG DẪN – FILE QUẢN LÝ ĐƠN HÀNG, CHI PHÍ, LÃI LỖ & CÔNG NỢ THEO THÁNG
A2: Nhân viên chỉ nhập Ô MÀU VÀNG ở sheet BẢNG GIÁ GỐC và 7 sheet THÁNG. Mọi báo cáo tự chạy.
A5: A. SHEET PHẢI NHẬP (thẻ màu vàng)
A6: BẢNG GIÁ GỐC | B6: Mỗi sản phẩm 1 dòng: TÊN SẢN PHẨM + GIÁ GỐC (giá vốn) + GIÁ BÁN GỢI Ý. Đây là nơi duy nhất khai giá gốc; các sheet tháng tự lấy về để tính lãi lỗ.
A7: THÁNG 6 → THÁNG 12 | B7: Mỗi tháng 1 sheet. Nhập đơn hàng vào bảng bên trái (từ dòng 10) và CHI PHÍ KHÁC vào khối vàng bên phải (cột Z). Báo cáo của tháng nằm ngay đầu sheet, tự cập nhật.
A9: B. SHEET TỰ ĐỘNG (thẻ xanh – không gõ gì)
A10: BÁO CÁO NĂM | B10: Doanh thu, VAT, chi phí, lãi lỗ, đã thu, còn nợ của cả 7 tháng và tổng cả năm.
A11: LÃI LỖ | B11: Tổng quan lãi lỗ, lãi lỗ theo tháng và lãi lỗ theo từng sản phẩm.
A12: THANH TOÁN | B12: Tiền hàng ĐÃ thanh toán / CHƯA thanh toán theo tháng, kèm danh sách đơn đã thu đủ.
A13: CÔNG NỢ | B13: Danh sách đơn khách còn nợ tiền, kèm số ngày kể từ ngày đặt.
A14: KHÁCH HÀNG | B14: Tự gom danh sách khách: đã mua bao nhiêu, đã trả, còn nợ, lãi thu được từ khách.
A15: KHÁCH LẤY VAT | B15: Các đơn có VAT, kèm tiền thuế từng đơn và tổng thuế phải xuất hóa đơn.
A16: KHÁCH KHÔNG VAT | B16: Các đơn không lấy hóa đơn VAT.
A18: C. QUY TẮC MÀU
A19: Ô MÀU VÀNG | B19: Nhân viên nhập tay.
A20: Ô MÀU XANH NHẠT | B20: Máy tự tính – KHÔNG gõ đè, sẽ mất công thức.
A21: Ô MÀU CAM (CẢNH BÁO) | B21: Dòng thiếu dữ liệu hoặc đang lỗ. Xử lý hết cảnh báo là số liệu chuẩn.
A23: D. CÔNG THỨC ĐANG CHẠY
A24: GIÁ GỐC / SP | B24: Tự dò từ BẢNG GIÁ GỐC theo TÊN SẢN PHẨM (VLOOKUP). Chưa khai giá gốc thì để trống và báo cảnh báo.
A25: TIỀN HÀNG | B25: SỐ LƯỢNG × GIÁ BÁN/SP (giá bán nhập là giá CHƯA có VAT)
A26: TIỀN VAT | B26: TIỀN HÀNG × THUẾ SUẤT (chọn Không lấy VAT / VAT 5% / VAT 8% / VAT 10%)
A27: TỔNG PHẢI THU | B27: TIỀN HÀNG + TIỀN VAT
A28: CÒN NỢ | B28: TỔNG PHẢI THU − ĐÃ THANH TOÁN
A29: TỔNG VỐN (giá vốn hàng bán) | B29: SỐ LƯỢNG × GIÁ GỐC/SP
A30: LÃI / LỖ trên từng đơn | B30: TIỀN HÀNG − TỔNG VỐN
A31: TỔNG CHI PHÍ THÁNG | B31: GIÁ VỐN HÀNG BÁN của tháng + CHI PHÍ KHÁC của tháng
A32: LÃI / LỖ THỰC của tháng | B32: DOANH THU TIỀN HÀNG − TỔNG CHI PHÍ THÁNG
A34: E. VIỆC CẦN LÀM NGAY
A35: Điền GIÁ GỐC còn thiếu | B35: Dữ liệu cũ có 31 tên sản phẩm chưa từng khai giá vốn. Vào BẢNG GIÁ GỐC điền cột GIÁ GỐC/SP (ô vàng) là toàn bộ lãi lỗ hiện ra ngay.
A36: Giá bán đã gồm VAT | B36: Nếu báo khách giá đã gồm 8% VAT thì lấy giá đó chia 1,08 rồi mới nhập vào cột GIÁ BÁN/SP.
A37: Thêm sản phẩm mới | B37: Thêm 1 dòng ở BẢNG GIÁ GỐC là danh sách chọn trong sheet tháng tự có ngay.

Sheet BẢNG GIÁ GỐC
A1: BẢNG GIÁ GỐC SẢN PHẨM – NHẬP GIÁ VỐN TẠI ĐÂY
A2: Khai 1 lần cho mỗi sản phẩm. Các sheet tháng tự lấy GIÁ GỐC về để tính lãi lỗ.
A3: SỐ SẢN PHẨM CHƯA CÓ GIÁ GỐC: | C3: =COUNTIFS($A$5:$A$254,"?*",$C$5:$C$254,"") -> 28 | D3: ← điền hết cột GIÁ GỐC là toàn bộ báo cáo lãi lỗ chạy đủ
A4: TÊN SẢN PHẨM | B4: QUY CÁCH | C4: GIÁ GỐC / SP (đ) | D4: GIÁ BÁN GỢI Ý (đ) | E4: LÃI GỢI Ý / SP (đ) | F4: % LÃI GỢI Ý | G4: GHI CHÚ
A5: GẤU TEDDY 25CM TRẮNG | B5: 25CM | C5: 35000 | D5: 50000 | E5: =IF(OR($A5="",$C5=""),"",N($D5)-$C5) -> 15000 | F5: =IF(OR($A5="",$C5="",N($D5)=0),"",($D5-$C5)/$D5) -> 0.3 | G5: Danh mục sản phẩm của file cũ
A6: GẤU TEDDY 30CM | B6: 30CM | C6: 35000 | D6: 50000 | E6: =IF(OR($A6="",$C6=""),"",N($D6)-$C6) -> 15000 | F6: =IF(OR($A6="",$C6="",N($D6)=0),"",($D6-$C6)/$D6) -> 0.3 | G6: Danh mục sản phẩm của file cũ
A7: GẤU TEDDY 20CM LÔNG MỊN | B7: 20CM | C7: 35000 | D7: 50000 | E7: =IF(OR($A7="",$C7=""),"",N($D7)-$C7) -> 15000 | F7: =IF(OR($A7="",$C7="",N($D7)=0),"",($D7-$C7)/$D7) -> 0.3 | G7: Danh mục sản phẩm của file cũ
A8: GỐI ÔM CỎ | B8: 25CM | C8: 35000 | D8: 45000 | E8: =IF(OR($A8="",$C8=""),"",N($D8)-$C8) -> 10000 | F8: =IF(OR($A8="",$C8="",N($D8)=0),"",($D8-$C8)/$D8) -> 0.22222222 | G8: Danh mục sản phẩm của file cũ
A9: GẤU TEDDY 20CM LÔNG XÙ | B9: 20CM | C9: 35000 | D9: 45000 | E9: =IF(OR($A9="",$C9=""),"",N($D9)-$C9) -> 10000 | F9: =IF(OR($A9="",$C9="",N($D9)=0),"",($D9-$C9)/$D9) -> 0.22222222 | G9: Danh mục sản phẩm của file cũ
A10: GẤU TEDDY 27CM NÂU | B10: 27CM | C10: 35000 | D10: 50000 | E10: =IF(OR($A10="",$C10=""),"",N($D10)-$C10) -> 15000 | F10: =IF(OR($A10="",$C10="",N($D10)=0),"",($D10-$C10)/$D10) -> 0.3 | G10: Danh mục sản phẩm của file cũ
A11: GẤU TỐT NGHIỆP | B11: 27CM | C11: 40000 | D11: 55000 | E11: =IF(OR($A11="",$C11=""),"",N($D11)-$C11) -> 15000 | F11: =IF(OR($A11="",$C11="",N($D11)=0),"",($D11-$C11)/$D11) -> 0.27272727 | G11: Danh mục sản phẩm của file cũ
A12: GẤU TEDY INLOGO HOA THÁI | B12: 30CM | C12: 42000 | D12: 52000 | E12: =IF(OR($A12="",$C12=""),"",N($D12)-$C12) -> 10000 | F12: =IF(OR($A12="",$C12="",N($D12)=0),"",($D12-$C12)/$D12) -> 0.19230769 | G12: Danh mục sản phẩm của file cũ
A13: GẤU TRÁI TIM INLOGO 1 MẶT HOA THÁI | B13: 40CM | C13: 42000 | D13: 55000 | E13: =IF(OR($A13="",$C13=""),"",N($D13)-$C13) -> 13000 | F13: =IF(OR($A13="",$C13="",N($D13)=0),"",($D13-$C13)/$D13) -> 0.23636364 | G13: Danh mục sản phẩm của file cũ
A14: GẤU BÔNG LENA TRÚC | B14: 30CM | C14: 50000 | D14: 65000 | E14: =IF(OR($A14="",$C14=""),"",N($D14)-$C14) -> 15000 | F14: =IF(OR($A14="",$C14="",N($D14)=0),"",($D14-$C14)/$D14) -> 0.23076923 | G14: Danh mục sản phẩm của file cũ
A15: CÁ MẬP INLOGO | B15: 30CM | C15: 36000 | D15: 48000 | E15: =IF(OR($A15="",$C15=""),"",N($D15)-$C15) -> 12000 | F15: =IF(OR($A15="",$C15="",N($D15)=0),"",($D15-$C15)/$D15) -> 0.25 | G15: Danh mục sản phẩm của file cũ
A16: MẦM INLOGO / ĐÀO TIÊN INLOGO | B16: 20CM | C16: 36000 | D16: 48000 | E16: =IF(OR($A16="",$C16=""),"",N($D16)-$C16) -> 12000 | F16: =IF(OR($A16="",$C16="",N($D16)=0),"",($D16-$C16)/$D16) -> 0.25 | G16: Danh mục sản phẩm của file cũ
... A18: TEDDY TRẮNG QUẢNG CHÂU INLOGO | B18: 30CM | C18: 45000 | D18: 58000 | E18: =IF(OR($A18="",$C18=""),"",N($D18)-$C18) -> 13000 | F18: =IF(OR($A18="",$C18="",N($D18)=0),"",($D18-$C18)/$D18) -> 0.22413793 | G18: Danh mục sản phẩm của file cũ
A19: Bình giữ nhiệt in logo | D19: 85000 | E19: =IF(OR($A19="",$C19=""),"",N($D19)-$C19) | F19: =IF(OR($A19="",$C19="",N($D19)=0),"",($D19-$C19)/$D19) | G19: Lấy từ đơn hàng cũ – CẦN ĐIỀN GIÁ GỐC
A20: Bút ký khắc tên | D20: 35000 | E20: =IF(OR($A20="",$C20=""),"",N($D20)-$C20) | F20: =IF(OR($A20="",$C20="",N($D20)=0),"",($D20-$C20)/$D20) | G20: Lấy từ đơn hàng cũ – CẦN ĐIỀN GIÁ GỐC
A21: CÁ BABY SHARK | D21: 48000 | E21: =IF(OR($A21="",$C21=""),"",N($D21)-$C21) | F21: =IF(OR($A21="",$C21="",N($D21)=0),"",($D21-$C21)/$D21) | G21: Lấy từ đơn hàng cũ – CẦN ĐIỀN GIÁ GỐC
A22: Gấu HT 30cm | D22: 65000 | E22: =IF(OR($A22="",$C22=""),"",N($D22)-$C22) | F22: =IF(OR($A22="",$C22="",N($D22)=0),"",($D22-$C22)/$D22) | G22: Lấy từ đơn hàng cũ – CẦN ĐIỀN GIÁ GỐC
A23: Sổ tay da in logo | D23: 120000 | E23: =IF(OR($A23="",$C23=""),"",N($D23)-$C23) | F23: =IF(OR($A23="",$C23="",N($D23)=0),"",($D23-$C23)/$D23) | G23: Lấy từ đơn hàng cũ – CẦN ĐIỀN GIÁ GỐC
A24: gấu 2 loại | D24: 52000 | E24: =IF(OR($A24="",$C24=""),"",N($D24)-$C24) | F24: =IF(OR($A24="",$C24="",N($D24)=0),"",($D24-$C24)/$D24) | G24: Lấy từ đơn hàng cũ – CẦN ĐIỀN GIÁ GỐC
A25: gấu 30 cm nhà HT | D25: 55000 | E25: =IF(OR($A25="",$C25=""),"",N($D25)-$C25) | F25: =IF(OR($A25="",$C25="",N($D25)=0),"",($D25-$C25)/$D25) | G25: Lấy từ đơn hàng cũ – CẦN ĐIỀN GIÁ GỐC
A26: gấu 30 cm nâu in 2 mặt | D26: 47000 | E26: =IF(OR($A26="",$C26=""),"",N($D26)-$C26) | F26: =IF(OR($A26="",$C26="",N($D26)=0),"",($D26-$C26)/$D26) | G26: Lấy từ đơn hàng cũ – CẦN ĐIỀN GIÁ GỐC
A27: gấu 4 loại, mỗi loại 5 con | D27: 55000 | E27: =IF(OR($A27="",$C27=""),"",N($D27)-$C27) | F27: =IF(OR($A27="",$C27="",N($D27)=0),"",($D27-$C27)/$D27) | G27: Lấy từ đơn hàng cũ – CẦN ĐIỀN GIÁ GỐC
A28: gấu mẫu | D28: 250000 | E28: =IF(OR($A28="",$C28=""),"",N($D28)-$C28) | F28: =IF(OR($A28="",$C28="",N($D28)=0),"",($D28-$C28)/$D28) | G28: Lấy từ đơn hàng cũ – CẦN ĐIỀN GIÁ GỐC
A29: gấu ngồi lông mịn | D29: 58000 | E29: =IF(OR($A29="",$C29=""),"",N($D29)-$C29) | F29: =IF(OR($A29="",$C29="",N($D29)=0),"",($D29-$C29)/$D29) | G29: Lấy từ đơn hàng cũ – CẦN ĐIỀN GIÁ GỐC
A30: gấu ngồi lông mịn kèm mũ tn | D30: 48000 | E30: =IF(OR($A30="",$C30=""),"",N($D30)-$C30) | F30: =IF(OR($A30="",$C30="",N($D30)=0),"",($D30-$C30)/$D30) | G30: Lấy từ đơn hàng cũ – CẦN ĐIỀN GIÁ GỐC
... A44: móc khóa | D44: 29000 | E44: =IF(OR($A44="",$C44=""),"",N($D44)-$C44) | F44: =IF(OR($A44="",$C44="",N($D44)=0),"",($D44-$C44)/$D44) | G44: Lấy từ đơn hàng cũ – CẦN ĐIỀN GIÁ GỐC
A45: móc khóa (ko lấy nữa do lâu quá) | E45: =IF(OR($A45="",$C45=""),"",N($D45)-$C45) | F45: =IF(OR($A45="",$C45="",N($D45)=0),"",($D45-$C45)/$D45) | G45: Lấy từ đơn hàng cũ – CẦN ĐIỀN GIÁ GỐC
A46: mẫu gấu | D46: 140000 | E46: =IF(OR($A46="",$C46=""),"",N($D46)-$C46) | F46: =IF(OR($A46="",$C46="",N($D46)=0),"",($D46-$C46)/$D46) | G46: Lấy từ đơn hàng cũ – CẦN ĐIỀN GIÁ GỐC
E47: =IF(OR($A47="",$C47=""),"",N($D47)-$C47) | F47: =IF(OR($A47="",$C47="",N($D47)=0),"",($D47-$C47)/$D47)
E48: =IF(OR($A48="",$C48=""),"",N($D48)-$C48) | F48: =IF(OR($A48="",$C48="",N($D48)=0),"",($D48-$C48)/$D48)
E49: =IF(OR($A49="",$C49=""),"",N($D49)-$C49) | F49: =IF(OR($A49="",$C49="",N($D49)=0),"",($D49-$C49)/$D49)
E50: =IF(OR($A50="",$C50=""),"",N($D50)-$C50) | F50: =IF(OR($A50="",$C50="",N($D50)=0),"",($D50-$C50)/$D50)
E51: =IF(OR($A51="",$C51=""),"",N($D51)-$C51) | F51: =IF(OR($A51="",$C51="",N($D51)=0),"",($D51-$C51)/$D51)
E52: =IF(OR($A52="",$C52=""),"",N($D52)-$C52) | F52: =IF(OR($A52="",$C52="",N($D52)=0),"",($D52-$C52)/$D52)
E53: =IF(OR($A53="",$C53=""),"",N($D53)-$C53) | F53: =IF(OR($A53="",$C53="",N($D53)=0),"",($D53-$C53)/$D53)
E54: =IF(OR($A54="",$C54=""),"",N($D54)-$C54) | F54: =IF(OR($A54="",$C54="",N($D54)=0),"",($D54-$C54)/$D54)
...

Sheet THÁNG 6
A1: THÁNG 6/2026 – NHẬP ĐƠN HÀNG & BÁO CÁO THÁNG
A2: Chỉ gõ Ô MÀU VÀNG. Chi phí khác của tháng nhập ở khối vàng bên phải (cột Z). Tiền hàng, VAT, còn nợ, giá vốn, lãi lỗ đều tự tính.
A3: SỐ ĐƠN HÀNG | D3: =COUNTIFS($C$10:$C$159,"?*",$L$10:$L$159,">0") -> 3 | F3: DOANH THU TIỀN HÀNG (chưa VAT) (đ) | I3: =SUM($L$10:$L$159) -> 21500000 | L3: CHI PHÍ – GIÁ VỐN HÀNG BÁN (đ) | P3: =SUM($T$10:$T$159) -> 0 | Z3: CHI PHÍ KHÁC TRONG THÁNG 6 (NHẬP TAY)
A4: SỐ KHÁCH HÀNG | D4: =IF(COUNTA($C$10:$C$159)=0,0,SUMPRODUCT(($C$10:$C$159<>"")/COUNTIF($C$10:$C$159,$C$10:$C$159&""))) -> 3 | F4: TIỀN VAT (đ) | I4: =SUM($O$10:$O$159) -> 0 | L4: CHI PHÍ KHÁC TRONG THÁNG (đ) | P4: =SUM($AC$5:$AC$24) -> 0 | Z4: NGÀY | AA4: LOẠI CHI PHÍ | AB4: NỘI DUNG | AC4: SỐ TIỀN (đ) | AD4: GHI CHÚ
A5: SỐ ĐƠN ĐÃ THU ĐỦ | D5: =COUNTIFS($P$10:$P$159,">0",$R$10:$R$159,"<=0") -> 2 | F5: TỔNG PHẢI THU (gồm VAT) (đ) | I5: =SUM($P$10:$P$159) -> 21500000 | L5: TỔNG CHI PHÍ THÁNG (đ) | P5: =$P3+$P4 -> 0
A6: SỐ ĐƠN CÒN NỢ | D6: =COUNTIF($R$10:$R$159,">0") -> 1 | F6: TIỀN HÀNG ĐÃ THANH TOÁN (đ) | I6: =SUM($Q$10:$Q$159) -> 15500000 | L6: LÃI / LỖ THỰC CỦA THÁNG (đ) | P6: =$I3-$P5 -> 21500000
A7: % ĐÃ THU | D7: =IF($I5=0,"",$I6/$I5) -> 0.72093023 | F7: TIỀN HÀNG CHƯA THANH TOÁN (đ) | I7: =SUM($R$10:$R$159) -> 6000000 | L7: % LÃI THỰC | P7: =IF($I3=0,"",$P6/$I3) -> 1
A8: =IF(SUMPRODUCT(($H$10:$H$159<>"")*($J$10:$J$159=""))=0,"✔ Mọi đơn trong tháng đã có GIÁ GỐC – số liệu lãi lỗ đầy đủ.","⚠ CÓ "&SUMPRODUCT(($H$10:$H$159<>"")*($J$10:$J$159=""))&" ĐƠN CHƯA KHAI GIÁ GỐC → GIÁ VỐN và LÃI/LỖ của tháng CHƯA ĐỦ. Vào sheet BẢNG GIÁ GỐC điền cột GIÁ GỐC/SP.") -> ⚠ CÓ 3 ĐƠN CHƯA KHAI GIÁ GỐC → GIÁ VỐN và LÃI/LỖ của tháng CHƯA ĐỦ. Vào sheet BẢNG GIÁ GỐC điền cột GIÁ GỐC/SP.
A9: STT | B9: NGÀY ĐẶT | C9: TÊN KHÁCH HÀNG | D9: SỐ ĐIỆN THOẠI | E9: CÔNG TY (nếu có) | F9: MÃ SỐ THUẾ | G9: ĐỊA CHỈ GIAO HÀNG | H9: TÊN SẢN PHẨM | I9: SỐ LƯỢNG | J9: GIÁ GỐC / SP (đ) | K9: GIÁ BÁN / SP (đ) (chưa VAT) | L9: TIỀN HÀNG (đ) | M9: LẤY VAT? | N9: THUẾ SUẤT | O9: TIỀN VAT (đ) | P9: TỔNG PHẢI THU (đ) | Q9: ĐÃ THANH TOÁN (đ) | R9: CÒN NỢ (đ) | S9: TÌNH TRẠNG | T9: TỔNG VỐN (đ) | U9: LÃI / LỖ (đ) | V9: % LÃI | W9: GHI CHÚ | X9: CẢNH BÁO
A10: =IF($C10="","",COUNTA($C$10:$C10)) -> 1 | B10: 46176 | C10: Nguyễn Văn An | D10: 0901234567 | E10: Công ty TNHH Thương Mại ABC | F10: 0312345678 | G10: 12 Nguyễn Trãi, Thanh Xuân, Hà Nội | H10: Bình giữ nhiệt in logo | I10: 100 | J10: =IF($H10="","",IFERROR(VLOOKUP($H10,'BẢNG GIÁ GỐC'!$A$5:$D$254,3,FALSE()),"")) -> 0 | K10: 85000 | L10: =IF($C10="","",N($I10)*N($K10)) -> 8500000 | M10: Không lấy VAT | N10: =IF($C10="","",IF($M10="VAT 5%",0.05,IF($M10="VAT 8%",0.08,IF($M10="VAT 10%",0.1,0)))) -> 0 | O10: =IF($C10="","",$L10*$N10) -> 0 | P10: =IF($C10="","",$L10+$O10) -> 8500000 | Q10: 8500000 | R10: =IF($C10="","",MAX(0,$P10-N($Q10))) -> 0 | S10: =IF(OR($C10="",$P10=0),"",IF(N($Q10)<=0,"Chưa thanh toán",IF(N($Q10)<$P10,"Thanh toán một phần","Đã thanh toán"))) -> Đã thanh toán | T10: =IF(OR($C10="",$J10=""),"",N($I10)*$J10) | U10: =IF(OR($C10="",$T10=""),"",$L10-$T10) | V10: =IF(OR($U10="",$L10=0),"",$U10/$L10) | W10: Giao đợt 1 (VÍ DỤ MẪU) | chuyển từ Tháng 6 dòng 10 | X10: =IF($C10="","",IF(AND($H10="",N($I10)=0,N($K10)=0),"Dòng chỉ lưu thông tin khách (chưa có đơn); ",IF($B10="","Thiếu ngày đặt; ","")&IF($H10="","Thiếu tên sản phẩm; ",IF($J10="","Chưa khai GIÁ GỐC ở BẢNG GIÁ GỐC; ",""))&IF(N($I10)<=0,"Thiếu số lượng; ","")&IF(N($K10)<=0,"Thiếu giá bán; ","")&IF(AND($N10>0,$F10=""),"Khách lấy VAT thiếu mã số thuế; ","")&IF(N($Q10)>$P10,"Đã thu vượt tổng phải thu; ","")&IF(AND($L10>0,$U10<>"",$U10<0),"CẢNH BÁO: ĐƠN NÀY ĐANG LỖ; ",""))) -> Chưa khai GIÁ GỐC ở BẢNG GIÁ GỐC;
A11: =IF($C11="","",COUNTA($C$10:$C11)) -> 2 | B11: 46183 | C11: Trần Thị Bích | D11: 0987654321 | E11: Công ty CP Đầu Tư XYZ | F11: 0109876543 | G11: 45 Lê Lợi, Quận 1, TP.HCM | H11: Sổ tay da in logo | I11: 50 | J11: =IF($H11="","",IFERROR(VLOOKUP($H11,'BẢNG GIÁ GỐC'!$A$5:$D$254,3,FALSE()),"")) -> 0 | K11: 120000 | L11: =IF($C11="","",N($I11)*N($K11)) -> 6000000 | M11: Không lấy VAT | N11: =IF($C11="","",IF($M11="VAT 5%",0.05,IF($M11="VAT 8%",0.08,IF($M11="VAT 10%",0.1,0)))) -> 0 | O11: =IF($C11="","",$L11*$N11) -> 0 | P11: =IF($C11="","",$L11+$O11) -> 6000000 | Q11: 0 | R11: =IF($C11="","",MAX(0,$P11-N($Q11))) -> 6000000 | S11: =IF(OR($C11="",$P11=0),"",IF(N($Q11)<=0,"Chưa thanh toán",IF(N($Q11)<$P11,"Thanh toán một phần","Đã thanh toán"))) -> Chưa thanh toán | T11: =IF(OR($C11="",$J11=""),"",N($I11)*$J11) | U11: =IF(OR($C11="",$T11=""),"",$L11-$T11) | V11: =IF(OR($U11="",$L11=0),"",$U11/$L11) | W11: (VÍ DỤ MẪU) | chuyển từ Tháng 6 dòng 92 | X11: =IF($C11="","",IF(AND($H11="",N($I11)=0,N($K11)=0),"Dòng chỉ lưu thông tin khách (chưa có đơn); ",IF($B11="","Thiếu ngày đặt; ","")&IF($H11="","Thiếu tên sản phẩm; ",IF($J11="","Chưa khai GIÁ GỐC ở BẢNG GIÁ GỐC; ",""))&IF(N($I11)<=0,"Thiếu số lượng; ","")&IF(N($K11)<=0,"Thiếu giá bán; ","")&IF(AND($N11>0,$F11=""),"Khách lấy VAT thiếu mã số thuế; ","")&IF(N($Q11)>$P11,"Đã thu vượt tổng phải thu; ","")&IF(AND($L11>0,$U11<>"",$U11<0),"CẢNH BÁO: ĐƠN NÀY ĐANG LỖ; ",""))) -> Chưa khai GIÁ GỐC ở BẢNG GIÁ GỐC;
A12: =IF($C12="","",COUNTA($C$10:$C12)) -> 3 | B12: 46188 | C12: Lê Minh Cường | D12: 0912345678 | E12: Công ty TNHH DEF | F12: 0301122334 | G12: 88 Trần Phú, Hải Châu, Đà Nẵng | H12: Bút ký khắc tên | I12: 200 | J12: =IF($H12="","",IFERROR(VLOOKUP($H12,'BẢNG GIÁ GỐC'!$A$5:$D$254,3,FALSE()),"")) -> 0 | K12: 35000 | L12: =IF($C12="","",N($I12)*N($K12)) -> 7000000 | M12: Không lấy VAT | N12: =IF($C12="","",IF($M12="VAT 5%",0.05,IF($M12="VAT 8%",0.08,IF($M12="VAT 10%",0.1,0)))) -> 0 | O12: =IF($C12="","",$L12*$N12) -> 0 | P12: =IF($C12="","",$L12+$O12) -> 7000000 | Q12: 7000000 | R12: =IF($C12="","",MAX(0,$P12-N($Q12))) -> 0 | S12: =IF(OR($C12="",$P12=0),"",IF(N($Q12)<=0,"Chưa thanh toán",IF(N($Q12)<$P12,"Thanh toán một phần","Đã thanh toán"))) -> Đã thanh toán | T12: =IF(OR($C12="",$J12=""),"",N($I12)*$J12) | U12: =IF(OR($C12="",$T12=""),"",$L12-$T12) | V12: =IF(OR($U12="",$L12=0),"",$U12/$L12) | W12: Khách quen (VÍ DỤ MẪU) | chuyển từ Tháng 6 dòng 174 | X12: =IF($C12="","",IF(AND($H12="",N($I12)=0,N($K12)=0),"Dòng chỉ lưu thông tin khách (chưa có đơn); ",IF($B12="","Thiếu ngày đặt; ","")&IF($H12="","Thiếu tên sản phẩm; ",IF($J12="","Chưa khai GIÁ GỐC ở BẢNG GIÁ GỐC; ",""))&IF(N($I12)<=0,"Thiếu số lượng; ","")&IF(N($K12)<=0,"Thiếu giá bán; ","")&IF(AND($N12>0,$F12=""),"Khách lấy VAT thiếu mã số thuế; ","")&IF(N($Q12)>$P12,"Đã thu vượt tổng phải thu; ","")&IF(AND($L12>0,$U12<>"",$U12<0),"CẢNH BÁO: ĐƠN NÀY ĐANG LỖ; ",""))) -> Chưa khai GIÁ GỐC ở BẢNG GIÁ GỐC;
A13: =IF($C13="","",COUNTA($C$10:$C13)) | J13: =IF($H13="","",IFERROR(VLOOKUP($H13,'BẢNG GIÁ GỐC'!$A$5:$D$254,3,FALSE()),"")) | L13: =IF($C13="","",N($I13)*N($K13)) | N13: =IF($C13="","",IF($M13="VAT 5%",0.05,IF($M13="VAT 8%",0.08,IF($M13="VAT 10%",0.1,0)))) | O13: =IF($C13="","",$L13*$N13) | P13: =IF($C13="","",$L13+$O13) | R13: =IF($C13="","",MAX(0,$P13-N($Q13))) | S13: =IF(OR($C13="",$P13=0),"",IF(N($Q13)<=0,"Chưa thanh toán",IF(N($Q13)<$P13,"Thanh toán một phần","Đã thanh toán"))) | T13: =IF(OR($C13="",$J13=""),"",N($I13)*$J13) | U13: =IF(OR($C13="",$T13=""),"",$L13-$T13) | V13: =IF(OR($U13="",$L13=0),"",$U13/$L13) | X13: =IF($C13="","",IF(AND($H13="",N($I13)=0,N($K13)=0),"Dòng chỉ lưu thông tin khách (chưa có đơn); ",IF($B13="","Thiếu ngày đặt; ","")&IF($H13="","Thiếu tên sản phẩm; ",IF($J13="","Chưa khai GIÁ GỐC ở BẢNG GIÁ GỐC; ",""))&IF(N($I13)<=0,"Thiếu số lượng; ","")&IF(N($K13)<=0,"Thiếu giá bán; ","")&IF(AND($N13>0,$F13=""),"Khách lấy VAT thiếu mã số thuế; ","")&IF(N($Q13)>$P13,"Đã thu vượt tổng phải thu; ","")&IF(AND($L13>0,$U13<>"",$U13<0),"CẢNH BÁO: ĐƠN NÀY ĐANG LỖ; ","")))
A14: =IF($C14="","",COUNTA($C$10:$C14)) | J14: =IF($H14="","",IFERROR(VLOOKUP($H14,'BẢNG GIÁ GỐC'!$A$5:$D$254,3,FALSE()),"")) | L14: =IF($C14="","",N($I14)*N($K14)) | N14: =IF($C14="","",IF($M14="VAT 5%",0.05,IF($M14="VAT 8%",0.08,IF($M14="VAT 10%",0.1,0)))) | O14: =IF($C14="","",$L14*$N14) | P14: =IF($C14="","",$L14+$O14) | R14: =IF($C14="","",MAX(0,$P14-N($Q14))) | S14: =IF(OR($C14="",$P14=0),"",IF(N($Q14)<=0,"Chưa thanh toán",IF(N($Q14)<$P14,"Thanh toán một phần","Đã thanh toán"))) | T14: =IF(OR($C14="",$J14=""),"",N($I14)*$J14) | U14: =IF(OR($C14="",$T14=""),"",$L14-$T14) | V14: =IF(OR($U14="",$L14=0),"",$U14/$L14) | X14: =IF($C14="","",IF(AND($H14="",N($I14)=0,N($K14)=0),"Dòng chỉ lưu thông tin khách (chưa có đơn); ",IF($B14="","Thiếu ngày đặt; ","")&IF($H14="","Thiếu tên sản phẩm; ",IF($J14="","Chưa khai GIÁ GỐC ở BẢNG GIÁ GỐC; ",""))&IF(N($I14)<=0,"Thiếu số lượng; ","")&IF(N($K14)<=0,"Thiếu giá bán; ","")&IF(AND($N14>0,$F14=""),"Khách lấy VAT thiếu mã số thuế; ","")&IF(N($Q14)>$P14,"Đã thu vượt tổng phải thu; ","")&IF(AND($L14>0,$U14<>"",$U14<0),"CẢNH BÁO: ĐƠN NÀY ĐANG LỖ; ","")))
A15: =IF($C15="","",COUNTA($C$10:$C15)) | J15: =IF($H15="","",IFERROR(VLOOKUP($H15,'BẢNG GIÁ GỐC'!$A$5:$D$254,3,FALSE()),"")) | L15: =IF($C15="","",N($I15)*N($K15)) | N15: =IF($C15="","",IF($M15="VAT 5%",0.05,IF($M15="VAT 8%",0.08,IF($M15="VAT 10%",0.1,0)))) | O15: =IF($C15="","",$L15*$N15) | P15: =IF($C15="","",$L15+$O15) | R15: =IF($C15="","",MAX(0,$P15-N($Q15))) | S15: =IF(OR($C15="",$P15=0),"",IF(N($Q15)<=0,"Chưa thanh toán",IF(N($Q15)<$P15,"Thanh toán một phần","Đã thanh toán"))) | T15: =IF(OR($C15="",$J15=""),"",N($I15)*$J15) | U15: =IF(OR($C15="",$T15=""),"",$L15-$T15) | V15: =IF(OR($U15="",$L15=0),"",$U15/$L15) | X15: =IF($C15="","",IF(AND($H15="",N($I15)=0,N($K15)=0),"Dòng chỉ lưu thông tin khách (chưa có đơn); ",IF($B15="","Thiếu ngày đặt; ","")&IF($H15="","Thiếu tên sản phẩm; ",IF($J15="","Chưa khai GIÁ GỐC ở BẢNG GIÁ GỐC; ",""))&IF(N($I15)<=0,"Thiếu số lượng; ","")&IF(N($K15)<=0,"Thiếu giá bán; ","")&IF(AND($N15>0,$F15=""),"Khách lấy VAT thiếu mã số thuế; ","")&IF(N($Q15)>$P15,"Đã thu vượt tổng phải thu; ","")&IF(AND($L15>0,$U15<>"",$U15<0),"CẢNH BÁO: ĐƠN NÀY ĐANG LỖ; ","")))
A16: =IF($C16="","",COUNTA($C$10:$C16)) | J16: =IF($H16="","",IFERROR(VLOOKUP($H16,'BẢNG GIÁ GỐC'!$A$5:$D$254,3,FALSE()),"")) | L16: =IF($C16="","",N($I16)*N($K16)) | N16: =IF($C16="","",IF($M16="VAT 5%",0.05,IF($M16="VAT 8%",0.08,IF($M16="VAT 10%",0.1,0)))) | O16: =IF($C16="","",$L16*$N16) | P16: =IF($C16="","",$L16+$O16) | R16: =IF($C16="","",MAX(0,$P16-N($Q16))) | S16: =IF(OR($C16="",$P16=0),"",IF(N($Q16)<=0,"Chưa thanh toán",IF(N($Q16)<$P16,"Thanh toán một phần","Đã thanh toán"))) | T16: =IF(OR($C16="",$J16=""),"",N($I16)*$J16) | U16: =IF(OR($C16="",$T16=""),"",$L16-$T16) | V16: =IF(OR($U16="",$L16=0),"",$U16/$L16) | X16: =IF($C16="","",IF(AND($H16="",N($I16)=0,N($K16)=0),"Dòng chỉ lưu thông tin khách (chưa có đơn); ",IF($B16="","Thiếu ngày đặt; ","")&IF($H16="","Thiếu tên sản phẩm; ",IF($J16="","Chưa khai GIÁ GỐC ở BẢNG GIÁ GỐC; ",""))&IF(N($I16)<=0,"Thiếu số lượng; ","")&IF(N($K16)<=0,"Thiếu giá bán; ","")&IF(AND($N16>0,$F16=""),"Khách lấy VAT thiếu mã số thuế; ","")&IF(N($Q16)>$P16,"Đã thu vượt tổng phải thu; ","")&IF(AND($L16>0,$U16<>"",$U16<0),"CẢNH BÁO: ĐƠN NÀY ĐANG LỖ; ","")))
A17: =IF($C17="","",COUNTA($C$10:$C17)) | J17: =IF($H17="","",IFERROR(VLOOKUP($H17,'BẢNG GIÁ GỐC'!$A$5:$D$254,3,FALSE()),"")) | L17: =IF($C17="","",N($I17)*N($K17)) | N17: =IF($C17="","",IF($M17="VAT 5%",0.05,IF($M17="VAT 8%",0.08,IF($M17="VAT 10%",0.1,0)))) | O17: =IF($C17="","",$L17*$N17) | P17: =IF($C17="","",$L17+$O17) | R17: =IF($C17="","",MAX(0,$P17-N($Q17))) | S17: =IF(OR($C17="",$P17=0),"",IF(N($Q17)<=0,"Chưa thanh toán",IF(N($Q17)<$P17,"Thanh toán một phần","Đã thanh toán"))) | T17: =IF(OR($C17="",$J17=""),"",N($I17)*$J17) | U17: =IF(OR($C17="",$T17=""),"",$L17-$T17) | V17: =IF(OR($U17="",$L17=0),"",$U17/$L17) | X17: =IF($C17="","",IF(AND($H17="",N($I17)=0,N($K17)=0),"Dòng chỉ lưu thông tin khách (chưa có đơn); ",IF($B17="","Thiếu ngày đặt; ","")&IF($H17="","Thiếu tên sản phẩm; ",IF($J17="","Chưa khai GIÁ GỐC ở BẢNG GIÁ GỐC; ",""))&IF(N($I17)<=0,"Thiếu số lượng; ","")&IF(N($K17)<=0,"Thiếu giá bán; ","")&IF(AND($N17>0,$F17=""),"Khách lấy VAT thiếu mã số thuế; ","")&IF(N($Q17)>$P17,"Đã thu vượt tổng phải thu; ","")&IF(AND($L17>0,$U17<>"",$U17<0),"CẢNH BÁO: ĐƠN NÀY ĐANG LỖ; ","")))
A18: =IF($C18="","",COUNTA($C$10:$C18)) | J18: =IF($H18="","",IFERROR(VLOOKUP($H18,'BẢNG GIÁ GỐC'!$A$5:$D$254,3,FALSE()),"")) | L18: =IF($C18="","",N($I18)*N($K18)) | N18: =IF($C18="","",IF($M18="VAT 5%",0.05,IF($M18="VAT 8%",0.08,IF($M18="VAT 10%",0.1,0)))) | O18: =IF($C18="","",$L18*$N18) | P18: =IF($C18="","",$L18+$O18) | R18: =IF($C18="","",MAX(0,$P18-N($Q18))) | S18: =IF(OR($C18="",$P18=0),"",IF(N($Q18)<=0,"Chưa thanh toán",IF(N($Q18)<$P18,"Thanh toán một phần","Đã thanh toán"))) | T18: =IF(OR($C18="",$J18=""),"",N($I18)*$J18) | U18: =IF(OR($C18="",$T18=""),"",$L18-$T18) | V18: =IF(OR($U18="",$L18=0),"",$U18/$L18) | X18: =IF($C18="","",IF(AND($H18="",N($I18)=0,N($K18)=0),"Dòng chỉ lưu thông tin khách (chưa có đơn); ",IF($B18="","Thiếu ngày đặt; ","")&IF($H18="","Thiếu tên sản phẩm; ",IF($J18="","Chưa khai GIÁ GỐC ở BẢNG GIÁ GỐC; ",""))&IF(N($I18)<=0,"Thiếu số lượng; ","")&IF(N($K18)<=0,"Thiếu giá bán; ","")&IF(AND($N18>0,$F18=""),"Khách lấy VAT thiếu mã số thuế; ","")&IF(N($Q18)>$P18,"Đã thu vượt tổng phải thu; ","")&IF(AND($L18>0,$U18<>"",$U18<0),"CẢNH BÁO: ĐƠN NÀY ĐANG LỖ; ","")))
A19: =IF($C19="","",COUNTA($C$10:$C19)) | J19: =IF($H19="","",IFERROR(VLOOKUP($H19,'BẢNG GIÁ GỐC'!$A$5:$D$254,3,FALSE()),"")) | L19: =IF($C19="","",N($I19)*N($K19)) | N19: =IF($C19="","",IF($M19="VAT 5%",0.05,IF($M19="VAT 8%",0.08,IF($M19="VAT 10%",0.1,0)))) | O19: =IF($C19="","",$L19*$N19) | P19: =IF($C19="","",$L19+$O19) | R19: =IF($C19="","",MAX(0,$P19-N($Q19))) | S19: =IF(OR($C19="",$P19=0),"",IF(N($Q19)<=0,"Chưa thanh toán",IF(N($Q19)<$P19,"Thanh toán một phần","Đã thanh toán"))) | T19: =IF(OR($C19="",$J19=""),"",N($I19)*$J19) | U19: =IF(OR($C19="",$T19=""),"",$L19-$T19) | V19: =IF(OR($U19="",$L19=0),"",$U19/$L19) | X19: =IF($C19="","",IF(AND($H19="",N($I19)=0,N($K19)=0),"Dòng chỉ lưu thông tin khách (chưa có đơn); ",IF($B19="","Thiếu ngày đặt; ","")&IF($H19="","Thiếu tên sản phẩm; ",IF($J19="","Chưa khai GIÁ GỐC ở BẢNG GIÁ GỐC; ",""))&IF(N($I19)<=0,"Thiếu số lượng; ","")&IF(N($K19)<=0,"Thiếu giá bán; ","")&IF(AND($N19>0,$F19=""),"Khách lấy VAT thiếu mã số thuế; ","")&IF(N($Q19)>$P19,"Đã thu vượt tổng phải thu; ","")&IF(AND($L19>0,$U19<>"",$U19<0),"CẢNH BÁO: ĐƠN NÀY ĐANG LỖ; ","")))
A20: =IF($C20="","",COUNTA($C$10:$C20)) | J20: =IF($H20="","",IFERROR(VLOOKUP($H20,'BẢNG GIÁ GỐC'!$A$5:$D$254,3,FALSE()),"")) | L20: =IF($C20="","",N($I20)*N($K20)) | N20: =IF($C20="","",IF($M20="VAT 5%",0.05,IF($M20="VAT 8%",0.08,IF($M20="VAT 10%",0.1,0)))) | O20: =IF($C20="","",$L20*$N20) | P20: =IF($C20="","",$L20+$O20) | R20: =IF($C20="","",MAX(0,$P20-N($Q20))) | S20: =IF(OR($C20="",$P20=0),"",IF(N($Q20)<=0,"Chưa thanh toán",IF(N($Q20)<$P20,"Thanh toán một phần","Đã thanh toán"))) | T20: =IF(OR($C20="",$J20=""),"",N($I20)*$J20) | U20: =IF(OR($C20="",$T20=""),"",$L20-$T20) | V20: =IF(OR($U20="",$L20=0),"",$U20/$L20) | X20: =IF($C20="","",IF(AND($H20="",N($I20)=0,N($K20)=0),"Dòng chỉ lưu thông tin khách (chưa có đơn); ",IF($B20="","Thiếu ngày đặt; ","")&IF($H20="","Thiếu tên sản phẩm; ",IF($J20="","Chưa khai GIÁ GỐC ở BẢNG GIÁ GỐC; ",""))&IF(N($I20)<=0,"Thiếu số lượng; ","")&IF(N($K20)<=0,"Thiếu giá bán; ","")&IF(AND($N20>0,$F20=""),"Khách lấy VAT thiếu mã số thuế; ","")&IF(N($Q20)>$P20,"Đã thu vượt tổng phải thu; ","")&IF(AND($L20>0,$U20<>"",$U20<0),"CẢNH BÁO: ĐƠN NÀY ĐANG LỖ; ","")))
A21: =IF($C21="","",COUNTA($C$10:$C21)) | J21: =IF($H21="","",IFERROR(VLOOKUP($H21,'BẢNG GIÁ GỐC'!$A$5:$D$254,3,FALSE()),"")) | L21: =IF($C21="","",N($I21)*N($K21)) | N21: =IF($C21="","",IF($M21="VAT 5%",0.05,IF($M21="VAT 8%",0.08,IF($M21="VAT 10%",0.1,0)))) | O21: =IF($C21="","",$L21*$N21) | P21: =IF($C21="","",$L21+$O21) | R21: =IF($C21="","",MAX(0,$P21-N($Q21))) | S21: =IF(OR($C21="",$P21=0),"",IF(N($Q21)<=0,"Chưa thanh toán",IF(N($Q21)<$P21,"Thanh toán một phần","Đã thanh toán"))) | T21: =IF(OR($C21="",$J21=""),"",N($I21)*$J21) | U21: =IF(OR($C21="",$T21=""),"",$L21-$T21) | V21: =IF(OR($U21="",$L21=0),"",$U21/$L21) | X21: =IF($C21="","",IF(AND($H21="",N($I21)=0,N($K21)=0),"Dòng chỉ lưu thông tin khách (chưa có đơn); ",IF($B21="","Thiếu ngày đặt; ","")&IF($H21="","Thiếu tên sản phẩm; ",IF($J21="","Chưa khai GIÁ GỐC ở BẢNG GIÁ GỐC; ",""))&IF(N($I21)<=0,"Thiếu số lượng; ","")&IF(N($K21)<=0,"Thiếu giá bán; ","")&IF(AND($N21>0,$F21=""),"Khách lấy VAT thiếu mã số thuế; ","")&IF(N($Q21)>$P21,"Đã thu vượt tổng phải thu; ","")&IF(AND($L21>0,$U21<>"",$U21<0),"CẢNH BÁO: ĐƠN NÀY ĐANG LỖ; ","")))
A22: =IF($C22="","",COUNTA($C$10:$C22)) | J22: =IF($H22="","",IFERROR(VLOOKUP($H22,'BẢNG GIÁ GỐC'!$A$5:$D$254,3,FALSE()),"")) | L22: =IF($C22="","",N($I22)*N($K22)) | N22: =IF($C22="","",IF($M22="VAT 5%",0.05,IF($M22="VAT 8%",0.08,IF($M22="VAT 10%",0.1,0)))) | O22: =IF($C22="","",$L22*$N22) | P22: =IF($C22="","",$L22+$O22) | R22: =IF($C22="","",MAX(0,$P22-N($Q22))) | S22: =IF(OR($C22="",$P22=0),"",IF(N($Q22)<=0,"Chưa thanh toán",IF(N($Q22)<$P22,"Thanh toán một phần","Đã thanh toán"))) | T22: =IF(OR($C22="",$J22=""),"",N($I22)*$J22) | U22: =IF(OR($C22="",$T22=""),"",$L22-$T22) | V22: =IF(OR($U22="",$L22=0),"",$U22/$L22) | X22: =IF($C22="","",IF(AND($H22="",N($I22)=0,N($K22)=0),"Dòng chỉ lưu thông tin khách (chưa có đơn); ",IF($B22="","Thiếu ngày đặt; ","")&IF($H22="","Thiếu tên sản phẩm; ",IF($J22="","Chưa khai GIÁ GỐC ở BẢNG GIÁ GỐC; ",""))&IF(N($I22)<=0,"Thiếu số lượng; ","")&IF(N($K22)<=0,"Thiếu giá bán; ","")&IF(AND($N22>0,$F22=""),"Khách lấy VAT thiếu mã số thuế; ","")&IF(N($Q22)>$P22,"Đã thu vượt tổng phải thu; ","")&IF(AND($L22>0,$U22<>"",$U22<0),"CẢNH BÁO: ĐƠN NÀY ĐANG LỖ; ","")))
A23: =IF($C23="","",COUNTA($C$10:$C23)) | J23: =IF($H23="","",IFERROR(VLOOKUP($H23,'BẢNG GIÁ GỐC'!$A$5:$D$254,3,FALSE()),"")) | L23: =IF($C23="","",N($I23)*N($K23)) | N23: =IF($C23="","",IF($M23="VAT 5%",0.05,IF($M23="VAT 8%",0.08,IF($M23="VAT 10%",0.1,0)))) | O23: =IF($C23="","",$L23*$N23) | P23: =IF($C23="","",$L23+$O23) | R23: =IF($C23="","",MAX(0,$P23-N($Q23))) | S23: =IF(OR($C23="",$P23=0),"",IF(N($Q23)<=0,"Chưa thanh toán",IF(N($Q23)<$P23,"Thanh toán một phần","Đã thanh toán"))) | T23: =IF(OR($C23="",$J23=""),"",N($I23)*$J23) | U23: =IF(OR($C23="",$T23=""),"",$L23-$T23) | V23: =IF(OR($U23="",$L23=0),"",$U23/$L23) | X23: =IF($C23="","",IF(AND($H23="",N($I23)=0,N($K23)=0),"Dòng chỉ lưu thông tin khách (chưa có đơn); ",IF($B23="","Thiếu ngày đặt; ","")&IF($H23="","Thiếu tên sản phẩm; ",IF($J23="","Chưa khai GIÁ GỐC ở BẢNG GIÁ GỐC; ",""))&IF(N($I23)<=0,"Thiếu số lượng; ","")&IF(N($K23)<=0,"Thiếu giá bán; ","")&IF(AND($N23>0,$F23=""),"Khách lấy VAT thiếu mã số thuế; ","")&IF(N($Q23)>$P23,"Đã thu vượt tổng phải thu; ","")&IF(AND($L23>0,$U23<>"",$U23<0),"CẢNH BÁO: ĐƠN NÀY ĐANG LỖ; ","")))
A24: =IF($C24="","",COUNTA($C$10:$C24)) | J24: =IF($H24="","",IFERROR(VLOOKUP($H24,'BẢNG GIÁ GỐC'!$A$5:$D$254,3,FALSE()),"")) | L24: =IF($C24="","",N($I24)*N($K24)) | N24: =IF($C24="","",IF($M24="VAT 5%",0.05,IF($M24="VAT 8%",0.08,IF($M24="VAT 10%",0.1,0)))) | O24: =IF($C24="","",$L24*$N24) | P24: =IF($C24="","",$L24+$O24) | R24: =IF($C24="","",MAX(0,$P24-N($Q24))) | S24: =IF(OR($C24="",$P24=0),"",IF(N($Q24)<=0,"Chưa thanh toán",IF(N($Q24)<$P24,"Thanh toán một phần","Đã thanh toán"))) | T24: =IF(OR($C24="",$J24=""),"",N($I24)*$J24) | U24: =IF(OR($C24="",$T24=""),"",$L24-$T24) | V24: =IF(OR($U24="",$L24=0),"",$U24/$L24) | X24: =IF($C24="","",IF(AND($H24="",N($I24)=0,N($K24)=0),"Dòng chỉ lưu thông tin khách (chưa có đơn); ",IF($B24="","Thiếu ngày đặt; ","")&IF($H24="","Thiếu tên sản phẩm; ",IF($J24="","Chưa khai GIÁ GỐC ở BẢNG GIÁ GỐC; ",""))&IF(N($I24)<=0,"Thiếu số lượng; ","")&IF(N($K24)<=0,"Thiếu giá bán; ","")&IF(AND($N24>0,$F24=""),"Khách lấy VAT thiếu mã số thuế; ","")&IF(N($Q24)>$P24,"Đã thu vượt tổng phải thu; ","")&IF(AND($L24>0,$U24<>"",$U24<0),"CẢNH BÁO: ĐƠN NÀY ĐANG LỖ; ","")))
A25: =IF($C25="","",COUNTA($C$10:$C25)) | J25: =IF($H25="","",IFERROR(VLOOKUP($H25,'BẢNG GIÁ GỐC'!$A$5:$D$254,3,FALSE()),"")) | L25: =IF($C25="","",N($I25)*N($K25)) | N25: =IF($C25="","",IF($M25="VAT 5%",0.05,IF($M25="VAT 8%",0.08,IF($M25="VAT 10%",0.1,0)))) | O25: =IF($C25="","",$L25*$N25) | P25: =IF($C25="","",$L25+$O25) | R25: =IF($C25="","",MAX(0,$P25-N($Q25))) | S25: =IF(OR($C25="",$P25=0),"",IF(N($Q25)<=0,"Chưa thanh toán",IF(N($Q25)<$P25,"Thanh toán một phần","Đã thanh toán"))) | T25: =IF(OR($C25="",$J25=""),"",N($I25)*$J25) | U25: =IF(OR($C25="",$T25=""),"",$L25-$T25) | V25: =IF(OR($U25="",$L25=0),"",$U25/$L25) | X25: =IF($C25="","",IF(AND($H25="",N($I25)=0,N($K25)=0),"Dòng chỉ lưu thông tin khách (chưa có đơn); ",IF($B25="","Thiếu ngày đặt; ","")&IF($H25="","Thiếu tên sản phẩm; ",IF($J25="","Chưa khai GIÁ GỐC ở BẢNG GIÁ GỐC; ",""))&IF(N($I25)<=0,"Thiếu số lượng; ","")&IF(N($K25)<=0,"Thiếu giá bán; ","")&IF(AND($N25>0,$F25=""),"Khách lấy VAT thiếu mã số thuế; ","")&IF(N($Q25)>$P25,"Đã thu vượt tổng phải thu; ","")&IF(AND($L25>0,$U25<>"",$U25<0),"CẢNH BÁO: ĐƠN NÀY ĐANG LỖ; ",""))) | Z25: TỔNG CHI PHÍ KHÁC | AC25: =SUM(AC5:AC24) -> 0
A26: =IF($C26="","",COUNTA($C$10:$C26)) | J26: =IF($H26="","",IFERROR(VLOOKUP($H26,'BẢNG GIÁ GỐC'!$A$5:$D$254,3,FALSE()),"")) | L26: =IF($C26="","",N($I26)*N($K26)) | N26: =IF($C26="","",IF($M26="VAT 5%",0.05,IF($M26="VAT 8%",0.08,IF($M26="VAT 10%",0.1,0)))) | O26: =IF($C26="","",$L26*$N26) | P26: =IF($C26="","",$L26+$O26) | R26: =IF($C26="","",MAX(0,$P26-N($Q26))) | S26: =IF(OR($C26="",$P26=0),"",IF(N($Q26)<=0,"Chưa thanh toán",IF(N($Q26)<$P26,"Thanh toán một phần","Đã thanh toán"))) | T26: =IF(OR($C26="",$J26=""),"",N($I26)*$J26) | U26: =IF(OR($C26="",$T26=""),"",$L26-$T26) | V26: =IF(OR($U26="",$L26=0),"",$U26/$L26) | X26: =IF($C26="","",IF(AND($H26="",N($I26)=0,N($K26)=0),"Dòng chỉ lưu thông tin khách (chưa có đơn); ",IF($B26="","Thiếu ngày đặt; ","")&IF($H26="","Thiếu tên sản phẩm; ",IF($J26="","Chưa khai GIÁ GỐC ở BẢNG GIÁ GỐC; ",""))&IF(N($I26)<=0,"Thiếu số lượng; ","")&IF(N($K26)<=0,"Thiếu giá bán; ","")&IF(AND($N26>0,$F26=""),"Khách lấy VAT thiếu mã số thuế; ","")&IF(N($Q26)>$P26,"Đã thu vượt tổng phải thu; ","")&IF(AND($L26>0,$U26<>"",$U26<0),"CẢNH BÁO: ĐƠN NÀY ĐANG LỖ; ","")))
A27: =IF($C27="","",COUNTA($C$10:$C27)) | J27: =IF($H27="","",IFERROR(VLOOKUP($H27,'BẢNG GIÁ GỐC'!$A$5:$D$254,3,FALSE()),"")) | L27: =IF($C27="","",N($I27)*N($K27)) | N27: =IF($C27="","",IF($M27="VAT 5%",0.05,IF($M27="VAT 8%",0.08,IF($M27="VAT 10%",0.1,0)))) | O27: =IF($C27="","",$L27*$N27) | P27: =IF($C27="","",$L27+$O27) | R27: =IF($C27="","",MAX(0,$P27-N($Q27))) | S27: =IF(OR($C27="",$P27=0),"",IF(N($Q27)<=0,"Chưa thanh toán",IF(N($Q27)<$P27,"Thanh toán một phần","Đã thanh toán"))) | T27: =IF(OR($C27="",$J27=""),"",N($I27)*$J27) | U27: =IF(OR($C27="",$T27=""),"",$L27-$T27) | V27: =IF(OR($U27="",$L27=0),"",$U27/$L27) | X27: =IF($C27="","",IF(AND($H27="",N($I27)=0,N($K27)=0),"Dòng chỉ lưu thông tin khách (chưa có đơn); ",IF($B27="","Thiếu ngày đặt; ","")&IF($H27="","Thiếu tên sản phẩm; ",IF($J27="","Chưa khai GIÁ GỐC ở BẢNG GIÁ GỐC; ",""))&IF(N($I27)<=0,"Thiếu số lượng; ","")&IF(N($K27)<=0,"Thiếu giá bán; ","")&IF(AND($N27>0,$F27=""),"Khách lấy VAT thiếu mã số thuế; ","")&IF(N($Q27)>$P27,"Đã thu vượt tổng phải thu; ","")&IF(AND($L27>0,$U27<>"",$U27<0),"CẢNH BÁO: ĐƠN NÀY ĐANG LỖ; ","")))
A28: =IF($C28="","",COUNTA($C$10:$C28)) | J28: =IF($H28="","",IFERROR(VLOOKUP($H28,'BẢNG GIÁ GỐC'!$A$5:$D$254,3,FALSE()),"")) | L28: =IF($C28="","",N($I28)*N($K28)) | N28: =IF($C28="","",IF($M28="VAT 5%",0.05,IF($M28="VAT 8%",0.08,IF($M28="VAT 10%",0.1,0)))) | O28: =IF($C28="","",$L28*$N28) | P28: =IF($C28="","",$L28+$O28) | R28: =IF($C28="","",MAX(0,$P28-N($Q28))) | S28: =IF(OR($C28="",$P28=0),"",IF(N($Q28)<=0,"Chưa thanh toán",IF(N($Q28)<$P28,"Thanh toán một phần","Đã thanh toán"))) | T28: =IF(OR($C28="",$J28=""),"",N($I28)*$J28) | U28: =IF(OR($C28="",$T28=""),"",$L28-$T28) | V28: =IF(OR($U28="",$L28=0),"",$U28/$L28) | X28: =IF($C28="","",IF(AND($H28="",N($I28)=0,N($K28)=0),"Dòng chỉ lưu thông tin khách (chưa có đơn); ",IF($B28="","Thiếu ngày đặt; ","")&IF($H28="","Thiếu tên sản phẩm; ",IF($J28="","Chưa khai GIÁ GỐC ở BẢNG GIÁ GỐC; ",""))&IF(N($I28)<=0,"Thiếu số lượng; ","")&IF(N($K28)<=0,"Thiếu giá bán; ","")&IF(AND($N28>0,$F28=""),"Khách lấy VAT thiếu mã số thuế; ","")&IF(N($Q28)>$P28,"Đã thu vượt tổng phải thu; ","")&IF(AND($L28>0,$U28<>"",$U28<0),"CẢNH BÁO: ĐƠN NÀY ĐANG LỖ; ","")))
A29: =IF($C29="","",COUNTA($C$10:$C29)) | J29: =IF($H29="","",IFERROR(VLOOKUP($H29,'BẢNG GIÁ GỐC'!$A$5:$D$254,3,FALSE()),"")) | L29: =IF($C29="","",N($I29)*N($K29)) | N29: =IF($C29="","",IF($M29="VAT 5%",0.05,IF($M29="VAT 8%",0.08,IF($M29="VAT 10%",0.1,0)))) | O29: =IF($C29="","",$L29*$N29) | P29: =IF($C29="","",$L29+$O29) | R29: =IF($C29="","",MAX(0,$P29-N($Q29))) | S29: =IF(OR($C29="",$P29=0),"",IF(N($Q29)<=0,"Chưa thanh toán",IF(N($Q29)<$P29,"Thanh toán một phần","Đã thanh toán"))) | T29: =IF(OR($C29="",$J29=""),"",N($I29)*$J29) | U29: =IF(OR($C29="",$T29=""),"",$L29-$T29) | V29: =IF(OR($U29="",$L29=0),"",$U29/$L29) | X29: =IF($C29="","",IF(AND($H29="",N($I29)=0,N($K29)=0),"Dòng chỉ lưu thông tin khách (chưa có đơn); ",IF($B29="","Thiếu ngày đặt; ","")&IF($H29="","Thiếu tên sản phẩm; ",IF($J29="","Chưa khai GIÁ GỐC ở BẢNG GIÁ GỐC; ",""))&IF(N($I29)<=0,"Thiếu số lượng; ","")&IF(N($K29)<=0,"Thiếu giá bán; ","")&IF(AND($N29>0,$F29=""),"Khách lấy VAT thiếu mã số thuế; ","")&IF(N($Q29)>$P29,"Đã thu vượt tổng phải thu; ","")&IF(AND($L29>0,$U29<>"",$U29<0),"CẢNH BÁO: ĐƠN NÀY ĐANG LỖ; ","")))
A30: =IF($C30="","",COUNTA($C$10:$C30)) | J30: =IF($H30="","",IFERROR(VLOOKUP($H30,'BẢNG GIÁ GỐC'!$A$5:$D$254,3,FALSE()),"")) | L30: =IF($C30="","",N($I30)*N($K30)) | N30: =IF($C30="","",IF($M30="VAT 5%",0.05,IF($M30="VAT 8%",0.08,IF($M30="VAT 10%",0.1,0)))) | O30: =IF($C30="","",$L30*$N30) | P30: =IF($C30="","",$L30+$O30) | R30: =IF($C30="","",MAX(0,$P30-N($Q30))) | S30: =IF(OR($C30="",$P30=0),"",IF(N($Q30)<=0,"Chưa thanh toán",IF(N($Q30)<$P30,"Thanh toán một phần","Đã thanh toán"))) | T30: =IF(OR($C30="",$J30=""),"",N($I30)*$J30) | U30: =IF(OR($C30="",$T30=""),"",$L30-$T30) | V30: =IF(OR($U30="",$L30=0),"",$U30/$L30) | X30: =IF($C30="","",IF(AND($H30="",N($I30)=0,N($K30)=0),"Dòng chỉ lưu thông tin khách (chưa có đơn); ",IF($B30="","Thiếu ngày đặt; ","")&IF($H30="","Thiếu tên sản phẩm; ",IF($J30="","Chưa khai GIÁ GỐC ở BẢNG GIÁ GỐC; ",""))&IF(N($I30)<=0,"Thiếu số lượng; ","")&IF(N($K30)<=0,"Thiếu giá bán; ","")&IF(AND($N30>0,$F30=""),"Khách lấy VAT thiếu mã số thuế; ","")&IF(N($Q30)>$P30,"Đã thu vượt tổng phải thu; ","")&IF(AND($L30>0,$U30<>"",$U30<0),"CẢNH BÁO: ĐƠN NÀY ĐANG LỖ; ","")))
A31: =IF($C31="","",COUNTA($C$10:$C31)) | J31: =IF($H31="","",IFERROR(VLOOKUP($H31,'BẢNG GIÁ GỐC'!$A$5:$D$254,3,FALSE()),"")) | L31: =IF($C31="","",N($I31)*N($K31)) | N31: =IF($C31="","",IF($M31="VAT 5%",0.05,IF($M31="VAT 8%",0.08,IF($M31="VAT 10%",0.1,0)))) | O31: =IF($C31="","",$L31*$N31) | P31: =IF($C31="","",$L31+$O31) | R31: =IF($C31="","",MAX(0,$P31-N($Q31))) | S31: =IF(OR($C31="",$P31=0),"",IF(N($Q31)<=0,"Chưa thanh toán",IF(N($Q31)<$P31,"Thanh toán một phần","Đã thanh toán"))) | T31: =IF(OR($C31="",$J31=""),"",N($I31)*$J31) | U31: =IF(OR($C31="",$T31=""),"",$L31-$T31) | V31: =IF(OR($U31="",$L31=0),"",$U31/$L31) | X31: =IF($C31="","",IF(AND($H31="",N($I31)=0,N($K31)=0),"Dòng chỉ lưu thông tin khách (chưa có đơn); ",IF($B31="","Thiếu ngày đặt; ","")&IF($H31="","Thiếu tên sản phẩm; ",IF($J31="","Chưa khai GIÁ GỐC ở BẢNG GIÁ GỐC; ",""))&IF(N($I31)<=0,"Thiếu số lượng; ","")&IF(N($K31)<=0,"Thiếu giá bán; ","")&IF(AND($N31>0,$F31=""),"Khách lấy VAT thiếu mã số thuế; ","")&IF(N($Q31)>$P31,"Đã thu vượt tổng phải thu; ","")&IF(AND($L31>0,$U31<>"",$U31<0),"CẢNH BÁO: ĐƠN NÀY ĐANG LỖ; ","")))
A32: =IF($C32="","",COUNTA($C$10:$C32)) | J32: =IF($H32="","",IFERROR(VLOOKUP($H32,'BẢNG GIÁ GỐC'!$A$5:$D$254,3,FALSE()),"")) | L32: =IF($C32="","",N($I32)*N($K32)) | N32: =IF($C32="","",IF($M32="VAT 5%",0.05,IF($M32="VAT 8%",0.08,IF($M32="VAT 10%",0.1,0)))) | O32: =IF($C32="","",$L32*$N32) | P32: =IF($C32="","",$L32+$O32) | R32: =IF($C32="","",MAX(0,$P32-N($Q32))) | S32: =IF(OR($C32="",$P32=0),"",IF(N($Q32)<=0,"Chưa thanh toán",IF(N($Q32)<$P32,"Thanh toán một phần","Đã thanh toán"))) | T32: =IF(OR($C32="",$J32=""),"",N($I32)*$J32) | U32: =IF(OR($C32="",$T32=""),"",$L32-$T32) | V32: =IF(OR($U32="",$L32=0),"",$U32/$L32) | X32: =IF($C32="","",IF(AND($H32="",N($I32)=0,N($K32)=0),"Dòng chỉ lưu thông tin khách (chưa có đơn); ",IF($B32="","Thiếu ngày đặt; ","")&IF($H32="","Thiếu tên sản phẩm; ",IF($J32="","Chưa khai GIÁ GỐC ở BẢNG GIÁ GỐC; ",""))&IF(N($I32)<=0,"Thiếu số lượng; ","")&IF(N($K32)<=0,"Thiếu giá bán; ","")&IF(AND($N32>0,$F32=""),"Khách lấy VAT thiếu mã số thuế; ","")&IF(N($Q32)>$P32,"Đã thu vượt tổng phải thu; ","")&IF(AND($L32>0,$U32<>"",$U32<0),"CẢNH BÁO: ĐƠN NÀY ĐANG LỖ; ","")))
A33: =IF($C33="","",COUNTA($C$10:$C33)) | J33: =IF($H33="","",IFERROR(VLOOKUP($H33,'BẢNG GIÁ GỐC'!$A$5:$D$254,3,FALSE()),"")) | L33: =IF($C33="","",N($I33)*N($K33)) | N33: =IF($C33="","",IF($M33="VAT 5%",0.05,IF($M33="VAT 8%",0.08,IF($M33="VAT 10%",0.1,0)))) | O33: =IF($C33="","",$L33*$N33) | P33: =IF($C33="","",$L33+$O33) | R33: =IF($C33="","",MAX(0,$P33-N($Q33))) | S33: =IF(OR($C33="",$P33=0),"",IF(N($Q33)<=0,"Chưa thanh toán",IF(N($Q33)<$P33,"Thanh toán một phần","Đã thanh toán"))) | T33: =IF(OR($C33="",$J33=""),"",N($I33)*$J33) | U33: =IF(OR($C33="",$T33=""),"",$L33-$T33) | V33: =IF(OR($U33="",$L33=0),"",$U33/$L33) | X33: =IF($C33="","",IF(AND($H33="",N($I33)=0,N($K33)=0),"Dòng chỉ lưu thông tin khách (chưa có đơn); ",IF($B33="","Thiếu ngày đặt; ","")&IF($H33="","Thiếu tên sản phẩm; ",IF($J33="","Chưa khai GIÁ GỐC ở BẢNG GIÁ GỐC; ",""))&IF(N($I33)<=0,"Thiếu số lượng; ","")&IF(N($K33)<=0,"Thiếu giá bán; ","")&IF(AND($N33>0,$F33=""),"Khách lấy VAT thiếu mã số thuế; ","")&IF(N($Q33)>$P33,"Đã thu vượt tổng phải thu; ","")&IF(AND($L33>0,$U33<>"",$U33<0),"CẢNH BÁO: ĐƠN NÀY ĐANG LỖ; ","")))
A34: =IF($C34="","",COUNTA($C$10:$C34)) | J34: =IF($H34="","",IFERROR(VLOOKUP($H34,'BẢNG GIÁ GỐC'!$A$5:$D$254,3,FALSE()),"")) | L34: =IF($C34="","",N($I34)*N($K34)) | N34: =IF($C34="","",IF($M34="VAT 5%",0.05,IF($M34="VAT 8%",0.08,IF($M34="VAT 10%",0.1,0)))) | O34: =IF($C34="","",$L34*$N34) | P34: =IF($C34="","",$L34+$O34) | R34: =IF($C34="","",MAX(0,$P34-N($Q34))) | S34: =IF(OR($C34="",$P34=0),"",IF(N($Q34)<=0,"Chưa thanh toán",IF(N($Q34)<$P34,"Thanh toán một phần","Đã thanh toán"))) | T34: =IF(OR($C34="",$J34=""),"",N($I34)*$J34) | U34: =IF(OR($C34="",$T34=""),"",$L34-$T34) | V34: =IF(OR($U34="",$L34=0),"",$U34/$L34) | X34: =IF($C34="","",IF(AND($H34="",N($I34)=0,N($K34)=0),"Dòng chỉ lưu thông tin khách (chưa có đơn); ",IF($B34="","Thiếu ngày đặt; ","")&IF($H34="","Thiếu tên sản phẩm; ",IF($J34="","Chưa khai GIÁ GỐC ở BẢNG GIÁ GỐC; ",""))&IF(N($I34)<=0,"Thiếu số lượng; ","")&IF(N($K34)<=0,"Thiếu giá bán; ","")&IF(AND($N34>0,$F34=""),"Khách lấy VAT thiếu mã số thuế; ","")&IF(N($Q34)>$P34,"Đã thu vượt tổng phải thu; ","")&IF(AND($L34>0,$U34<>"",$U34<0),"CẢNH BÁO: ĐƠN NÀY ĐANG LỖ; ","")))
A35: =IF($C35="","",COUNTA($C$10:$C35)) | J35: =IF($H35="","",IFERROR(VLOOKUP($H35,'BẢNG GIÁ GỐC'!$A$5:$D$254,3,FALSE()),"")) | L35: =IF($C35="","",N($I35)*N($K35)) | N35: =IF($C35="","",IF($M35="VAT 5%",0.05,IF($M35="VAT 8%",0.08,IF($M35="VAT 10%",0.1,0)))) | O35: =IF($C35="","",$L35*$N35) | P35: =IF($C35="","",$L35+$O35) | R35: =IF($C35="","",MAX(0,$P35-N($Q35))) | S35: =IF(OR($C35="",$P35=0),"",IF(N($Q35)<=0,"Chưa thanh toán",IF(N($Q35)<$P35,"Thanh toán một phần","Đã thanh toán"))) | T35: =IF(OR($C35="",$J35=""),"",N($I35)*$J35) | U35: =IF(OR($C35="",$T35=""),"",$L35-$T35) | V35: =IF(OR($U35="",$L35=0),"",$U35/$L35) | X35: =IF($C35="","",IF(AND($H35="",N($I35)=0,N($K35)=0),"Dòng chỉ lưu thông tin khách (chưa có đơn); ",IF($B35="","Thiếu ngày đặt; ","")&IF($H35="","Thiếu tên sản phẩm; ",IF($J35="","Chưa khai GIÁ GỐC ở BẢNG GIÁ GỐC; ",""))&IF(N($I35)<=0,"Thiếu số lượng; ","")&IF(N($K35)<=0,"Thiếu giá bán; ","")&IF(AND($N35>0,$F35=""),"Khách lấy VAT thiếu mã số thuế; ","")&IF(N($Q35)>$P35,"Đã thu vượt tổng phải thu; ","")&IF(AND($L35>0,$U35<>"",$U35<0),"CẢNH BÁO: ĐƠN NÀY ĐANG LỖ; ","")))
A36: =IF($C36="","",COUNTA($C$10:$C36)) | J36: =IF($H36="","",IFERROR(VLOOKUP($H36,'BẢNG GIÁ GỐC'!$A$5:$D$254,3,FALSE()),"")) | L36: =IF($C36="","",N($I36)*N($K36)) | N36: =IF($C36="","",IF($M36="VAT 5%",0.05,IF($M36="VAT 8%",0.08,IF($M36="VAT 10%",0.1,0)))) | O36: =IF($C36="","",$L36*$N36) | P36: =IF($C36="","",$L36+$O36) | R36: =IF($C36="","",MAX(0,$P36-N($Q36))) | S36: =IF(OR($C36="",$P36=0),"",IF(N($Q36)<=0,"Chưa thanh toán",IF(N($Q36)<$P36,"Thanh toán một phần","Đã thanh toán"))) | T36: =IF(OR($C36="",$J36=""),"",N($I36)*$J36) | U36: =IF(OR($C36="",$T36=""),"",$L36-$T36) | V36: =IF(OR($U36="",$L36=0),"",$U36/$L36) | X36: =IF($C36="","",IF(AND($H36="",N($I36)=0,N($K36)=0),"Dòng chỉ lưu thông tin khách (chưa có đơn); ",IF($B36="","Thiếu ngày đặt; ","")&IF($H36="","Thiếu tên sản phẩm; ",IF($J36="","Chưa khai GIÁ GỐC ở BẢNG GIÁ GỐC; ",""))&IF(N($I36)<=0,"Thiếu số lượng; ","")&IF(N($K36)<=0,"Thiếu giá bán; ","")&IF(AND($N36>0,$F36=""),"Khách lấy VAT thiếu mã số thuế; ","")&IF(N($Q36)>$P36,"Đã thu vượt tổng phải thu; ","")&IF(AND($L36>0,$U36<>"",$U36<0),"CẢNH BÁO: ĐƠN NÀY ĐANG LỖ; ","")))
A37: =IF($C37="","",COUNTA($C$10:$C37)) | J37: =IF($H37="","",IFERROR(VLOOKUP($H37,'BẢNG GIÁ GỐC'!$A$5:$D$254,3,FALSE()),"")) | L37: =IF($C37="","",N($I37)*N($K37)) | N37: =IF($C37="","",IF($M37="VAT 5%",0.05,IF($M37="VAT 8%",0.08,IF($M37="VAT 10%",0.1,0)))) | O37: =IF($C37="","",$L37*$N37) | P37: =IF($C37="","",$L37+$O37) | R37: =IF($C37="","",MAX(0,$P37-N($Q37))) | S37: =IF(OR($C37="",$P37=0),"",IF(N($Q37)<=0,"Chưa thanh toán",IF(N($Q37)<$P37,"Thanh toán một phần","Đã thanh toán"))) | T37: =IF(OR($C37="",$J37=""),"",N($I37)*$J37) | U37: =IF(OR($C37="",$T37=""),"",$L37-$T37) | V37: =IF(OR($U37="",$L37=0),"",$U37/$L37) | X37: =IF($C37="","",IF(AND($H37="",N($I37)=0,N($K37)=0),"Dòng chỉ lưu thông tin khách (chưa có đơn); ",IF($B37="","Thiếu ngày đặt; ","")&IF($H37="","Thiếu tên sản phẩm; ",IF($J37="","Chưa khai GIÁ GỐC ở BẢNG GIÁ GỐC; ",""))&IF(N($I37)<=0,"Thiếu số lượng; ","")&IF(N($K37)<=0,"Thiếu giá bán; ","")&IF(AND($N37>0,$F37=""),"Khách lấy VAT thiếu mã số thuế; ","")&IF(N($Q37)>$P37,"Đã thu vượt tổng phải thu; ","")&IF(AND($L37>0,$U37<>"",$U37<0),"CẢNH BÁO: ĐƠN NÀY ĐANG LỖ; ","")))
... A159: =IF($C159="","",COUNTA($C$10:$C159)) | J159: =IF($H159="","",IFERROR(VLOOKUP($H159,'BẢNG GIÁ GỐC'!$A$5:$D$254,3,FALSE()),"")) | L159: =IF($C159="","",N($I159)*N($K159)) | N159: =IF($C159="","",IF($M159="VAT 5%",0.05,IF($M159="VAT 8%",0.08,IF($M159="VAT 10%",0.1,0)))) | O159: =IF($C159="","",$L159*$N159) | P159: =IF($C159="","",$L159+$O159) | R159: =IF($C159="","",MAX(0,$P159-N($Q159))) | S159: =IF(OR($C159="",$P159=0),"",IF(N($Q159)<=0,"Chưa thanh toán",IF(N($Q159)<$P159,"Thanh toán một phần","Đã thanh toán"))) | T159: =IF(OR($C159="",$J159=""),"",N($I159)*$J159) | U159: =IF(OR($C159="",$T159=""),"",$L159-$T159) | V159: =IF(OR($U159="",$L159=0),"",$U159/$L159) | X159: =IF($C159="","",IF(AND($H159="",N($I159)=0,N($K159)=0),"Dòng chỉ lưu thông tin khách (chưa có đơn); ",IF($B159="","Thiếu ngày đặt; ","")&IF($H159="","Thiếu tên sản phẩm; ",IF($J159="","Chưa khai GIÁ GỐC ở BẢNG GIÁ GỐC; ",""))&IF(N($I159)<=0,"Thiếu số lượng; ","")&IF(N($K159)<=0,"Thiếu giá bán; ","")&IF(AND($N159>0,$F159=""),"Khách lấy VAT thiếu mã số thuế; ","")&IF(N($Q159)>$P159,"Đã thu vượt tổng phải thu; ","")&IF(AND($L159>0,$U159<>"",$U159<0),"CẢNH BÁO: ĐƠN NÀY ĐANG LỖ; ","")))

Sheet THÁNG 7
A1: THÁNG 7/2026 – NHẬP ĐƠN HÀNG & BÁO CÁO THÁNG
A2: Chỉ gõ Ô MÀU VÀNG. Chi phí khác của tháng nhập ở khối vàng bên phải (cột Z). Tiền hàng, VAT, còn nợ, giá vốn, lãi lỗ đều tự tính.
A3: SỐ ĐƠN HÀNG | D3: =COUNTIFS($C$10:$C$159,"?*",$L$10:$L$159,">0") -> 53 | F3: DOANH THU TIỀN HÀNG (chưa VAT) (đ) | I3: =SUM($L$10:$L$159) -> 182995000 | L3: CHI PHÍ – GIÁ VỐN HÀNG BÁN (đ) | P3: =SUM($T$10:$T$159) -> 1000000 | Z3: CHI PHÍ KHÁC TRONG THÁNG 7 (NHẬP TAY)
A4: SỐ KHÁCH HÀNG | D4: =IF(COUNTA($C$10:$C$159)=0,0,SUMPRODUCT(($C$10:$C$159<>"")/COUNTIF($C$10:$C$159,$C$10:$C$159&""))) -> 52 | F4: TIỀN VAT (đ) | I4: =SUM($O$10:$O$159) -> 4333200 | L4: CHI PHÍ KHÁC TRONG THÁNG (đ) | P4: =SUM($AC$5:$AC$24) -> 0 | Z4: NGÀY | AA4: LOẠI CHI PHÍ | AB4: NỘI DUNG | AC4: SỐ TIỀN (đ) | AD4: GHI CHÚ
A5: SỐ ĐƠN ĐÃ THU ĐỦ | D5: =COUNTIFS($P$10:$P$159,">0",$R$10:$R$159,"<=0") -> 39 | F5: TỔNG PHẢI THU (gồm VAT) (đ) | I5: =SUM($P$10:$P$159) -> 187328200 | L5: TỔNG CHI PHÍ THÁNG (đ) | P5: =$P3+$P4 -> 1000000
A6: SỐ ĐƠN CÒN NỢ | D6: =COUNTIF($R$10:$R$159,">0") -> 14 | F6: TIỀN HÀNG ĐÃ THANH TOÁN (đ) | I6: =SUM($Q$10:$Q$159) -> 167102200 | L6: LÃI / LỖ THỰC CỦA THÁNG (đ) | P6: =$I3-$P5 -> 181995000
A7: % ĐÃ THU | D7: =IF($I5=0,"",$I6/$I5) -> 0.89202907 | F7: TIỀN HÀNG CHƯA THANH TOÁN (đ) | I7: =SUM($R$10:$R$159) -> 20226000 | L7: % LÃI THỰC | P7: =IF($I3=0,"",$P6/$I3) -> 0.99453537
A8: =IF(SUMPRODUCT(($H$10:$H$159<>"")*($J$10:$J$159=""))=0,"✔ Mọi đơn trong tháng đã có GIÁ GỐC – số liệu lãi lỗ đầy đủ.","⚠ CÓ "&SUMPRODUCT(($H$10:$H$159<>"")*($J$10:$J$159=""))&" ĐƠN CHƯA KHAI GIÁ GỐC → GIÁ VỐN và LÃI/LỖ của tháng CHƯA ĐỦ. Vào sheet BẢNG GIÁ GỐC điền cột GIÁ GỐC/SP.") -> ⚠ CÓ 53 ĐƠN CHƯA KHAI GIÁ GỐC → GIÁ VỐN và LÃI/LỖ của tháng CHƯA ĐỦ. Vào sheet BẢNG GIÁ GỐC điền cột GIÁ GỐC/SP.
A9: STT | B9: NGÀY ĐẶT | C9: TÊN KHÁCH HÀNG | D9: SỐ ĐIỆN THOẠI | E9: CÔNG TY (nếu có) | F9: MÃ SỐ THUẾ | G9: ĐỊA CHỈ GIAO HÀNG | H9: TÊN SẢN PHẨM | I9: SỐ LƯỢNG | J9: GIÁ GỐC / SP (đ) | K9: GIÁ BÁN / SP (đ) (chưa VAT) | L9: TIỀN HÀNG (đ) | M9: LẤY VAT? | N9: THUẾ SUẤT | O9: TIỀN VAT (đ) | P9: TỔNG PHẢI THU (đ) | Q9: ĐÃ THANH TOÁN (đ) | R9: CÒN NỢ (đ) | S9: TÌNH TRẠNG | T9: TỔNG VỐN (đ) | U9: LÃI / LỖ (đ) | V9: % LÃI | W9: GHI CHÚ | X9: CẢNH BÁO
A10: =IF($C10="","",COUNTA($C$10:$C10)) -> 1 | B10: 46204 | C10: A Tài - Huyndai - 20c | D10: 0935494005 | G10: 461 Tây sơn, Quy Nhơn Nam, Gia lai | H10: gấu teddy trắng | I10: 20 | J10: =IF($H10="","",IFERROR(VLOOKUP($H10,'BẢNG GIÁ GỐC'!$A$5:$D$254,3,FALSE()),"")) -> 0 | K10: 50000 | L10: =IF($C10="","",N($I10)*N($K10)) -> 1000000 | M10: Không lấy VAT | N10: =IF($C10="","",IF($M10="VAT 5%",0.05,IF($M10="VAT 8%",0.08,IF($M10="VAT 10%",0.1,0)))) -> 0 | O10: =IF($C10="","",$L10*$N10) -> 0 | P10: =IF($C10="","",$L10+$O10) -> 1000000 | Q10: 1000000 | R10: =IF($C10="","",MAX(0,$P10-N($Q10))) -> 0 | S10: =IF(OR($C10="",$P10=0),"",IF(N($Q10)<=0,"Chưa thanh toán",IF(N($Q10)<$P10,"Thanh toán một phần","Đã thanh toán"))) -> Đã thanh toán | T10: =IF(OR($C10="",$J10=""),"",N($I10)*$J10) | U10: =IF(OR($C10="",$T10=""),"",$L10-$T10) | V10: =IF(OR($U10="",$L10=0),"",$U10/$L10) | W10: chuyển từ Tháng 7 dòng 10 | X10: =IF($C10="","",IF(AND($H10="",N($I10)=0,N($K10)=0),"Dòng chỉ lưu thông tin khách (chưa có đơn); ",IF($B10="","Thiếu ngày đặt; ","")&IF($H10="","Thiếu tên sản phẩm; ",IF($J10="","Chưa khai GIÁ GỐC ở BẢNG GIÁ GỐC; ",""))&IF(N($I10)<=0,"Thiếu số lượng; ","")&IF(N($K10)<=0,"Thiếu giá bán; ","")&IF(AND($N10>0,$F10=""),"Khách lấy VAT thiếu mã số thuế; ","")&IF(N($Q10)>$P10,"Đã thu vượt tổng phải thu; ","")&IF(AND($L10>0,$U10<>"",$U10<0),"CẢNH BÁO: ĐƠN NÀY ĐANG LỖ; ",""))) -> Chưa khai GIÁ GỐC ở BẢNG GIÁ GỐC;
A11: =IF($C11="","",COUNTA($C$10:$C11)) -> 2 | B11: 46205 | C11: BGB - Cô An Mến Tặng | D11: 0903535291 | G11: 658 đường 2/9 Hải châu - Đà Nẵng | H11: gấu teddy trắng | I11: 22 | J11: =IF($H11="","",IFERROR(VLOOKUP($H11,'BẢNG GIÁ GỐC'!$A$5:$D$254,3,FALSE()),"")) -> 0 | K11: 50000 | L11: =IF($C11="","",N($I11)*N($K11)) -> 1100000 | M11: Không lấy VAT | N11: =IF($C11="","",IF($M11="VAT 5%",0.05,IF($M11="VAT 8%",0.08,IF($M11="VAT 10%",0.1,0)))) -> 0 | O11: =IF($C11="","",$L11*$N11) -> 0 | P11: =IF($C11="","",$L11+$O11) -> 1100000 | Q11: 1100000 | R11: =IF($C11="","",MAX(0,$P11-N($Q11))) -> 0 | S11: =IF(OR($C11="",$P11=0),"",IF(N($Q11)<=0,"Chưa thanh toán",IF(N($Q11)<$P11,"Thanh toán một phần","Đã thanh toán"))) -> Đã thanh toán | T11: =IF(OR($C11="",$J11=""),"",N($I11)*$J11) | U11: =IF(OR($C11="",$T11=""),"",$L11-$T11) | V11: =IF(OR($U11="",$L11=0),"",$U11/$L11) | W11: chuyển từ Tháng 7 dòng 11 | X11: =IF($C11="","",IF(AND($H11="",N($I11)=0,N($K11)=0),"Dòng chỉ lưu thông tin khách (chưa có đơn); ",IF($B11="","Thiếu ngày đặt; ","")&IF($H11="","Thiếu tên sản phẩm; ",IF($J11="","Chưa khai GIÁ GỐC ở BẢNG GIÁ GỐC; ",""))&IF(N($I11)<=0,"Thiếu số lượng; ","")&IF(N($K11)<=0,"Thiếu giá bán; ","")&IF(AND($N11>0,$F11=""),"Khách lấy VAT thiếu mã số thuế; ","")&IF(N($Q11)>$P11,"Đã thu vượt tổng phải thu; ","")&IF(AND($L11>0,$U11<>"",$U11<0),"CẢNH BÁO: ĐƠN NÀY ĐANG LỖ; ",""))) -> Chưa khai GIÁ GỐC ở BẢNG GIÁ GỐC;
A12: =IF($C12="","",COUNTA($C$10:$C12)) -> 3 | B12: 46206 | C12: BGB - GẤU TỐT NGHIỆP AMES EL | D12: 0865895498 | G12: 18 Phan Chu Trinh, Hạc Thành, Thanh Hóa | H12: gấu nâu tốt nghiệp | I12: 20 | J12: =IF($H12="","",IFERROR(VLOOKUP($H12,'BẢNG GIÁ GỐC'!$A$5:$D$254,3,FALSE()),"")) -> 0 | K12: 54000 | L12: =IF($C12="","",N($I12)*N($K12)) -> 1080000 | M12: VAT 8% | N12: =IF($C12="","",IF($M12="VAT 5%",0.05,IF($M12="VAT 8%",0.08,IF($M12="VAT 10%",0.1,0)))) -> 0.08 | O12: =IF($C12="","",$L12*$N12) -> 86400 | P12: =IF($C12="","",$L12+$O12) -> 1166400 | Q12: 1166400 | R12: =IF($C12="","",MAX(0,$P12-N($Q12))) -> 0 | S12: =IF(OR($C12="",$P12=0),"",IF(N($Q12)<=0,"Chưa thanh toán",IF(N($Q12)<$P12,"Thanh toán một phần","Đã thanh toán"))) -> Đã thanh toán | T12: =IF(OR($C12="",$J12=""),"",N($I12)*$J12) | U12: =IF(OR($C12="",$T12=""),"",$L12-$T12) | V12: =IF(OR($U12="",$L12=0),"",$U12/$L12) | W12: chuyển từ Tháng 7 dòng 12 | X12: =IF($C12="","",IF(AND($H12="",N($I12)=0,N($K12)=0),"Dòng chỉ lưu thông tin khách (chưa có đơn); ",IF($B12="","Thiếu ngày đặt; ","")&IF($H12="","Thiếu tên sản phẩm; ",IF($J12="","Chưa khai GIÁ GỐC ở BẢNG GIÁ GỐC; ",""))&IF(N($I12)<=0,"Thiếu số lượng; ","")&IF(N($K12)<=0,"Thiếu giá bán; ","")&IF(AND($N12>0,$F12=""),"Khách lấy VAT thiếu mã số thuế; ","")&IF(N($Q12)>$P12,"Đã thu vượt tổng phải thu; ","")&IF(AND($L12>0,$U12<>"",$U12<0),"CẢNH BÁO: ĐƠN NÀY ĐANG LỖ; ",""))) -> Chưa khai GIÁ GỐC ở BẢNG GIÁ GỐC; Khách lấy VAT thiếu mã số thuế;
A13: =IF($C13="","",COUNTA($C$10:$C13)) -> 4 | B13: 46207 | C13: C Trang Jade | D13: 0799740948 | G13: số 9 đường Trương Vĩnh Kỳ, Vùng Tàu, HCM | H13: gấu trắng | I13: 25 | J13: =IF($H13="","",IFERROR(VLOOKUP($H13,'BẢNG GIÁ GỐC'!$A$5:$D$254,3,FALSE()),"")) -> 0 | K13: 49000 | L13: =IF($C13="","",N($I13)*N($K13)) -> 1225000 | M13: VAT 8% | N13: =IF($C13="","",IF($M13="VAT 5%",0.05,IF($M13="VAT 8%",0.08,IF($M13="VAT 10%",0.1,0)))) -> 0.08 | O13: =IF($C13="","",$L13*$N13) -> 98000 | P13: =IF($C13="","",$L13+$O13) -> 1323000 | Q13: 1323000 | R13: =IF($C13="","",MAX(0,$P13-N($Q13))) -> 0 | S13: =IF(OR($C13="",$P13=0),"",IF(N($Q13)<=0,"Chưa thanh toán",IF(N($Q13)<$P13,"Thanh toán một phần","Đã thanh toán"))) -> Đã thanh toán | T13: =IF(OR($C13="",$J13=""),"",N($I13)*$J13) | U13: =IF(OR($C13="",$T13=""),"",$L13-$T13) | V13: =IF(OR($U13="",$L13=0),"",$U13/$L13) | W13: chuyển từ Tháng 7 dòng 13 | X13: =IF($C13="","",IF(AND($H13="",N($I13)=0,N($K13)=0),"Dòng chỉ lưu thông tin khách (chưa có đơn); ",IF($B13="","Thiếu ngày đặt; ","")&IF($H13="","Thiếu tên sản phẩm; ",IF($J13="","Chưa khai GIÁ GỐC ở BẢNG GIÁ GỐC; ",""))&IF(N($I13)<=0,"Thiếu số lượng; ","")&IF(N($K13)<=0,"Thiếu giá bán; ","")&IF(AND($N13>0,$F13=""),"Khách lấy VAT thiếu mã số thuế; ","")&IF(N($Q13)>$P13,"Đã thu vượt tổng phải thu; ","")&IF(AND($L13>0,$U13<>"",$U13<0),"CẢNH BÁO: ĐƠN NÀY ĐANG LỖ; ",""))) -> Chưa khai GIÁ GỐC ở BẢNG GIÁ GỐC; Khách lấy VAT thiếu mã số thuế;
A14: =IF($C14="","",COUNTA($C$10:$C14)) -> 5 | B14: 46207 | C14: Điện máy Ngọc Hiển | D14: 097579661 | G14: Cổng chợ Phú Cường - Xã Phú Thịnh - Tỉnh Thái Nguyên | H14: gấy nâu 25cm | I14: 50 | J14: =IF($H14="","",IFERROR(VLOOKUP($H14,'BẢNG GIÁ GỐC'!$A$5:$D$254,3,FALSE()),"")) -> 0 | K14: 50000 | L14: =IF($C14="","",N($I14)*N($K14)) -> 2500000 | M14: Không lấy VAT | N14: =IF($C14="","",IF($M14="VAT 5%",0.05,IF($M14="VAT 8%",0.08,IF($M14="VAT 10%",0.1,0)))) -> 0 | O14: =IF($C14="","",$L14*$N14) -> 0 | P14: =IF($C14="","",$L14+$O14) -> 2500000 | Q14: 2500000 | R14: =IF($C14="","",MAX(0,$P14-N($Q14))) -> 0 | S14: =IF(OR($C14="",$P14=0),"",IF(N($Q14)<=0,"Chưa thanh toán",IF(N($Q14)<$P14,"Thanh toán một phần","Đã thanh toán"))) -> Đã thanh toán | T14: =IF(OR($C14="",$J14=""),"",N($I14)*$J14) | U14: =IF(OR($C14="",$T14=""),"",$L14-$T14) | V14: =IF(OR($U14="",$L14=0),"",$U14/$L14) | W14: chuyển từ Tháng 7 dòng 14 | X14: =IF($C14="","",IF(AND($H14="",N($I14)=0,N($K14)=0),"Dòng chỉ lưu thông tin khách (chưa có đơn); ",IF($B14="","Thiếu ngày đặt; ","")&IF($H14="","Thiếu tên sản phẩm; ",IF($J14="","Chưa khai GIÁ GỐC ở BẢNG GIÁ GỐC; ",""))&IF(N($I14)<=0,"Thiếu số lượng; ","")&IF(N($K14)<=0,"Thiếu giá bán; ","")&IF(AND($N14>0,$F14=""),"Khách lấy VAT thiếu mã số thuế; ","")&IF(N($Q14)>$P14,"Đã thu vượt tổng phải thu; ","")&IF(AND($L14>0,$U14<>"",$U14<0),"CẢNH BÁO: ĐƠN NÀY ĐANG LỖ; ",""))) -> Chưa khai GIÁ GỐC ở BẢNG GIÁ GỐC;
A15: =IF($C15="","",COUNTA($C$10:$C15)) -> 6 | B15: 46209 | C15: Tạ Quang Bửu | D15: 0347713942 | E15: TRƯỜNG THCS-THPT TẠ QUANG BỬU | F15: 0106193778 | G15: "94A Lê Thanh Nghị, Hà Nội Đối diện sân vân động bách khoa " | H15: gấu nâu 25cm | I15: 25 | J15: =IF($H15="","",IFERROR(VLOOKUP($H15,'BẢNG GIÁ GỐC'!$A$5:$D$254,3,FALSE()),"")) -> 0 | K15: 54000 | L15: =IF($C15="","",N($I15)*N($K15)) -> 1350000 | M15: VAT 8% | N15: =IF($C15="","",IF($M15="VAT 5%",0.05,IF($M15="VAT 8%",0.08,IF($M15="VAT 10%",0.1,0)))) -> 0.08 | O15: =IF($C15="","",$L15*$N15) -> 108000 | P15: =IF($C15="","",$L15+$O15) -> 1458000 | Q15: 1458000 | R15: =IF($C15="","",MAX(0,$P15-N($Q15))) -> 0 | S15: =IF(OR($C15="",$P15=0),"",IF(N($Q15)<=0,"Chưa thanh toán",IF(N($Q15)<$P15,"Thanh toán một phần","Đã thanh toán"))) -> Đã thanh toán | T15: =IF(OR($C15="",$J15=""),"",N($I15)*$J15) | U15: =IF(OR($C15="",$T15=""),"",$L15-$T15) | V15: =IF(OR($U15="",$L15=0),"",$U15/$L15) | W15: gộp tiền ship vào gấu | chuyển từ Tháng 7 dòng 15 | X15: =IF($C15="","",IF(AND($H15="",N($I15)=0,N($K15)=0),"Dòng chỉ lưu thông tin khách (chưa có đơn); ",IF($B15="","Thiếu ngày đặt; ","")&IF($H15="","Thiếu tên sản phẩm; ",IF($J15="","Chưa khai GIÁ GỐC ở BẢNG GIÁ GỐC; ",""))&IF(N($I15)<=0,"Thiếu số lượng; ","")&IF(N($K15)<=0,"Thiếu giá bán; ","")&IF(AND($N15>0,$F15=""),"Khách lấy VAT thiếu mã số thuế; ","")&IF(N($Q15)>$P15,"Đã thu vượt tổng phải thu; ","")&IF(AND($L15>0,$U15<>"",$U15<0),"CẢNH BÁO: ĐƠN NÀY ĐANG LỖ; ",""))) -> Chưa khai GIÁ GỐC ở BẢNG GIÁ GỐC;
A16: =IF($C16="","",COUNTA($C$10:$C16)) -> 7 | B16: 46210 | C16: C Lan Anh | D16: 0989472201 | G16: thôn Bình Phú, xã Việt Yên, tỉnh Hưng Yên. | H16: gấu ngồi lông mịn | I16: 20 | J16: =IF($H16="","",IFERROR(VLOOKUP($H16,'BẢNG GIÁ GỐC'!$A$5:$D$254,3,FALSE()),"")) -> 0 | K16: 58000 | L16: =IF($C16="","",N($I16)*N($K16)) -> 1160000 | M16: Không lấy VAT | N16: =IF($C16="","",IF($M16="VAT 5%",0.05,IF($M16="VAT 8%",0.08,IF($M16="VAT 10%",0.1,0)))) -> 0 | O16: =IF($C16="","",$L16*$N16) -> 0 | P16: =IF($C16="","",$L16+$O16) -> 1160000 | Q16: 1160000 | R16: =IF($C16="","",MAX(0,$P16-N($Q16))) -> 0 | S16: =IF(OR($C16="",$P16=0),"",IF(N($Q16)<=0,"Chưa thanh toán",IF(N($Q16)<$P16,"Thanh toán một phần","Đã thanh toán"))) -> Đã thanh toán | T16: =IF(OR($C16="",$J16=""),"",N($I16)*$J16) | U16: =IF(OR($C16="",$T16=""),"",$L16-$T16) | V16: =IF(OR($U16="",$L16=0),"",$U16/$L16) | W16: chuyển từ Tháng 7 dòng 16 | X16: =IF($C16="","",IF(AND($H16="",N($I16)=0,N($K16)=0),"Dòng chỉ lưu thông tin khách (chưa có đơn); ",IF($B16="","Thiếu ngày đặt; ","")&IF($H16="","Thiếu tên sản phẩm; ",IF($J16="","Chưa khai GIÁ GỐC ở BẢNG GIÁ GỐC; ",""))&IF(N($I16)<=0,"Thiếu số lượng; ","")&IF(N($K16)<=0,"Thiếu giá bán; ","")&IF(AND($N16>0,$F16=""),"Khách lấy VAT thiếu mã số thuế; ","")&IF(N($Q16)>$P16,"Đã thu vượt tổng phải thu; ","")&IF(AND($L16>0,$U16<>"",$U16<0),"CẢNH BÁO: ĐƠN NÀY ĐANG LỖ; ",""))) -> Chưa khai GIÁ GỐC ở BẢNG GIÁ GỐC;
A17: =IF($C17="","",COUNTA($C$10:$C17)) -> 8 | B17: 46210 | C17: BGB - SPA ĐẸP TPHCM | D17: 0399871317 | G17: 134 Liêu Bình Dương, Thị trấn Củ Chi, TPHCM | H17: gấu trắng, gấu nâu | I17: 100 | J17: =IF($H17="","",IFERROR(VLOOKUP($H17,'BẢNG GIÁ GỐC'!$A$5:$D$254,3,FALSE()),"")) -> 0 | K17: 45000 | L17: =IF($C17="","",N($I17)*N($K17)) -> 4500000 | M17: Không lấy VAT | N17: =IF($C17="","",IF($M17="VAT 5%",0.05,IF($M17="VAT 8%",0.08,IF($M17="VAT 10%",0.1,0)))) -> 0 | O17: =IF($C17="","",$L17*$N17) -> 0 | P17: =IF($C17="","",$L17+$O17) -> 4500000 | Q17: 4500000 | R17: =IF($C17="","",MAX(0,$P17-N($Q17))) -> 0 | S17: =IF(OR($C17="",$P17=0),"",IF(N($Q17)<=0,"Chưa thanh toán",IF(N($Q17)<$P17,"Thanh toán một phần","Đã thanh toán"))) -> Đã thanh toán | T17: =IF(OR($C17="",$J17=""),"",N($I17)*$J17) | U17: =IF(OR($C17="",$T17=""),"",$L17-$T17) | V17: =IF(OR($U17="",$L17=0),"",$U17/$L17) | W17: chuyển từ Tháng 7 dòng 17 | X17: =IF($C17="","",IF(AND($H17="",N($I17)=0,N($K17)=0),"Dòng chỉ lưu thông tin khách (chưa có đơn); ",IF($B17="","Thiếu ngày đặt; ","")&IF($H17="","Thiếu tên sản phẩm; ",IF($J17="","Chưa khai GIÁ GỐC ở BẢNG GIÁ GỐC; ",""))&IF(N($I17)<=0,"Thiếu số lượng; ","")&IF(N($K17)<=0,"Thiếu giá bán; ","")&IF(AND($N17>0,$F17=""),"Khách lấy VAT thiếu mã số thuế; ","")&IF(N($Q17)>$P17,"Đã thu vượt tổng phải thu; ","")&IF(AND($L17>0,$U17<>"",$U17<0),"CẢNH BÁO: ĐƠN NÀY ĐANG LỖ; ",""))) -> Chưa khai GIÁ GỐC ở BẢNG GIÁ GỐC;
