Workbook

Sheet HƯỚNG DẪN
B2: HƯỚNG DẪN SỬ DỤNG FILE BÁO CÁO DOANH THU - THÔNG TIN ĐƠN HÀNG (THÁNG 6 - THÁNG 12/2026)
B4: 1. CẤU TRÚC FILE
B5: • 7 sheet 'Tháng 6' → 'Tháng 12': nhập đơn hàng của từng tháng, mỗi tháng 1 sheet riêng (mỗi tab 1 màu).
B6: • Mỗi tháng chia sẵn 4 KHỐI TUẦN: Tuần 1 (ngày 1-7) · Tuần 2 (ngày 8-14) · Tuần 3 (ngày 15-21) · Tuần 4 (ngày 22-cuối tháng).
B7: • Mỗi tuần có 80 dòng nhập; ngay trên đầu mỗi khối là DOANH THU TUẦN tự cộng.
B8: • Sheet 'BÁO CÁO NĂM': tự động tính doanh thu theo NGÀY - TUẦN - THÁNG - QUÝ - NĂM, không cần nhập gì thêm.
B10: 2. CÁCH NHẬP LIỆU (trong các sheet tháng)
B11: • Nhập đơn vào đúng KHỐI TUẦN chứa ngày đặt (ví dụ đơn ngày 21/07 → khối TUẦN 3 của sheet Tháng 7).
B12: • Chỉ nhập các cột: NGÀY ĐẶT, TÊN KHÁCH HÀNG, CÔNG TY, MÃ SỐ THUẾ, SỐ ĐIỆN THOẠI, TÊN SẢN PHẨM, SỐ LƯỢNG, ĐƠN GIÁ, HÌNH ẢNH, TÌNH TRẠNG CHUYỂN KHOẢN, ĐỊA CHỈ GIAO HÀNG, GHI CHÚ.
B13: • Cột STT và THÀNH TIỀN tự tính, KHÔNG sửa (Thành tiền = Số lượng × Đơn giá).
B14: • NGÀY ĐẶT nhập dạng dd/mm/yyyy (ví dụ 05/07/2026) — bắt buộc đúng định dạng thì báo cáo mới tính được.
B15: • SỐ LƯỢNG và ĐƠN GIÁ chỉ gõ số (ví dụ 50 và 85000) — không gõ chữ 'cái', 'đ', dấu chấm phẩy.
... B37: • Chữ XANH DƯƠNG: dữ liệu ví dụ / ô người dùng nhập. • Chữ ĐEN: công thức tự tính. • Chữ XANH LÁ: số lấy từ sheet khác. • Ô nền VÀNG: ô cần bạn nhập.

Sheet Tháng 6
A1: BÁO CÁO DOANH THU THÁNG 6/2026
B3: TỔNG DOANH THU THÁNG (đ): | D3: =SUM($J$10:$J$335) -> 21500000
B4: ĐÃ CHUYỂN KHOẢN (đ): | D4: =SUMIF($L$10:$L$335,"Đã chuyển khoản",$J$10:$J$335) -> 15500000
B5: CHƯA CHUYỂN KHOẢN (đ): | D5: =SUMIF($L$10:$L$335,"Chưa chuyển khoản",$J$10:$J$335) -> 6000000
P6: DOANH THU THEO NGÀY
P7: NGÀY | Q7: DOANH THU (đ)
A8: TUẦN 1 (01/06 → 07/06) — DOANH THU TUẦN (đ): | K8: =SUM($J$10:$J$89) -> 8500000 | P8: 46174 | Q8: =SUMIF($B$10:$B$335,$P8,$J$10:$J$335) -> 0
A9: STT | B9: NGÀY ĐẶT | C9: TÊN KHÁCH HÀNG | D9: CÔNG TY | E9: MÃ SỐ THUẾ | F9: SỐ ĐIỆN THOẠI | G9: TÊN SẢN PHẨM | H9: SỐ LƯỢNG | I9: ĐƠN GIÁ (đ) | J9: THÀNH TIỀN (đ) | K9: HÌNH ẢNH SẢN PHẨM | L9: TÌNH TRẠNG CHUYỂN KHOẢN | M9: ĐỊA CHỈ GIAO HÀNG | N9: GHI CHÚ | P9: 46175 | Q9: =SUMIF($B$10:$B$335,$P9,$J$10:$J$335) -> 0
A10: =IF($B10="","",ROW()-9) -> 1 | B10: 46176 | C10: Nguyễn Văn An | D10: Công ty TNHH Thương Mại ABC | E10: 0312345678 | F10: 0901234567 | G10: Bình giữ nhiệt in logo | H10: 100 | I10: 85000 | J10: =IF($H10="","",$H10*$I10) -> 8500000 | K10: (chèn ảnh vào ô này) | L10: Đã chuyển khoản | M10: 12 Nguyễn Trãi, Thanh Xuân, Hà Nội | N10: Giao đợt 1 (VÍ DỤ MẪU) | P10: 46176 | Q10: =SUMIF($B$10:$B$335,$P10,$J$10:$J$335) -> 8500000
A11: =IF($B11="","",ROW()-9) | J11: =IF($H11="","",$H11*$I11) | P11: 46177 | Q11: =SUMIF($B$10:$B$335,$P11,$J$10:$J$335) -> 0
A12: =IF($B12="","",ROW()-9) | J12: =IF($H12="","",$H12*$I12) | P12: 46178 | Q12: =SUMIF($B$10:$B$335,$P12,$J$10:$J$335) -> 0
A13: =IF($B13="","",ROW()-9) | J13: =IF($H13="","",$H13*$I13) | P13: 46179 | Q13: =SUMIF($B$10:$B$335,$P13,$J$10:$J$335) -> 0
A14: =IF($B14="","",ROW()-9) | J14: =IF($H14="","",$H14*$I14) | P14: 46180 | Q14: =SUMIF($B$10:$B$335,$P14,$J$10:$J$335) -> 0
A15: =IF($B15="","",ROW()-9) | J15: =IF($H15="","",$H15*$I15) | P15: 46181 | Q15: =SUMIF($B$10:$B$335,$P15,$J$10:$J$335) -> 0
A16: =IF($B16="","",ROW()-9) | J16: =IF($H16="","",$H16*$I16) | P16: 46182 | Q16: =SUMIF($B$10:$B$335,$P16,$J$10:$J$335) -> 0
A17: =IF($B17="","",ROW()-9) | J17: =IF($H17="","",$H17*$I17) | P17: 46183 | Q17: =SUMIF($B$10:$B$335,$P17,$J$10:$J$335) -> 6000000
A18: =IF($B18="","",ROW()-9) | J18: =IF($H18="","",$H18*$I18) | P18: 46184 | Q18: =SUMIF($B$10:$B$335,$P18,$J$10:$J$335) -> 0
A19: =IF($B19="","",ROW()-9) | J19: =IF($H19="","",$H19*$I19) | P19: 46185 | Q19: =SUMIF($B$10:$B$335,$P19,$J$10:$J$335) -> 0
A20: =IF($B20="","",ROW()-9) | J20: =IF($H20="","",$H20*$I20) | P20: 46186 | Q20: =SUMIF($B$10:$B$335,$P20,$J$10:$J$335) -> 0
A21: =IF($B21="","",ROW()-9) | J21: =IF($H21="","",$H21*$I21) | P21: 46187 | Q21: =SUMIF($B$10:$B$335,$P21,$J$10:$J$335) -> 0
A22: =IF($B22="","",ROW()-9) | J22: =IF($H22="","",$H22*$I22) | P22: 46188 | Q22: =SUMIF($B$10:$B$335,$P22,$J$10:$J$335) -> 7000000
... A37: =IF($B37="","",ROW()-9) | J37: =IF($H37="","",$H37*$I37) | P37: 46203 | Q37: =SUMIF($B$10:$B$335,$P37,$J$10:$J$335) -> 0
A38: =IF($B38="","",ROW()-9) | J38: =IF($H38="","",$H38*$I38) | P38: CỘNG THÁNG | Q38: =SUM($Q$8:$Q$37) -> 21500000
A39: =IF($B39="","",ROW()-9) | J39: =IF($H39="","",$H39*$I39)
A40: =IF($B40="","",ROW()-9) | J40: =IF($H40="","",$H40*$I40)
A41: =IF($B41="","",ROW()-9) | J41: =IF($H41="","",$H41*$I41)
A42: =IF($B42="","",ROW()-9) | J42: =IF($H42="","",$H42*$I42)
A43: =IF($B43="","",ROW()-9) | J43: =IF($H43="","",$H43*$I43)
A44: =IF($B44="","",ROW()-9) | J44: =IF($H44="","",$H44*$I44)
A45: =IF($B45="","",ROW()-9) | J45: =IF($H45="","",$H45*$I45)
A46: =IF($B46="","",ROW()-9) | J46: =IF($H46="","",$H46*$I46)
A47: =IF($B47="","",ROW()-9) | J47: =IF($H47="","",$H47*$I47)
A48: =IF($B48="","",ROW()-9) | J48: =IF($H48="","",$H48*$I48)
A49: =IF($B49="","",ROW()-9) | J49: =IF($H49="","",$H49*$I49)
A50: =IF($B50="","",ROW()-9) | J50: =IF($H50="","",$H50*$I50)
... A89: =IF($B89="","",ROW()-9) | J89: =IF($H89="","",$H89*$I89)
A90: TUẦN 2 (08/06 → 14/06) — DOANH THU TUẦN (đ): | K90: =SUM($J$92:$J$171) -> 6000000
A91: STT | B91: NGÀY ĐẶT | C91: TÊN KHÁCH HÀNG | D91: CÔNG TY | E91: MÃ SỐ THUẾ | F91: SỐ ĐIỆN THOẠI | G91: TÊN SẢN PHẨM | H91: SỐ LƯỢNG | I91: ĐƠN GIÁ (đ) | J91: THÀNH TIỀN (đ) | K91: HÌNH ẢNH SẢN PHẨM | L91: TÌNH TRẠNG CHUYỂN KHOẢN | M91: ĐỊA CHỈ GIAO HÀNG | N91: GHI CHÚ
A92: =IF($B92="","",ROW()-91) -> 1 | B92: 46183 | C92: Trần Thị Bích | D92: Công ty CP Đầu Tư XYZ | E92: 0109876543 | F92: 0987654321 | G92: Sổ tay da in logo | H92: 50 | I92: 120000 | J92: =IF($H92="","",$H92*$I92) -> 6000000 | K92: (chèn ảnh vào ô này) | L92: Chưa chuyển khoản | M92: 45 Lê Lợi, Quận 1, TP.HCM | N92: (VÍ DỤ MẪU)
A93: =IF($B93="","",ROW()-91) | J93: =IF($H93="","",$H93*$I93)
...

Sheet Tháng 7
A1: BÁO CÁO DOANH THU THÁNG 7/2026
B3: TỔNG DOANH THU THÁNG (đ): | D3: =SUM($J$10:$J$335) -> 97000000
B4: ĐÃ CHUYỂN KHOẢN (đ): | D4: =SUMIF($L$10:$L$335,"Đã chuyển khoản",$J$10:$J$335) -> 50000000
B5: CHƯA CHUYỂN KHOẢN (đ): | D5: =SUMIF($L$10:$L$335,"Chưa chuyển khoản",$J$10:$J$335) -> 47000000
P6: DOANH THU THEO NGÀY
P7: NGÀY | Q7: DOANH THU (đ)
A8: TUẦN 1 (01/07 → 07/07) — DOANH THU TUẦN (đ): | K8: =SUM($J$10:$J$89) -> 0 | P8: 46204 | Q8: =SUMIF($B$10:$B$335,$P8,$J$10:$J$335) -> 0
A9: STT | B9: NGÀY ĐẶT | C9: TÊN KHÁCH HÀNG | D9: CÔNG TY | E9: MÃ SỐ THUẾ | F9: SỐ ĐIỆN THOẠI | G9: TÊN SẢN PHẨM | H9: SỐ LƯỢNG | I9: ĐƠN GIÁ (đ) | J9: THÀNH TIỀN (đ) | K9: HÌNH ẢNH SẢN PHẨM | L9: TÌNH TRẠNG CHUYỂN KHOẢN | M9: ĐỊA CHỈ GIAO HÀNG | N9: GHI CHÚ | P9: 46205 | Q9: =SUMIF($B$10:$B$335,$P9,$J$10:$J$335) -> 0
A10: =IF($B10="","",ROW()-9) | J10: =IF($H10="","",$H10*$I10) | P10: 46206 | Q10: =SUMIF($B$10:$B$335,$P10,$J$10:$J$335) -> 0
A11: =IF($B11="","",ROW()-9) | J11: =IF($H11="","",$H11*$I11) | P11: 46207 | Q11: =SUMIF($B$10:$B$335,$P11,$J$10:$J$335) -> 0
A12: =IF($B12="","",ROW()-9) | J12: =IF($H12="","",$H12*$I12) | P12: 46208 | Q12: =SUMIF($B$10:$B$335,$P12,$J$10:$J$335) -> 0
A13: =IF($B13="","",ROW()-9) | J13: =IF($H13="","",$H13*$I13) | P13: 46209 | Q13: =SUMIF($B$10:$B$335,$P13,$J$10:$J$335) -> 0
A14: =IF($B14="","",ROW()-9) | J14: =IF($H14="","",$H14*$I14) | P14: 46210 | Q14: =SUMIF($B$10:$B$335,$P14,$J$10:$J$335) -> 0
A15: =IF($B15="","",ROW()-9) | J15: =IF($H15="","",$H15*$I15) | P15: 46211 | Q15: =SUMIF($B$10:$B$335,$P15,$J$10:$J$335) -> 0
A16: =IF($B16="","",ROW()-9) | J16: =IF($H16="","",$H16*$I16) | P16: 46212 | Q16: =SUMIF($B$10:$B$335,$P16,$J$10:$J$335) -> 0
A17: =IF($B17="","",ROW()-9) | J17: =IF($H17="","",$H17*$I17) | P17: 46213 | Q17: =SUMIF($B$10:$B$335,$P17,$J$10:$J$335) -> 0
A18: =IF($B18="","",ROW()-9) | J18: =IF($H18="","",$H18*$I18) | P18: 46214 | Q18: =SUMIF($B$10:$B$335,$P18,$J$10:$J$335) -> 0
A19: =IF($B19="","",ROW()-9) | J19: =IF($H19="","",$H19*$I19) | P19: 46215 | Q19: =SUMIF($B$10:$B$335,$P19,$J$10:$J$335) -> 0
A20: =IF($B20="","",ROW()-9) | J20: =IF($H20="","",$H20*$I20) | P20: 46216 | Q20: =SUMIF($B$10:$B$335,$P20,$J$10:$J$335) -> 0
A21: =IF($B21="","",ROW()-9) | J21: =IF($H21="","",$H21*$I21) | P21: 46217 | Q21: =SUMIF($B$10:$B$335,$P21,$J$10:$J$335) -> 0
... A38: =IF($B38="","",ROW()-9) | J38: =IF($H38="","",$H38*$I38) | P38: 46234 | Q38: =SUMIF($B$10:$B$335,$P38,$J$10:$J$335) -> 0
A39: =IF($B39="","",ROW()-9) | J39: =IF($H39="","",$H39*$I39) | P39: CỘNG THÁNG | Q39: =SUM($Q$8:$Q$38) -> 97000000
A40: =IF($B40="","",ROW()-9) | J40: =IF($H40="","",$H40*$I40)
A41: =IF($B41="","",ROW()-9) | J41: =IF($H41="","",$H41*$I41)
A42: =IF($B42="","",ROW()-9) | J42: =IF($H42="","",$H42*$I42)
A43: =IF($B43="","",ROW()-9) | J43: =IF($H43="","",$H43*$I43)
A44: =IF($B44="","",ROW()-9) | J44: =IF($H44="","",$H44*$I44)
A45: =IF($B45="","",ROW()-9) | J45: =IF($H45="","",$H45*$I45)
A46: =IF($B46="","",ROW()-9) | J46: =IF($H46="","",$H46*$I46)
A47: =IF($B47="","",ROW()-9) | J47: =IF($H47="","",$H47*$I47)
A48: =IF($B48="","",ROW()-9) | J48: =IF($H48="","",$H48*$I48)
A49: =IF($B49="","",ROW()-9) | J49: =IF($H49="","",$H49*$I49)
A50: =IF($B50="","",ROW()-9) | J50: =IF($H50="","",$H50*$I50)
A51: =IF($B51="","",ROW()-9) | J51: =IF($H51="","",$H51*$I51)
... A89: =IF($B89="","",ROW()-9) | J89: =IF($H89="","",$H89*$I89)
A90: TUẦN 2 (08/07 → 14/07) — DOANH THU TUẦN (đ): | K90: =SUM($J$92:$J$171) -> 0
A91: STT | B91: NGÀY ĐẶT | C91: TÊN KHÁCH HÀNG | D91: CÔNG TY | E91: MÃ SỐ THUẾ | F91: SỐ ĐIỆN THOẠI | G91: TÊN SẢN PHẨM | H91: SỐ LƯỢNG | I91: ĐƠN GIÁ (đ) | J91: THÀNH TIỀN (đ) | K91: HÌNH ẢNH SẢN PHẨM | L91: TÌNH TRẠNG CHUYỂN KHOẢN | M91: ĐỊA CHỈ GIAO HÀNG | N91: GHI CHÚ
A92: =IF($B92="","",ROW()-91) | J92: =IF($H92="","",$H92*$I92)
A93: =IF($B93="","",ROW()-91) | J93: =IF($H93="","",$H93*$I93)
A94: =IF($B94="","",ROW()-91) | J94: =IF($H94="","",$H94*$I94)
...

Sheet Tháng 8
A1: BÁO CÁO DOANH THU THÁNG 8/2026
B3: TỔNG DOANH THU THÁNG (đ): | D3: =SUM($J$10:$J$335) -> 0
B4: ĐÃ CHUYỂN KHOẢN (đ): | D4: =SUMIF($L$10:$L$335,"Đã chuyển khoản",$J$10:$J$335) -> 0
B5: CHƯA CHUYỂN KHOẢN (đ): | D5: =SUMIF($L$10:$L$335,"Chưa chuyển khoản",$J$10:$J$335) -> 0
P6: DOANH THU THEO NGÀY
P7: NGÀY | Q7: DOANH THU (đ)
A8: TUẦN 1 (01/08 → 07/08) — DOANH THU TUẦN (đ): | K8: =SUM($J$10:$J$89) -> 0 | P8: 46235 | Q8: =SUMIF($B$10:$B$335,$P8,$J$10:$J$335) -> 0
A9: STT | B9: NGÀY ĐẶT | C9: TÊN KHÁCH HÀNG | D9: CÔNG TY | E9: MÃ SỐ THUẾ | F9: SỐ ĐIỆN THOẠI | G9: TÊN SẢN PHẨM | H9: SỐ LƯỢNG | I9: ĐƠN GIÁ (đ) | J9: THÀNH TIỀN (đ) | K9: HÌNH ẢNH SẢN PHẨM | L9: TÌNH TRẠNG CHUYỂN KHOẢN | M9: ĐỊA CHỈ GIAO HÀNG | N9: GHI CHÚ | P9: 46236 | Q9: =SUMIF($B$10:$B$335,$P9,$J$10:$J$335) -> 0
A10: =IF($B10="","",ROW()-9) | J10: =IF($H10="","",$H10*$I10) | P10: 46237 | Q10: =SUMIF($B$10:$B$335,$P10,$J$10:$J$335) -> 0
A11: =IF($B11="","",ROW()-9) | J11: =IF($H11="","",$H11*$I11) | P11: 46238 | Q11: =SUMIF($B$10:$B$335,$P11,$J$10:$J$335) -> 0
A12: =IF($B12="","",ROW()-9) | J12: =IF($H12="","",$H12*$I12) | P12: 46239 | Q12: =SUMIF($B$10:$B$335,$P12,$J$10:$J$335) -> 0
A13: =IF($B13="","",ROW()-9) | J13: =IF($H13="","",$H13*$I13) | P13: 46240 | Q13: =SUMIF($B$10:$B$335,$P13,$J$10:$J$335) -> 0
A14: =IF($B14="","",ROW()-9) | J14: =IF($H14="","",$H14*$I14) | P14: 46241 | Q14: =SUMIF($B$10:$B$335,$P14,$J$10:$J$335) -> 0
A15: =IF($B15="","",ROW()-9) | J15: =IF($H15="","",$H15*$I15) | P15: 46242 | Q15: =SUMIF($B$10:$B$335,$P15,$J$10:$J$335) -> 0
A16: =IF($B16="","",ROW()-9) | J16: =IF($H16="","",$H16*$I16) | P16: 46243 | Q16: =SUMIF($B$10:$B$335,$P16,$J$10:$J$335) -> 0
A17: =IF($B17="","",ROW()-9) | J17: =IF($H17="","",$H17*$I17) | P17: 46244 | Q17: =SUMIF($B$10:$B$335,$P17,$J$10:$J$335) -> 0
A18: =IF($B18="","",ROW()-9) | J18: =IF($H18="","",$H18*$I18) | P18: 46245 | Q18: =SUMIF($B$10:$B$335,$P18,$J$10:$J$335) -> 0
A19: =IF($B19="","",ROW()-9) | J19: =IF($H19="","",$H19*$I19) | P19: 46246 | Q19: =SUMIF($B$10:$B$335,$P19,$J$10:$J$335) -> 0
A20: =IF($B20="","",ROW()-9) | J20: =IF($H20="","",$H20*$I20) | P20: 46247 | Q20: =SUMIF($B$10:$B$335,$P20,$J$10:$J$335) -> 0
A21: =IF($B21="","",ROW()-9) | J21: =IF($H21="","",$H21*$I21) | P21: 46248 | Q21: =SUMIF($B$10:$B$335,$P21,$J$10:$J$335) -> 0
... A38: =IF($B38="","",ROW()-9) | J38: =IF($H38="","",$H38*$I38) | P38: 46265 | Q38: =SUMIF($B$10:$B$335,$P38,$J$10:$J$335) -> 0
A39: =IF($B39="","",ROW()-9) | J39: =IF($H39="","",$H39*$I39) | P39: CỘNG THÁNG | Q39: =SUM($Q$8:$Q$38) -> 0
A40: =IF($B40="","",ROW()-9) | J40: =IF($H40="","",$H40*$I40)
A41: =IF($B41="","",ROW()-9) | J41: =IF($H41="","",$H41*$I41)
A42: =IF($B42="","",ROW()-9) | J42: =IF($H42="","",$H42*$I42)
A43: =IF($B43="","",ROW()-9) | J43: =IF($H43="","",$H43*$I43)
A44: =IF($B44="","",ROW()-9) | J44: =IF($H44="","",$H44*$I44)
A45: =IF($B45="","",ROW()-9) | J45: =IF($H45="","",$H45*$I45)
A46: =IF($B46="","",ROW()-9) | J46: =IF($H46="","",$H46*$I46)
A47: =IF($B47="","",ROW()-9) | J47: =IF($H47="","",$H47*$I47)
A48: =IF($B48="","",ROW()-9) | J48: =IF($H48="","",$H48*$I48)
A49: =IF($B49="","",ROW()-9) | J49: =IF($H49="","",$H49*$I49)
A50: =IF($B50="","",ROW()-9) | J50: =IF($H50="","",$H50*$I50)
A51: =IF($B51="","",ROW()-9) | J51: =IF($H51="","",$H51*$I51)
... A89: =IF($B89="","",ROW()-9) | J89: =IF($H89="","",$H89*$I89)
A90: TUẦN 2 (08/08 → 14/08) — DOANH THU TUẦN (đ): | K90: =SUM($J$92:$J$171) -> 0
A91: STT | B91: NGÀY ĐẶT | C91: TÊN KHÁCH HÀNG | D91: CÔNG TY | E91: MÃ SỐ THUẾ | F91: SỐ ĐIỆN THOẠI | G91: TÊN SẢN PHẨM | H91: SỐ LƯỢNG | I91: ĐƠN GIÁ (đ) | J91: THÀNH TIỀN (đ) | K91: HÌNH ẢNH SẢN PHẨM | L91: TÌNH TRẠNG CHUYỂN KHOẢN | M91: ĐỊA CHỈ GIAO HÀNG | N91: GHI CHÚ
A92: =IF($B92="","",ROW()-91) | J92: =IF($H92="","",$H92*$I92)
A93: =IF($B93="","",ROW()-91) | J93: =IF($H93="","",$H93*$I93)
A94: =IF($B94="","",ROW()-91) | J94: =IF($H94="","",$H94*$I94)
...

Sheet Tháng 9
A1: BÁO CÁO DOANH THU THÁNG 9/2026
B3: TỔNG DOANH THU THÁNG (đ): | D3: =SUM($J$10:$J$335) -> 0
B4: ĐÃ CHUYỂN KHOẢN (đ): | D4: =SUMIF($L$10:$L$335,"Đã chuyển khoản",$J$10:$J$335) -> 0
B5: CHƯA CHUYỂN KHOẢN (đ): | D5: =SUMIF($L$10:$L$335,"Chưa chuyển khoản",$J$10:$J$335) -> 0
P6: DOANH THU THEO NGÀY
P7: NGÀY | Q7: DOANH THU (đ)
A8: TUẦN 1 (01/09 → 07/09) — DOANH THU TUẦN (đ): | K8: =SUM($J$10:$J$89) -> 0 | P8: 46266 | Q8: =SUMIF($B$10:$B$335,$P8,$J$10:$J$335) -> 0
A9: STT | B9: NGÀY ĐẶT | C9: TÊN KHÁCH HÀNG | D9: CÔNG TY | E9: MÃ SỐ THUẾ | F9: SỐ ĐIỆN THOẠI | G9: TÊN SẢN PHẨM | H9: SỐ LƯỢNG | I9: ĐƠN GIÁ (đ) | J9: THÀNH TIỀN (đ) | K9: HÌNH ẢNH SẢN PHẨM | L9: TÌNH TRẠNG CHUYỂN KHOẢN | M9: ĐỊA CHỈ GIAO HÀNG | N9: GHI CHÚ | P9: 46267 | Q9: =SUMIF($B$10:$B$335,$P9,$J$10:$J$335) -> 0
A10: =IF($B10="","",ROW()-9) | J10: =IF($H10="","",$H10*$I10) | P10: 46268 | Q10: =SUMIF($B$10:$B$335,$P10,$J$10:$J$335) -> 0
A11: =IF($B11="","",ROW()-9) | J11: =IF($H11="","",$H11*$I11) | P11: 46269 | Q11: =SUMIF($B$10:$B$335,$P11,$J$10:$J$335) -> 0
A12: =IF($B12="","",ROW()-9) | J12: =IF($H12="","",$H12*$I12) | P12: 46270 | Q12: =SUMIF($B$10:$B$335,$P12,$J$10:$J$335) -> 0
A13: =IF($B13="","",ROW()-9) | J13: =IF($H13="","",$H13*$I13) | P13: 46271 | Q13: =SUMIF($B$10:$B$335,$P13,$J$10:$J$335) -> 0
A14: =IF($B14="","",ROW()-9) | J14: =IF($H14="","",$H14*$I14) | P14: 46272 | Q14: =SUMIF($B$10:$B$335,$P14,$J$10:$J$335) -> 0
A15: =IF($B15="","",ROW()-9) | J15: =IF($H15="","",$H15*$I15) | P15: 46273 | Q15: =SUMIF($B$10:$B$335,$P15,$J$10:$J$335) -> 0
A16: =IF($B16="","",ROW()-9) | J16: =IF($H16="","",$H16*$I16) | P16: 46274 | Q16: =SUMIF($B$10:$B$335,$P16,$J$10:$J$335) -> 0
A17: =IF($B17="","",ROW()-9) | J17: =IF($H17="","",$H17*$I17) | P17: 46275 | Q17: =SUMIF($B$10:$B$335,$P17,$J$10:$J$335) -> 0
A18: =IF($B18="","",ROW()-9) | J18: =IF($H18="","",$H18*$I18) | P18: 46276 | Q18: =SUMIF($B$10:$B$335,$P18,$J$10:$J$335) -> 0
A19: =IF($B19="","",ROW()-9) | J19: =IF($H19="","",$H19*$I19) | P19: 46277 | Q19: =SUMIF($B$10:$B$335,$P19,$J$10:$J$335) -> 0
A20: =IF($B20="","",ROW()-9) | J20: =IF($H20="","",$H20*$I20) | P20: 46278 | Q20: =SUMIF($B$10:$B$335,$P20,$J$10:$J$335) -> 0
A21: =IF($B21="","",ROW()-9) | J21: =IF($H21="","",$H21*$I21) | P21: 46279 | Q21: =SUMIF($B$10:$B$335,$P21,$J$10:$J$335) -> 0
... A37: =IF($B37="","",ROW()-9) | J37: =IF($H37="","",$H37*$I37) | P37: 46295 | Q37: =SUMIF($B$10:$B$335,$P37,$J$10:$J$335) -> 0
A38: =IF($B38="","",ROW()-9) | J38: =IF($H38="","",$H38*$I38) | P38: CỘNG THÁNG | Q38: =SUM($Q$8:$Q$37) -> 0
A39: =IF($B39="","",ROW()-9) | J39: =IF($H39="","",$H39*$I39)
A40: =IF($B40="","",ROW()-9) | J40: =IF($H40="","",$H40*$I40)
A41: =IF($B41="","",ROW()-9) | J41: =IF($H41="","",$H41*$I41)
A42: =IF($B42="","",ROW()-9) | J42: =IF($H42="","",$H42*$I42)
A43: =IF($B43="","",ROW()-9) | J43: =IF($H43="","",$H43*$I43)
A44: =IF($B44="","",ROW()-9) | J44: =IF($H44="","",$H44*$I44)
A45: =IF($B45="","",ROW()-9) | J45: =IF($H45="","",$H45*$I45)
A46: =IF($B46="","",ROW()-9) | J46: =IF($H46="","",$H46*$I46)
A47: =IF($B47="","",ROW()-9) | J47: =IF($H47="","",$H47*$I47)
A48: =IF($B48="","",ROW()-9) | J48: =IF($H48="","",$H48*$I48)
A49: =IF($B49="","",ROW()-9) | J49: =IF($H49="","",$H49*$I49)
A50: =IF($B50="","",ROW()-9) | J50: =IF($H50="","",$H50*$I50)
... A89: =IF($B89="","",ROW()-9) | J89: =IF($H89="","",$H89*$I89)
A90: TUẦN 2 (08/09 → 14/09) — DOANH THU TUẦN (đ): | K90: =SUM($J$92:$J$171) -> 0
A91: STT | B91: NGÀY ĐẶT | C91: TÊN KHÁCH HÀNG | D91: CÔNG TY | E91: MÃ SỐ THUẾ | F91: SỐ ĐIỆN THOẠI | G91: TÊN SẢN PHẨM | H91: SỐ LƯỢNG | I91: ĐƠN GIÁ (đ) | J91: THÀNH TIỀN (đ) | K91: HÌNH ẢNH SẢN PHẨM | L91: TÌNH TRẠNG CHUYỂN KHOẢN | M91: ĐỊA CHỈ GIAO HÀNG | N91: GHI CHÚ
A92: =IF($B92="","",ROW()-91) | J92: =IF($H92="","",$H92*$I92)
A93: =IF($B93="","",ROW()-91) | J93: =IF($H93="","",$H93*$I93)
A94: =IF($B94="","",ROW()-91) | J94: =IF($H94="","",$H94*$I94)
...

Sheet Tháng 10
A1: BÁO CÁO DOANH THU THÁNG 10/2026
B3: TỔNG DOANH THU THÁNG (đ): | D3: =SUM($J$10:$J$335) -> 0
B4: ĐÃ CHUYỂN KHOẢN (đ): | D4: =SUMIF($L$10:$L$335,"Đã chuyển khoản",$J$10:$J$335) -> 0
B5: CHƯA CHUYỂN KHOẢN (đ): | D5: =SUMIF($L$10:$L$335,"Chưa chuyển khoản",$J$10:$J$335) -> 0
P6: DOANH THU THEO NGÀY
P7: NGÀY | Q7: DOANH THU (đ)
A8: TUẦN 1 (01/10 → 07/10) — DOANH THU TUẦN (đ): | K8: =SUM($J$10:$J$89) -> 0 | P8: 46296 | Q8: =SUMIF($B$10:$B$335,$P8,$J$10:$J$335) -> 0
A9: STT | B9: NGÀY ĐẶT | C9: TÊN KHÁCH HÀNG | D9: CÔNG TY | E9: MÃ SỐ THUẾ | F9: SỐ ĐIỆN THOẠI | G9: TÊN SẢN PHẨM | H9: SỐ LƯỢNG | I9: ĐƠN GIÁ (đ) | J9: THÀNH TIỀN (đ) | K9: HÌNH ẢNH SẢN PHẨM | L9: TÌNH TRẠNG CHUYỂN KHOẢN | M9: ĐỊA CHỈ GIAO HÀNG | N9: GHI CHÚ | P9: 46297 | Q9: =SUMIF($B$10:$B$335,$P9,$J$10:$J$335) -> 0
A10: =IF($B10="","",ROW()-9) | J10: =IF($H10="","",$H10*$I10) | P10: 46298 | Q10: =SUMIF($B$10:$B$335,$P10,$J$10:$J$335) -> 0
A11: =IF($B11="","",ROW()-9) | J11: =IF($H11="","",$H11*$I11) | P11: 46299 | Q11: =SUMIF($B$10:$B$335,$P11,$J$10:$J$335) -> 0
A12: =IF($B12="","",ROW()-9) | J12: =IF($H12="","",$H12*$I12) | P12: 46300 | Q12: =SUMIF($B$10:$B$335,$P12,$J$10:$J$335) -> 0
A13: =IF($B13="","",ROW()-9) | J13: =IF($H13="","",$H13*$I13) | P13: 46301 | Q13: =SUMIF($B$10:$B$335,$P13,$J$10:$J$335) -> 0
A14: =IF($B14="","",ROW()-9) | J14: =IF($H14="","",$H14*$I14) | P14: 46302 | Q14: =SUMIF($B$10:$B$335,$P14,$J$10:$J$335) -> 0
A15: =IF($B15="","",ROW()-9) | J15: =IF($H15="","",$H15*$I15) | P15: 46303 | Q15: =SUMIF($B$10:$B$335,$P15,$J$10:$J$335) -> 0
A16: =IF($B16="","",ROW()-9) | J16: =IF($H16="","",$H16*$I16) | P16: 46304 | Q16: =SUMIF($B$10:$B$335,$P16,$J$10:$J$335) -> 0
A17: =IF($B17="","",ROW()-9) | J17: =IF($H17="","",$H17*$I17) | P17: 46305 | Q17: =SUMIF($B$10:$B$335,$P17,$J$10:$J$335) -> 0
A18: =IF($B18="","",ROW()-9) | J18: =IF($H18="","",$H18*$I18) | P18: 46306 | Q18: =SUMIF($B$10:$B$335,$P18,$J$10:$J$335) -> 0
A19: =IF($B19="","",ROW()-9) | J19: =IF($H19="","",$H19*$I19) | P19: 46307 | Q19: =SUMIF($B$10:$B$335,$P19,$J$10:$J$335) -> 0
A20: =IF($B20="","",ROW()-9) | J20: =IF($H20="","",$H20*$I20) | P20: 46308 | Q20: =SUMIF($B$10:$B$335,$P20,$J$10:$J$335) -> 0
A21: =IF($B21="","",ROW()-9) | J21: =IF($H21="","",$H21*$I21) | P21: 46309 | Q21: =SUMIF($B$10:$B$335,$P21,$J$10:$J$335) -> 0
... A38: =IF($B38="","",ROW()-9) | J38: =IF($H38="","",$H38*$I38) | P38: 46326 | Q38: =SUMIF($B$10:$B$335,$P38,$J$10:$J$335) -> 0
A39: =IF($B39="","",ROW()-9) | J39: =IF($H39="","",$H39*$I39) | P39: CỘNG THÁNG | Q39: =SUM($Q$8:$Q$38) -> 0
A40: =IF($B40="","",ROW()-9) | J40: =IF($H40="","",$H40*$I40)
A41: =IF($B41="","",ROW()-9) | J41: =IF($H41="","",$H41*$I41)
A42: =IF($B42="","",ROW()-9) | J42: =IF($H42="","",$H42*$I42)
A43: =IF($B43="","",ROW()-9) | J43: =IF($H43="","",$H43*$I43)
A44: =IF($B44="","",ROW()-9) | J44: =IF($H44="","",$H44*$I44)
A45: =IF($B45="","",ROW()-9) | J45: =IF($H45="","",$H45*$I45)
A46: =IF($B46="","",ROW()-9) | J46: =IF($H46="","",$H46*$I46)
A47: =IF($B47="","",ROW()-9) | J47: =IF($H47="","",$H47*$I47)
A48: =IF($B48="","",ROW()-9) | J48: =IF($H48="","",$H48*$I48)
A49: =IF($B49="","",ROW()-9) | J49: =IF($H49="","",$H49*$I49)
A50: =IF($B50="","",ROW()-9) | J50: =IF($H50="","",$H50*$I50)
A51: =IF($B51="","",ROW()-9) | J51: =IF($H51="","",$H51*$I51)
... A89: =IF($B89="","",ROW()-9) | J89: =IF($H89="","",$H89*$I89)
A90: TUẦN 2 (08/10 → 14/10) — DOANH THU TUẦN (đ): | K90: =SUM($J$92:$J$171) -> 0
A91: STT | B91: NGÀY ĐẶT | C91: TÊN KHÁCH HÀNG | D91: CÔNG TY | E91: MÃ SỐ THUẾ | F91: SỐ ĐIỆN THOẠI | G91: TÊN SẢN PHẨM | H91: SỐ LƯỢNG | I91: ĐƠN GIÁ (đ) | J91: THÀNH TIỀN (đ) | K91: HÌNH ẢNH SẢN PHẨM | L91: TÌNH TRẠNG CHUYỂN KHOẢN | M91: ĐỊA CHỈ GIAO HÀNG | N91: GHI CHÚ
A92: =IF($B92="","",ROW()-91) | J92: =IF($H92="","",$H92*$I92)
A93: =IF($B93="","",ROW()-91) | J93: =IF($H93="","",$H93*$I93)
A94: =IF($B94="","",ROW()-91) | J94: =IF($H94="","",$H94*$I94)
...

Sheet Tháng 11
A1: BÁO CÁO DOANH THU THÁNG 11/2026
B3: TỔNG DOANH THU THÁNG (đ): | D3: =SUM($J$10:$J$335) -> 0
B4: ĐÃ CHUYỂN KHOẢN (đ): | D4: =SUMIF($L$10:$L$335,"Đã chuyển khoản",$J$10:$J$335) -> 0
B5: CHƯA CHUYỂN KHOẢN (đ): | D5: =SUMIF($L$10:$L$335,"Chưa chuyển khoản",$J$10:$J$335) -> 0
P6: DOANH THU THEO NGÀY
P7: NGÀY | Q7: DOANH THU (đ)
A8: TUẦN 1 (01/11 → 07/11) — DOANH THU TUẦN (đ): | K8: =SUM($J$10:$J$89) -> 0 | P8: 46327 | Q8: =SUMIF($B$10:$B$335,$P8,$J$10:$J$335) -> 0
A9: STT | B9: NGÀY ĐẶT | C9: TÊN KHÁCH HÀNG | D9: CÔNG TY | E9: MÃ SỐ THUẾ | F9: SỐ ĐIỆN THOẠI | G9: TÊN SẢN PHẨM | H9: SỐ LƯỢNG | I9: ĐƠN GIÁ (đ) | J9: THÀNH TIỀN (đ) | K9: HÌNH ẢNH SẢN PHẨM | L9: TÌNH TRẠNG CHUYỂN KHOẢN | M9: ĐỊA CHỈ GIAO HÀNG | N9: GHI CHÚ | P9: 46328 | Q9: =SUMIF($B$10:$B$335,$P9,$J$10:$J$335) -> 0
A10: =IF($B10="","",ROW()-9) | J10: =IF($H10="","",$H10*$I10) | P10: 46329 | Q10: =SUMIF($B$10:$B$335,$P10,$J$10:$J$335) -> 0
A11: =IF($B11="","",ROW()-9) | J11: =IF($H11="","",$H11*$I11) | P11: 46330 | Q11: =SUMIF($B$10:$B$335,$P11,$J$10:$J$335) -> 0
A12: =IF($B12="","",ROW()-9) | J12: =IF($H12="","",$H12*$I12) | P12: 46331 | Q12: =SUMIF($B$10:$B$335,$P12,$J$10:$J$335) -> 0
A13: =IF($B13="","",ROW()-9) | J13: =IF($H13="","",$H13*$I13) | P13: 46332 | Q13: =SUMIF($B$10:$B$335,$P13,$J$10:$J$335) -> 0
A14: =IF($B14="","",ROW()-9) | J14: =IF($H14="","",$H14*$I14) | P14: 46333 | Q14: =SUMIF($B$10:$B$335,$P14,$J$10:$J$335) -> 0
A15: =IF($B15="","",ROW()-9) | J15: =IF($H15="","",$H15*$I15) | P15: 46334 | Q15: =SUMIF($B$10:$B$335,$P15,$J$10:$J$335) -> 0
A16: =IF($B16="","",ROW()-9) | J16: =IF($H16="","",$H16*$I16) | P16: 46335 | Q16: =SUMIF($B$10:$B$335,$P16,$J$10:$J$335) -> 0
A17: =IF($B17="","",ROW()-9) | J17: =IF($H17="","",$H17*$I17) | P17: 46336 | Q17: =SUMIF($B$10:$B$335,$P17,$J$10:$J$335) -> 0
A18: =IF($B18="","",ROW()-9) | J18: =IF($H18="","",$H18*$I18) | P18: 46337 | Q18: =SUMIF($B$10:$B$335,$P18,$J$10:$J$335) -> 0
A19: =IF($B19="","",ROW()-9) | J19: =IF($H19="","",$H19*$I19) | P19: 46338 | Q19: =SUMIF($B$10:$B$335,$P19,$J$10:$J$335) -> 0
A20: =IF($B20="","",ROW()-9) | J20: =IF($H20="","",$H20*$I20) | P20: 46339 | Q20: =SUMIF($B$10:$B$335,$P20,$J$10:$J$335) -> 0
A21: =IF($B21="","",ROW()-9) | J21: =IF($H21="","",$H21*$I21) | P21: 46340 | Q21: =SUMIF($B$10:$B$335,$P21,$J$10:$J$335) -> 0
... A37: =IF($B37="","",ROW()-9) | J37: =IF($H37="","",$H37*$I37) | P37: 46356 | Q37: =SUMIF($B$10:$B$335,$P37,$J$10:$J$335) -> 0
A38: =IF($B38="","",ROW()-9) | J38: =IF($H38="","",$H38*$I38) | P38: CỘNG THÁNG | Q38: =SUM($Q$8:$Q$37) -> 0
A39: =IF($B39="","",ROW()-9) | J39: =IF($H39="","",$H39*$I39)
A40: =IF($B40="","",ROW()-9) | J40: =IF($H40="","",$H40*$I40)
A41: =IF($B41="","",ROW()-9) | J41: =IF($H41="","",$H41*$I41)
A42: =IF($B42="","",ROW()-9) | J42: =IF($H42="","",$H42*$I42)
A43: =IF($B43="","",ROW()-9) | J43: =IF($H43="","",$H43*$I43)
A44: =IF($B44="","",ROW()-9) | J44: =IF($H44="","",$H44*$I44)
A45: =IF($B45="","",ROW()-9) | J45: =IF($H45="","",$H45*$I45)
A46: =IF($B46="","",ROW()-9) | J46: =IF($H46="","",$H46*$I46)
A47: =IF($B47="","",ROW()-9) | J47: =IF($H47="","",$H47*$I47)
A48: =IF($B48="","",ROW()-9) | J48: =IF($H48="","",$H48*$I48)
A49: =IF($B49="","",ROW()-9) | J49: =IF($H49="","",$H49*$I49)
A50: =IF($B50="","",ROW()-9) | J50: =IF($H50="","",$H50*$I50)
... A89: =IF($B89="","",ROW()-9) | J89: =IF($H89="","",$H89*$I89)
A90: TUẦN 2 (08/11 → 14/11) — DOANH THU TUẦN (đ): | K90: =SUM($J$92:$J$171) -> 0
A91: STT | B91: NGÀY ĐẶT | C91: TÊN KHÁCH HÀNG | D91: CÔNG TY | E91: MÃ SỐ THUẾ | F91: SỐ ĐIỆN THOẠI | G91: TÊN SẢN PHẨM | H91: SỐ LƯỢNG | I91: ĐƠN GIÁ (đ) | J91: THÀNH TIỀN (đ) | K91: HÌNH ẢNH SẢN PHẨM | L91: TÌNH TRẠNG CHUYỂN KHOẢN | M91: ĐỊA CHỈ GIAO HÀNG | N91: GHI CHÚ
A92: =IF($B92="","",ROW()-91) | J92: =IF($H92="","",$H92*$I92)
A93: =IF($B93="","",ROW()-91) | J93: =IF($H93="","",$H93*$I93)
A94: =IF($B94="","",ROW()-91) | J94: =IF($H94="","",$H94*$I94)
...

Sheet Tháng 12
A1: BÁO CÁO DOANH THU THÁNG 12/2026
B3: TỔNG DOANH THU THÁNG (đ): | D3: =SUM($J$10:$J$335) -> 0
B4: ĐÃ CHUYỂN KHOẢN (đ): | D4: =SUMIF($L$10:$L$335,"Đã chuyển khoản",$J$10:$J$335) -> 0
B5: CHƯA CHUYỂN KHOẢN (đ): | D5: =SUMIF($L$10:$L$335,"Chưa chuyển khoản",$J$10:$J$335) -> 0
P6: DOANH THU THEO NGÀY
P7: NGÀY | Q7: DOANH THU (đ)
A8: TUẦN 1 (01/12 → 07/12) — DOANH THU TUẦN (đ): | K8: =SUM($J$10:$J$89) -> 0 | P8: 46357 | Q8: =SUMIF($B$10:$B$335,$P8,$J$10:$J$335) -> 0
A9: STT | B9: NGÀY ĐẶT | C9: TÊN KHÁCH HÀNG | D9: CÔNG TY | E9: MÃ SỐ THUẾ | F9: SỐ ĐIỆN THOẠI | G9: TÊN SẢN PHẨM | H9: SỐ LƯỢNG | I9: ĐƠN GIÁ (đ) | J9: THÀNH TIỀN (đ) | K9: HÌNH ẢNH SẢN PHẨM | L9: TÌNH TRẠNG CHUYỂN KHOẢN | M9: ĐỊA CHỈ GIAO HÀNG | N9: GHI CHÚ | P9: 46358 | Q9: =SUMIF($B$10:$B$335,$P9,$J$10:$J$335) -> 0
A10: =IF($B10="","",ROW()-9) | J10: =IF($H10="","",$H10*$I10) | P10: 46359 | Q10: =SUMIF($B$10:$B$335,$P10,$J$10:$J$335) -> 0
A11: =IF($B11="","",ROW()-9) | J11: =IF($H11="","",$H11*$I11) | P11: 46360 | Q11: =SUMIF($B$10:$B$335,$P11,$J$10:$J$335) -> 0
A12: =IF($B12="","",ROW()-9) | J12: =IF($H12="","",$H12*$I12) | P12: 46361 | Q12: =SUMIF($B$10:$B$335,$P12,$J$10:$J$335) -> 0
A13: =IF($B13="","",ROW()-9) | J13: =IF($H13="","",$H13*$I13) | P13: 46362 | Q13: =SUMIF($B$10:$B$335,$P13,$J$10:$J$335) -> 0
A14: =IF($B14="","",ROW()-9) | J14: =IF($H14="","",$H14*$I14) | P14: 46363 | Q14: =SUMIF($B$10:$B$335,$P14,$J$10:$J$335) -> 0
A15: =IF($B15="","",ROW()-9) | J15: =IF($H15="","",$H15*$I15) | P15: 46364 | Q15: =SUMIF($B$10:$B$335,$P15,$J$10:$J$335) -> 0
A16: =IF($B16="","",ROW()-9) | J16: =IF($H16="","",$H16*$I16) | P16: 46365 | Q16: =SUMIF($B$10:$B$335,$P16,$J$10:$J$335) -> 0
A17: =IF($B17="","",ROW()-9) | J17: =IF($H17="","",$H17*$I17) | P17: 46366 | Q17: =SUMIF($B$10:$B$335,$P17,$J$10:$J$335) -> 0
A18: =IF($B18="","",ROW()-9) | J18: =IF($H18="","",$H18*$I18) | P18: 46367 | Q18: =SUMIF($B$10:$B$335,$P18,$J$10:$J$335) -> 0
A19: =IF($B19="","",ROW()-9) | J19: =IF($H19="","",$H19*$I19) | P19: 46368 | Q19: =SUMIF($B$10:$B$335,$P19,$J$10:$J$335) -> 0
A20: =IF($B20="","",ROW()-9) | J20: =IF($H20="","",$H20*$I20) | P20: 46369 | Q20: =SUMIF($B$10:$B$335,$P20,$J$10:$J$335) -> 0
A21: =IF($B21="","",ROW()-9) | J21: =IF($H21="","",$H21*$I21) | P21: 46370 | Q21: =SUMIF($B$10:$B$335,$P21,$J$10:$J$335) -> 0
... A38: =IF($B38="","",ROW()-9) | J38: =IF($H38="","",$H38*$I38) | P38: 46387 | Q38: =SUMIF($B$10:$B$335,$P38,$J$10:$J$335) -> 0
A39: =IF($B39="","",ROW()-9) | J39: =IF($H39="","",$H39*$I39) | P39: CỘNG THÁNG | Q39: =SUM($Q$8:$Q$38) -> 0
A40: =IF($B40="","",ROW()-9) | J40: =IF($H40="","",$H40*$I40)
A41: =IF($B41="","",ROW()-9) | J41: =IF($H41="","",$H41*$I41)
A42: =IF($B42="","",ROW()-9) | J42: =IF($H42="","",$H42*$I42)
A43: =IF($B43="","",ROW()-9) | J43: =IF($H43="","",$H43*$I43)
A44: =IF($B44="","",ROW()-9) | J44: =IF($H44="","",$H44*$I44)
A45: =IF($B45="","",ROW()-9) | J45: =IF($H45="","",$H45*$I45)
A46: =IF($B46="","",ROW()-9) | J46: =IF($H46="","",$H46*$I46)
A47: =IF($B47="","",ROW()-9) | J47: =IF($H47="","",$H47*$I47)
A48: =IF($B48="","",ROW()-9) | J48: =IF($H48="","",$H48*$I48)
A49: =IF($B49="","",ROW()-9) | J49: =IF($H49="","",$H49*$I49)
A50: =IF($B50="","",ROW()-9) | J50: =IF($H50="","",$H50*$I50)
A51: =IF($B51="","",ROW()-9) | J51: =IF($H51="","",$H51*$I51)
... A89: =IF($B89="","",ROW()-9) | J89: =IF($H89="","",$H89*$I89)
A90: TUẦN 2 (08/12 → 14/12) — DOANH THU TUẦN (đ): | K90: =SUM($J$92:$J$171) -> 0
A91: STT | B91: NGÀY ĐẶT | C91: TÊN KHÁCH HÀNG | D91: CÔNG TY | E91: MÃ SỐ THUẾ | F91: SỐ ĐIỆN THOẠI | G91: TÊN SẢN PHẨM | H91: SỐ LƯỢNG | I91: ĐƠN GIÁ (đ) | J91: THÀNH TIỀN (đ) | K91: HÌNH ẢNH SẢN PHẨM | L91: TÌNH TRẠNG CHUYỂN KHOẢN | M91: ĐỊA CHỈ GIAO HÀNG | N91: GHI CHÚ
A92: =IF($B92="","",ROW()-91) | J92: =IF($H92="","",$H92*$I92)
A93: =IF($B93="","",ROW()-91) | J93: =IF($H93="","",$H93*$I93)
A94: =IF($B94="","",ROW()-91) | J94: =IF($H94="","",$H94*$I94)
...

Sheet BÁO CÁO NĂM
A1: BÁO CÁO TỔNG HỢP DOANH THU NĂM 2026 (THÁNG 6 → THÁNG 12)
A3: 1. TRA CỨU DOANH THU THEO NGÀY
A4: Nhập ngày cần xem: | C4: 46224 | D4: =SUMIF('Tháng 6'!$B$10:$B$335,$C$4,'Tháng 6'!$J$10:$J$335)+SUMIF('Tháng 7'!$B$10:$B$335,$C$4,'Tháng 7'!$J$10:$J$335)+SUMIF('Tháng 8'!$B$10:$B$335,$C$4,'Tháng 8'!$J$10:$J$335)+SUMIF('Tháng 9'!$B$10:$B$335,$C$4,'Tháng 9'!$J$10:$J$335)+SUMIF('Tháng 10'!$B$10:$B$335,$C$4,'Tháng 10'!$J$10:$J$335)+SUMIF('Tháng 11'!$B$10:$B$335,$C$4,'Tháng 11'!$J$10:$J$335)+SUMIF('Tháng 12'!$B$10:$B$335,$C$4,'Tháng 12'!$J$10:$J$335) -> 97000000
A5: → Doanh thu ngày đó hiện ở ô D4
A7: 2. DOANH THU THEO TUẦN (khớp với khối tuần bạn nhập) | F7: 3. DOANH THU THEO THÁNG
A8: THÁNG | B8: TUẦN | C8: TỪ NGÀY | D8: ĐẾN NGÀY | E8: DOANH THU (đ) | F8: THÁNG | G8: DOANH THU (đ) | H8: ĐÃ CK (đ) | I8: CHƯA CK (đ)
A9: Tháng 6 | B9: Tuần 1 | C9: 46174 | D9: 46180 | E9: =SUMIFS('Tháng 6'!$J$10:$J$335,'Tháng 6'!$B$10:$B$335,">="&$C9,'Tháng 6'!$B$10:$B$335,"<="&$D9) -> 8500000 | F9: Tháng 6/2026 | G9: ='Tháng 6'!$D$3 -> 21500000 | H9: ='Tháng 6'!$D$4 -> 15500000 | I9: ='Tháng 6'!$D$5 -> 6000000
A10: Tháng 6 | B10: Tuần 2 | C10: 46181 | D10: 46187 | E10: =SUMIFS('Tháng 6'!$J$10:$J$335,'Tháng 6'!$B$10:$B$335,">="&$C10,'Tháng 6'!$B$10:$B$335,"<="&$D10) -> 6000000 | F10: Tháng 7/2026 | G10: ='Tháng 7'!$D$3 -> 97000000 | H10: ='Tháng 7'!$D$4 -> 50000000 | I10: ='Tháng 7'!$D$5 -> 47000000
A11: Tháng 6 | B11: Tuần 3 | C11: 46188 | D11: 46194 | E11: =SUMIFS('Tháng 6'!$J$10:$J$335,'Tháng 6'!$B$10:$B$335,">="&$C11,'Tháng 6'!$B$10:$B$335,"<="&$D11) -> 7000000 | F11: Tháng 8/2026 | G11: ='Tháng 8'!$D$3 -> 0 | H11: ='Tháng 8'!$D$4 -> 0 | I11: ='Tháng 8'!$D$5 -> 0
A12: Tháng 6 | B12: Tuần 4 | C12: 46195 | D12: 46203 | E12: =SUMIFS('Tháng 6'!$J$10:$J$335,'Tháng 6'!$B$10:$B$335,">="&$C12,'Tháng 6'!$B$10:$B$335,"<="&$D12) -> 0 | F12: Tháng 9/2026 | G12: ='Tháng 9'!$D$3 -> 0 | H12: ='Tháng 9'!$D$4 -> 0 | I12: ='Tháng 9'!$D$5 -> 0
A13: Tháng 7 | B13: Tuần 1 | C13: 46204 | D13: 46210 | E13: =SUMIFS('Tháng 7'!$J$10:$J$335,'Tháng 7'!$B$10:$B$335,">="&$C13,'Tháng 7'!$B$10:$B$335,"<="&$D13) -> 0 | F13: Tháng 10/2026 | G13: ='Tháng 10'!$D$3 -> 0 | H13: ='Tháng 10'!$D$4 -> 0 | I13: ='Tháng 10'!$D$5 -> 0
A14: Tháng 7 | B14: Tuần 2 | C14: 46211 | D14: 46217 | E14: =SUMIFS('Tháng 7'!$J$10:$J$335,'Tháng 7'!$B$10:$B$335,">="&$C14,'Tháng 7'!$B$10:$B$335,"<="&$D14) -> 0 | F14: Tháng 11/2026 | G14: ='Tháng 11'!$D$3 -> 0 | H14: ='Tháng 11'!$D$4 -> 0 | I14: ='Tháng 11'!$D$5 -> 0
A15: Tháng 7 | B15: Tuần 3 | C15: 46218 | D15: 46224 | E15: =SUMIFS('Tháng 7'!$J$10:$J$335,'Tháng 7'!$B$10:$B$335,">="&$C15,'Tháng 7'!$B$10:$B$335,"<="&$D15) -> 97000000 | F15: Tháng 12/2026 | G15: ='Tháng 12'!$D$3 -> 0 | H15: ='Tháng 12'!$D$4 -> 0 | I15: ='Tháng 12'!$D$5 -> 0
A16: Tháng 7 | B16: Tuần 4 | C16: 46225 | D16: 46234 | E16: =SUMIFS('Tháng 7'!$J$10:$J$335,'Tháng 7'!$B$10:$B$335,">="&$C16,'Tháng 7'!$B$10:$B$335,"<="&$D16) -> 0
A17: Tháng 8 | B17: Tuần 1 | C17: 46235 | D17: 46241 | E17: =SUMIFS('Tháng 8'!$J$10:$J$335,'Tháng 8'!$B$10:$B$335,">="&$C17,'Tháng 8'!$B$10:$B$335,"<="&$D17) -> 0 | F17: 4. DOANH THU THEO QUÝ
A18: Tháng 8 | B18: Tuần 2 | C18: 46242 | D18: 46248 | E18: =SUMIFS('Tháng 8'!$J$10:$J$335,'Tháng 8'!$B$10:$B$335,">="&$C18,'Tháng 8'!$B$10:$B$335,"<="&$D18) -> 0 | F18: Quý 2/2026 (chỉ có T6) | G18: =SUM($G$9:$G$9) -> 21500000 | H18: =SUM($H$9:$H$9) -> 15500000 | I18: =SUM($I$9:$I$9) -> 6000000
A19: Tháng 8 | B19: Tuần 3 | C19: 46249 | D19: 46255 | E19: =SUMIFS('Tháng 8'!$J$10:$J$335,'Tháng 8'!$B$10:$B$335,">="&$C19,'Tháng 8'!$B$10:$B$335,"<="&$D19) -> 0 | F19: Quý 3/2026 (T7-T9) | G19: =SUM($G$10:$G$12) -> 97000000 | H19: =SUM($H$10:$H$12) -> 50000000 | I19: =SUM($I$10:$I$12) -> 47000000
A20: Tháng 8 | B20: Tuần 4 | C20: 46256 | D20: 46265 | E20: =SUMIFS('Tháng 8'!$J$10:$J$335,'Tháng 8'!$B$10:$B$335,">="&$C20,'Tháng 8'!$B$10:$B$335,"<="&$D20) -> 0 | F20: Quý 4/2026 (T10-T12) | G20: =SUM($G$13:$G$15) -> 0 | H20: =SUM($H$13:$H$15) -> 0 | I20: =SUM($I$13:$I$15) -> 0
A21: Tháng 9 | B21: Tuần 1 | C21: 46266 | D21: 46272 | E21: =SUMIFS('Tháng 9'!$J$10:$J$335,'Tháng 9'!$B$10:$B$335,">="&$C21,'Tháng 9'!$B$10:$B$335,"<="&$D21) -> 0
A22: Tháng 9 | B22: Tuần 2 | C22: 46273 | D22: 46279 | E22: =SUMIFS('Tháng 9'!$J$10:$J$335,'Tháng 9'!$B$10:$B$335,">="&$C22,'Tháng 9'!$B$10:$B$335,"<="&$D22) -> 0 | F22: 5. DOANH THU CẢ NĂM 2026
A23: Tháng 9 | B23: Tuần 3 | C23: 46280 | D23: 46286 | E23: =SUMIFS('Tháng 9'!$J$10:$J$335,'Tháng 9'!$B$10:$B$335,">="&$C23,'Tháng 9'!$B$10:$B$335,"<="&$D23) -> 0 | F23: TỔNG NĂM 2026 | G23: =SUM($G$18:$G$20) -> 118500000 | H23: =SUM($H$18:$H$20) -> 65500000 | I23: =SUM($I$18:$I$20) -> 53000000
A24: Tháng 9 | B24: Tuần 4 | C24: 46287 | D24: 46295 | E24: =SUMIFS('Tháng 9'!$J$10:$J$335,'Tháng 9'!$B$10:$B$335,">="&$C24,'Tháng 9'!$B$10:$B$335,"<="&$D24) -> 0
A25: Tháng 10 | B25: Tuần 1 | C25: 46296 | D25: 46302 | E25: =SUMIFS('Tháng 10'!$J$10:$J$335,'Tháng 10'!$B$10:$B$335,">="&$C25,'Tháng 10'!$B$10:$B$335,"<="&$D25) -> 0 | F25: Ghi chú: file theo dõi từ Tháng 6 đến Tháng 12/2026 nên Tổng năm = Quý 2 (chỉ T6) + Quý 3 + Quý 4. Tuần chia theo ngày trong tháng: 1-7, 8-14, 15-21, 22-cuối tháng.
A26: Tháng 10 | B26: Tuần 2 | C26: 46303 | D26: 46309 | E26: =SUMIFS('Tháng 10'!$J$10:$J$335,'Tháng 10'!$B$10:$B$335,">="&$C26,'Tháng 10'!$B$10:$B$335,"<="&$D26) -> 0
A27: Tháng 10 | B27: Tuần 3 | C27: 46310 | D27: 46316 | E27: =SUMIFS('Tháng 10'!$J$10:$J$335,'Tháng 10'!$B$10:$B$335,">="&$C27,'Tháng 10'!$B$10:$B$335,"<="&$D27) -> 0
A28: Tháng 10 | B28: Tuần 4 | C28: 46317 | D28: 46326 | E28: =SUMIFS('Tháng 10'!$J$10:$J$335,'Tháng 10'!$B$10:$B$335,">="&$C28,'Tháng 10'!$B$10:$B$335,"<="&$D28) -> 0
A29: Tháng 11 | B29: Tuần 1 | C29: 46327 | D29: 46333 | E29: =SUMIFS('Tháng 11'!$J$10:$J$335,'Tháng 11'!$B$10:$B$335,">="&$C29,'Tháng 11'!$B$10:$B$335,"<="&$D29) -> 0
A30: Tháng 11 | B30: Tuần 2 | C30: 46334 | D30: 46340 | E30: =SUMIFS('Tháng 11'!$J$10:$J$335,'Tháng 11'!$B$10:$B$335,">="&$C30,'Tháng 11'!$B$10:$B$335,"<="&$D30) -> 0
A31: Tháng 11 | B31: Tuần 3 | C31: 46341 | D31: 46347 | E31: =SUMIFS('Tháng 11'!$J$10:$J$335,'Tháng 11'!$B$10:$B$335,">="&$C31,'Tháng 11'!$B$10:$B$335,"<="&$D31) -> 0
A32: Tháng 11 | B32: Tuần 4 | C32: 46348 | D32: 46356 | E32: =SUMIFS('Tháng 11'!$J$10:$J$335,'Tháng 11'!$B$10:$B$335,">="&$C32,'Tháng 11'!$B$10:$B$335,"<="&$D32) -> 0
A33: Tháng 12 | B33: Tuần 1 | C33: 46357 | D33: 46363 | E33: =SUMIFS('Tháng 12'!$J$10:$J$335,'Tháng 12'!$B$10:$B$335,">="&$C33,'Tháng 12'!$B$10:$B$335,"<="&$D33) -> 0
A34: Tháng 12 | B34: Tuần 2 | C34: 46364 | D34: 46370 | E34: =SUMIFS('Tháng 12'!$J$10:$J$335,'Tháng 12'!$B$10:$B$335,">="&$C34,'Tháng 12'!$B$10:$B$335,"<="&$D34) -> 0
A35: Tháng 12 | B35: Tuần 3 | C35: 46371 | D35: 46377 | E35: =SUMIFS('Tháng 12'!$J$10:$J$335,'Tháng 12'!$B$10:$B$335,">="&$C35,'Tháng 12'!$B$10:$B$335,"<="&$D35) -> 0
A36: Tháng 12 | B36: Tuần 4 | C36: 46378 | D36: 46387 | E36: =SUMIFS('Tháng 12'!$J$10:$J$335,'Tháng 12'!$B$10:$B$335,">="&$C36,'Tháng 12'!$B$10:$B$335,"<="&$D36) -> 0
